Workbook
Name GeneAge: Results!$J$2:$J$17253
Name GeneDate: Results!$E$2:$E$17253
Name GeneDeployment: Results!$D$2:$D$17253
Name GeneHIV: Results!$H$2:$H$17253
Name GeneLab: Results!$D$2:$D$17253
Name GeneMicroscope: Results!$L$2:$L$17253
Name GeneMTB: Results!$F$2:$F$17253
Name GenePreviousHistory: Results!$K$2:$K$17253
Name GeneRif: Results!$G$2:$G$17253
Name GeneSex: Results!$I$2:$I$17253

Sheet Results
A1: # | B1: Patient ID | C1: Sample ID | D1: Deployment | E1: Test Date | F1: MTB | G1: Rif | H1: HIV | I1: Gender | J1: Age | K1: Previously Treated for TB | L1: Microscopy Result | M1: Test Notes | Q1: 33 | R1: 1601 | S1: =Q1/R1% -> 2.0612117
A2: 1 | B2: Patient 1 | C2: SMP-123 | E2: 16-6-2016 | F2: Negative | G2: Negative | H2: Positive | I2: Female | J2: 54 | K2: Yes | L2: Not done
A3: 2 | B3: Patient 2 | C3: SMP-124 | E3: 16-6-2016 | F3: Negative | G3: Negative | H3: Negative | I3: Male | J3: 16 | K3: No | L3: Not done
A4: 3 | B4: Patient 3 | C4: SMP-125 | E4: 16-6-2016 | F4: Negative | G4: Negative | H4: Positive | I4: Male | J4: 67 | K4: Yes | L4: Not done
A5: 4 | B5: Patient 4 | C5: SMP-126 | E5: 16-6-2016 | F5: Negative | G5: Negative | H5: Negative | I5: Female | J5: 34 | K5: No | L5: Not done
A6: 5
A7: 6
A8: 7
A9: 8
A10: 9
A11: 10
A12: 11
A13: 12
A14: 13
A15: 14
A16: 15
A17: 1
... A100: 9

Sheet Jan16
A1: Gene X pert MTE/RIF Testing Report | I1: DD/MMM/YYYY
H2: Report Start Date | I2: 42370
A3: Monthly report for the month of | C3: =IF(MONTH($I$2)=1,"January",IF(MONTH($I$2)=2,"February",IF(MONTH($I$2)=3,"March",IF(MONTH($I$2)=4,"April",IF(MONTH($I$2)=5,"May",IF(MONTH($I$2)=6,"June",IF(MONTH($I$2)=7,"July",IF(MONTH($I$2)=8,"Auguest",IF(MONTH($I$2)=9,"September",IF(MONTH($I$2)=10,"October",IF(MONTH($I$2)=11,"November",IF(MONTH($I$2)=12,"December",A3)))))))))))) -> January | E3: Year | F3: =YEAR($I$2) -> 2016 | H3: Report End Date | I3: 42401
A4: Reporting Unit
A6: 1. Age and sex distribution of tested patient
B7: Male | D7: Female | F7: Total
B8: <15 | C8: >=15 | D8: <15 | E8: >=15
B9: =COUNTIFS(GeneDate,">="&$I$2,GeneDate,"<="&$I$3,GeneAge,"<15",GeneSex,"Male",GeneMTB,"*tive") -> 0 | C9: =COUNTIFS(GeneDate,">="&$I$2,GeneDate,"<="&$I$3,GeneAge,">=15",GeneSex,"M*",GeneMTB,"*tive") -> 0 | D9: =COUNTIFS(GeneDate,">="&$I$2,GeneDate,"<="&$I$3,GeneAge,"<15",GeneSex,"F*",GeneMTB,"*tive") -> 0 | E9: =COUNTIFS(GeneDate,">="&$I$2,GeneDate,"<="&$I$3,GeneAge,">=15",GeneSex,"F*",GeneMTB,"*tive") -> 0 | F9: =COUNTIFS(GeneDate,">="&$I$2,GeneDate,"<="&$I$3,GeneMTB,"*tive") -> 0 | G9: =IF(SUM(B9:E9)=F9,"","Check Total Vaue & Category")
A11: 2. Test results and previous history of TB
C12: New | D12: Retreatment | E12: Unknown | F12: Total
A13: Sputum microscopy | B13: AFB (Positive) | C13: =COUNTIFS(GeneDate,">="&$I$2,GeneDate,"<="&$I$3,GeneMicroscope,"Pos*",GenePreviousHistory,"N*",GeneMTB,"*tive") -> 0 | D13: =COUNTIFS(GeneDate,">="&$I$2,GeneDate,"<="&$I$3,GeneMicroscope,"Pos*",GenePreviousHistory,"Y*",GeneMTB,"*tive") -> 0 | E13: =COUNTIFS(GeneDate,">="&$I$2,GeneDate,"<="&$I$3,GeneMicroscope,"Pos*",GenePreviousHistory,"Un*",GeneMTB,"*tive") -> 0 | F13: =COUNTIFS(GeneDate,">="&$I$2,GeneDate,"<="&$I$3,GeneMicroscope,"Pos*",GeneMTB,"*tive") -> 0 | G13: =IF($F$9=SUM(F13:F15),"","Error! Possibly there were be Error or Missing information at Microscopy Result") | I13: =IF(SUM(C13:E13)=F13,"","Check Total Vaue & Category")
B14: AFB (Negative) | C14: =COUNTIFS(GeneDate,">="&$I$2,GeneDate,"<="&$I$3,GeneMicroscope,"Neg*",GenePreviousHistory,"N*",GeneMTB,"*tive") -> 0 | D14: =COUNTIFS(GeneDate,">="&$I$2,GeneDate,"<="&$I$3,GeneMicroscope,"Neg*",GenePreviousHistory,"Y*",GeneMTB,"*tive") -> 0 | E14: =COUNTIFS(GeneDate,">="&$I$2,GeneDate,"<="&$I$3,GeneMicroscope,"Neg*",GenePreviousHistory,"Un*",GeneMTB,"*tive") -> 0 | F14: =COUNTIFS(GeneDate,">="&$I$2,GeneDate,"<="&$I$3,GeneMicroscope,"Neg*",GeneMTB,"*tive") -> 0 | I14: =IF(SUM(C14:E14)=F14,"","Check Total Vaue & Category")
B15: Not Done | C15: =COUNTIFS(GeneDate,">="&$I$2,GeneDate,"<="&$I$3,GeneMicroscope,"Not*",GenePreviousHistory,"N*",GeneMTB,"*tive") -> 0 | D15: =COUNTIFS(GeneDate,">="&$I$2,GeneDate,"<="&$I$3,GeneMicroscope,"Not*",GenePreviousHistory,"Y*",GeneMTB,"*tive") -> 0 | E15: =COUNTIFS(GeneDate,">="&$I$2,GeneDate,"<="&$I$3,GeneMicroscope,"Not*",GenePreviousHistory,"Un*",GeneMTB,"*tive") -> 0 | F15: =COUNTIFS(GeneDate,">="&$I$2,GeneDate,"<="&$I$3,GeneMicroscope,"Not*",GeneMTB,"*tive") -> 0 | I15: =IF(SUM(C15:E15)=F15,"","Check Total Vaue & Category")
A16: X pert MTB/RIF | B16: Negative | C16: =COUNTIFS(GeneDate,">="&$I$2,GeneDate,"<="&$I$3,GenePreviousHistory,"N*",GeneMTB,"Neg*") -> 0 | D16: =COUNTIFS(GeneDate,">="&$I$2,GeneDate,"<="&$I$3,GenePreviousHistory,"Y*",GeneMTB,"Neg*") -> 0 | E16: =F16-(C16+D16) -> 0 | F16: =COUNTIFS(GeneDate,">="&$I$2,GeneDate,"<="&$I$3,GeneMTB,"Neg*") -> 0 | G16: =IF($F$9=SUM(F16:F19),"","Error! Cross information between Xpert result and treatment category are not match; possibly there will be Erorr or missing information on MTB result OR RIF result") | I16: =IF(SUM(C16:E16)=F16,"","Check Total Vaue & Category")
B17: TB with NO RIF- Resistance | C17: =COUNTIFS(GeneDate,">="&$I$2,GeneDate,"<="&$I$3,GenePreviousHistory,"N*",GeneMTB,"Pos*",GeneRif,"Neg*") -> 0 | D17: =COUNTIFS(GeneDate,">="&$I$2,GeneDate,"<="&$I$3,GenePreviousHistory,"Y*",GeneMTB,"Pos*",GeneRif,"Neg*") -> 0 | E17: =F17-(C17+D17) -> 0 | F17: =COUNTIFS(GeneDate,">="&$I$2,GeneDate,"<="&$I$3,GeneMTB,"Pos*",GeneRif,"Neg*") -> 0 | I17: =IF(SUM(C17:E17)=F17,"","Check Total Vaue & Category")
B18: TB with RIF- Resistance | C18: =COUNTIFS(GeneDate,">="&$I$2,GeneDate,"<="&$I$3,GenePreviousHistory,"N*",GeneMTB,"Pos*",GeneRif,"Pos*") -> 0 | D18: =COUNTIFS(GeneDate,">="&$I$2,GeneDate,"<="&$I$3,GenePreviousHistory,"Y*",GeneMTB,"Pos*",GeneRif,"Pos*") -> 0 | E18: =F18-(C18+D18) -> 0 | F18: =COUNTIFS(GeneDate,">="&$I$2,GeneDate,"<="&$I$3,GeneMTB,"Pos*",GeneRif,"Pos*") -> 0 | I18: =IF(SUM(C18:E18)=F18,"","Check Total Vaue & Category")
B19: TB with RIF- Indeterminate | C19: =COUNTIFS(GeneDate,">="&$I$2,GeneDate,"<="&$I$3,GenePreviousHistory,"N*",GeneMTB,"Pos*",GeneRif,"IND*") -> 0 | D19: =COUNTIFS(GeneDate,">="&$I$2,GeneDate,"<="&$I$3,GenePreviousHistory,"Y*",GeneMTB,"Pos*",GeneRif,"IND*") -> 0 | E19: =F19-(C19+D19) -> 0 | F19: =COUNTIFS(GeneDate,">="&$I$2,GeneDate,"<="&$I$3,GeneMTB,"Pos*",GeneRif,"IND*") -> 0 | I19: =IF(SUM(C19:E19)=F19,"","Check Total Vaue & Category")
A21: 3. Test results and HIV status
C22: HIV (+) | D22: HIV (-) | E22: Unknown | F22: Total
A23: Sputum microscopy | B23: AFB (Positive) | C23: =COUNTIFS(GeneDate,">="&$I$2,GeneDate,"<="&$I$3,GeneMicroscope,"Pos*",GeneHIV,"Pos*",GeneMTB,"*tive") -> 0 | D23: =COUNTIFS(GeneDate,">="&$I$2,GeneDate,"<="&$I$3,GeneMicroscope,"Pos*",GeneHIV,"Neg*",GeneMTB,"*tive") -> 0 | E23: =COUNTIFS(GeneDate,">="&$I$2,GeneDate,"<="&$I$3,GeneMicroscope,"Pos*",GeneHIV,"Un*",GeneMTB,"*tive") -> 0 | F23: =COUNTIFS(GeneDate,">="&$I$2,GeneDate,"<="&$I$3,GeneMicroscope,"Pos*",GeneMTB,"*tive") -> 0 | G23: =IF($F$9=SUM(F23:F25),"","Error! Cross information between Microscope Result and HIV Status are not match; possibly there will be Erorr or missing information on Microscope Result OR HIV Status") | I23: =IF(SUM(C23:E23)=F23,"","Check Total Vaue & Category")
B24: AFB (Negative) | C24: =COUNTIFS(GeneDate,">="&$I$2,GeneDate,"<="&$I$3,GeneMicroscope,"Neg*",GeneHIV,"Pos*",GeneMTB,"*tive") -> 0 | D24: =COUNTIFS(GeneDate,">="&$I$2,GeneDate,"<="&$I$3,GeneMicroscope,"Neg*",GeneHIV,"Neg*",GeneMTB,"*tive") -> 0 | E24: =COUNTIFS(GeneDate,">="&$I$2,GeneDate,"<="&$I$3,GeneMicroscope,"Neg*",GeneHIV,"Un*",GeneMTB,"*tive") -> 0 | F24: =COUNTIFS(GeneDate,">="&$I$2,GeneDate,"<="&$I$3,GeneMicroscope,"Neg*",GeneMTB,"*tive") -> 0 | I24: =IF(SUM(C24:E24)=F24,"","Check Total Vaue & Category")
B25: Not Done | C25: =COUNTIFS(GeneDate,">="&$I$2,GeneDate,"<="&$I$3,GeneMicroscope,"Not*",GeneHIV,"Pos*",GeneMTB,"*tive") -> 0 | D25: =COUNTIFS(GeneDate,">="&$I$2,GeneDate,"<="&$I$3,GeneMicroscope,"Not*",GeneHIV,"Neg*",GeneMTB,"*tive") -> 0 | E25: =COUNTIFS(GeneDate,">="&$I$2,GeneDate,"<="&$I$3,GeneMicroscope,"Not*",GeneHIV,"Un*",GeneMTB,"*tive") -> 0 | F25: =COUNTIFS(GeneDate,">="&$I$2,GeneDate,"<="&$I$3,GeneMicroscope,"Not*",GeneMTB,"*tive") -> 0 | I25: =IF(SUM(C25:E25)=F25,"","Check Total Vaue & Category")
A26: X pert MTB/RIF | B26: Negative | C26: =COUNTIFS(GeneDate,">="&$I$2,GeneDate,"<="&$I$3,GeneHIV,"Pos*",GeneMTB,"Neg*") -> 0 | D26: =COUNTIFS(GeneDate,">="&$I$2,GeneDate,"<="&$I$3,GeneHIV,"Neg*",GeneMTB,"Neg*") -> 0 | E26: =COUNTIFS(GeneDate,">="&$I$2,GeneDate,"<="&$I$3,GeneHIV,"Un*",GeneMTB,"Neg*") -> 0 | F26: =COUNTIFS(GeneDate,">="&$I$2,GeneDate,"<="&$I$3,GeneMTB,"*tive",GeneMTB,"Neg*") -> 0 | G26: =IF($F$9=SUM(F26:F29),"","Error! Cross information between Xpert result and HIV Status are not match; possibly there will be Erorr or missing information on MTB result OR HIV Status") | I26: =IF(SUM(C26:E26)=F26,"","Check Total Vaue & Category")
B27: TB with NO RIF- Resistance | C27: =COUNTIFS(GeneDate,">="&$I$2,GeneDate,"<="&$I$3,GeneHIV,"Pos*",GeneMTB,"Pos*",GeneRif,"Neg*") -> 0 | D27: =COUNTIFS(GeneDate,">="&$I$2,GeneDate,"<="&$I$3,GeneHIV,"Neg*",GeneMTB,"Pos*",GeneRif,"Neg*") -> 0 | E27: =COUNTIFS(GeneDate,">="&$I$2,GeneDate,"<="&$I$3,GeneHIV,"Un*",GeneMTB,"Pos*",GeneRif,"Neg*") -> 0 | F27: =COUNTIFS(GeneDate,">="&$I$2,GeneDate,"<="&$I$3,GeneMTB,"Pos*",GeneRif,"Neg*") -> 0 | I27: =IF(SUM(C27:E27)=F27,"","Check Total Vaue & Category")
B28: TB with RIF- Resistance | C28: =COUNTIFS(GeneDate,">="&$I$2,GeneDate,"<="&$I$3,GeneHIV,"Pos*",GeneMTB,"Pos*",GeneRif,"Pos*") -> 0 | D28: =COUNTIFS(GeneDate,">="&$I$2,GeneDate,"<="&$I$3,GeneHIV,"Neg*",GeneMTB,"Pos*",GeneRif,"Pos*") -> 0 | E28: =COUNTIFS(GeneDate,">="&$I$2,GeneDate,"<="&$I$3,GeneHIV,"Un*",GeneMTB,"Pos*",GeneRif,"Pos*") -> 0 | F28: =COUNTIFS(GeneDate,">="&$I$2,GeneDate,"<="&$I$3,GeneMTB,"Pos*",GeneRif,"Pos*") -> 0 | I28: =IF(SUM(C28:E28)=F28,"","Check Total Vaue & Category")
B29: TB with RIF- Inderterminate | C29: =COUNTIFS(GeneDate,">="&$I$2,GeneDate,"<="&$I$3,GeneHIV,"Pos*",GeneMTB,"Pos*",GeneRif,"IND*") -> 0 | D29: =COUNTIFS(GeneDate,">="&$I$2,GeneDate,"<="&$I$3,GeneHIV,"Neg*",GeneMTB,"Pos*",GeneRif,"IND*") -> 0 | E29: =COUNTIFS(GeneDate,">="&$I$2,GeneDate,"<="&$I$3,GeneHIV,"Un*",GeneMTB,"Pos*",GeneRif,"IND*") -> 0 | F29: =COUNTIFS(GeneDate,">="&$I$2,GeneDate,"<="&$I$3,GeneMTB,"Pos*",GeneRif,"IND*") -> 0 | I29: =IF(SUM(C29:E29)=F29,"","Check Total Vaue & Category")
C31: Male | E31: Female | G31: Total
A32: TB with Rif-Resistance detected | C32: =COUNTIFS(GeneDate,">="&$I$2,GeneDate,"<="&$I$3,GeneMTB,"Pos*",GeneRif,"Pos*",GeneSex,"Male") -> 0 | E32: =COUNTIFS(GeneDate,">="&$I$2,GeneDate,"<="&$I$3,GeneMTB,"Pos*",GeneRif,"Pos*",GeneSex,"Female") -> 0 | G32: =COUNTIFS(GeneDate,">="&$I$2,GeneDate,"<="&$I$3,GeneMTB,"Pos*",GeneRif,"Pos*") -> 0
A34: 5. Compare with sputum microscopy
C35: X pert + | E35: X pert Negative | G35: Total
A36: Microscopy AFB (Positive) | C36: =COUNTIFS(GeneDate,">="&$I$2,GeneDate,"<="&$I$3,GeneMTB,"Pos*",GeneMicroscope,"Pos*") -> 0 | E36: =COUNTIFS(GeneDate,">="&$I$2,GeneDate,"<="&$I$3,GeneMTB,"Neg*",GeneMicroscope,"Pos*") -> 0 | G36: =COUNTIFS(GeneDate,">="&$I$2,GeneDate,"<="&$I$3,GeneMicroscope,"Pos*",GeneMTB,"*tive") -> 0 | H36: =IF($F$9=SUM(G36:G38),"","Error! Cross information between Xpert result and Microscope result are not match; possibly there will be Erorr or missing information on MTB result OR Microscope result") | J36: =IF(SUM(C36:F36)=G36,"","Check Total Vaue & Category")
A37: Microscopy AFB (Negative) | C37: =COUNTIFS(GeneDate,">="&$I$2,GeneDate,"<="&$I$3,GeneMTB,"Pos*",GeneMicroscope,"Neg*") -> 0 | E37: =COUNTIFS(GeneDate,">="&$I$2,GeneDate,"<="&$I$3,GeneMTB,"Neg*",GeneMicroscope,"Neg*") -> 0 | G37: =COUNTIFS(GeneDate,">="&$I$2,GeneDate,"<="&$I$3,GeneMicroscope,"Neg*",GeneMTB,"*tive") -> 0 | J37: =IF(SUM(C37:F37)=G37,"","Check Total Vaue & Category")
A38: Microscopy AFB (Not Done) | C38: =COUNTIFS(GeneDate,">="&$I$2,GeneDate,"<="&$I$3,GeneMTB,"Pos*",GeneMicroscope,"Not*") -> 0 | E38: =COUNTIFS(GeneDate,">="&$I$2,GeneDate,"<="&$I$3,GeneMTB,"Neg*",GeneMicroscope,"Not*") -> 0 | G38: =COUNTIFS(GeneDate,">="&$I$2,GeneDate,"<="&$I$3,GeneMTB,"*tive",GeneMicroscope,"Not*") -> 0 | J38: =IF(SUM(C38:F38)=G38,"","Check Total Vaue & Category")
D39: =IF(SUM(C36:D38)=SUM(F27:F29),"","Error")
A40: 6. Test kit Balance
C41: Amount | E41: Expire date
A42: Opening balance
A43: Received during this month
A44: Used | C44: =C46+F9+C47 -> 0
A45: Closing balance | C45: =SUM(C42+C43)-C44 -> 0
...

Sheet Feb16
A1: Gene X pert MTE/RIF Testing Report | I1: DD/MMM/YYYY
H2: Report Start Date | I2: 42401
A3: Monthly report for the month of | C3: =IF(MONTH($I$2)=1,"January",IF(MONTH($I$2)=2,"February",IF(MONTH($I$2)=3,"March",IF(MONTH($I$2)=4,"April",IF(MONTH($I$2)=5,"May",IF(MONTH($I$2)=6,"June",IF(MONTH($I$2)=7,"July",IF(MONTH($I$2)=8,"Auguest",IF(MONTH($I$2)=9,"September",IF(MONTH($I$2)=10,"October",IF(MONTH($I$2)=11,"November",IF(MONTH($I$2)=12,"December",A3)))))))))))) -> February | E3: Year | F3: =YEAR($I$2) -> 2016 | H3: Report End Date | I3: 42429
A4: Reporting Unit
A6: 1. Age and sex distribution of tested patient
B7: Male | D7: Female | F7: Total
B8: <15 | C8: >=15 | D8: <15 | E8: >=15
B9: =COUNTIFS(GeneDate,">="&$I$2,GeneDate,"<="&$I$3,GeneAge,"<15",GeneSex,"Male",GeneMTB,"*tive") -> 0 | C9: =COUNTIFS(GeneDate,">="&$I$2,GeneDate,"<="&$I$3,GeneAge,">=15",GeneSex,"M*",GeneMTB,"*tive") -> 0 | D9: =COUNTIFS(GeneDate,">="&$I$2,GeneDate,"<="&$I$3,GeneAge,"<15",GeneSex,"F*",GeneMTB,"*tive") -> 0 | E9: =COUNTIFS(GeneDate,">="&$I$2,GeneDate,"<="&$I$3,GeneAge,">=15",GeneSex,"F*",GeneMTB,"*tive") -> 0 | F9: =COUNTIFS(GeneDate,">="&$I$2,GeneDate,"<="&$I$3,GeneMTB,"*tive") -> 0 | G9: =IF(SUM(B9:E9)=F9,"","Check Total Vaue & Category")
A11: 2. Test results and previous history of TB
C12: New | D12: Retreatment | E12: Unknown | F12: Total
A13: Sputum microscopy | B13: AFB (Positive) | C13: =COUNTIFS(GeneDate,">="&$I$2,GeneDate,"<="&$I$3,GeneMicroscope,"Pos*",GenePreviousHistory,"N*",GeneMTB,"*tive") -> 0 | D13: =COUNTIFS(GeneDate,">="&$I$2,GeneDate,"<="&$I$3,GeneMicroscope,"Pos*",GenePreviousHistory,"Y*",GeneMTB,"*tive") -> 0 | E13: =COUNTIFS(GeneDate,">="&$I$2,GeneDate,"<="&$I$3,GeneMicroscope,"Pos*",GenePreviousHistory,"Un*",GeneMTB,"*tive") -> 0 | F13: =COUNTIFS(GeneDate,">="&$I$2,GeneDate,"<="&$I$3,GeneMicroscope,"Pos*",GeneMTB,"*tive") -> 0 | G13: =IF($F$9=SUM(F13:F15),"","Error! Possibly there were be Error or Missing information at Microscopy Result") | I13: =IF(SUM(C13:E13)=F13,"","Check Total Vaue & Category")
B14: AFB (Negative) | C14: =COUNTIFS(GeneDate,">="&$I$2,GeneDate,"<="&$I$3,GeneMicroscope,"Neg*",GenePreviousHistory,"N*",GeneMTB,"*tive") -> 0 | D14: =COUNTIFS(GeneDate,">="&$I$2,GeneDate,"<="&$I$3,GeneMicroscope,"Neg*",GenePreviousHistory,"Y*",GeneMTB,"*tive") -> 0 | E14: =COUNTIFS(GeneDate,">="&$I$2,GeneDate,"<="&$I$3,GeneMicroscope,"Neg*",GenePreviousHistory,"Un*",GeneMTB,"*tive") -> 0 | F14: =COUNTIFS(GeneDate,">="&$I$2,GeneDate,"<="&$I$3,GeneMicroscope,"Neg*",GeneMTB,"*tive") -> 0 | I14: =IF(SUM(C14:E14)=F14,"","Check Total Vaue & Category")
B15: Not Done | C15: =COUNTIFS(GeneDate,">="&$I$2,GeneDate,"<="&$I$3,GeneMicroscope,"Not*",GenePreviousHistory,"N*",GeneMTB,"*tive") -> 0 | D15: =COUNTIFS(GeneDate,">="&$I$2,GeneDate,"<="&$I$3,GeneMicroscope,"Not*",GenePreviousHistory,"Y*",GeneMTB,"*tive") -> 0 | E15: =COUNTIFS(GeneDate,">="&$I$2,GeneDate,"<="&$I$3,GeneMicroscope,"Not*",GenePreviousHistory,"Un*",GeneMTB,"*tive") -> 0 | F15: =COUNTIFS(GeneDate,">="&$I$2,GeneDate,"<="&$I$3,GeneMicroscope,"Not*",GeneMTB,"*tive") -> 0 | I15: =IF(SUM(C15:E15)=F15,"","Check Total Vaue & Category")
A16: X pert MTB/RIF | B16: Negative | C16: =COUNTIFS(GeneDate,">="&$I$2,GeneDate,"<="&$I$3,GenePreviousHistory,"N*",GeneMTB,"Neg*") -> 0 | D16: =COUNTIFS(GeneDate,">="&$I$2,GeneDate,"<="&$I$3,GenePreviousHistory,"Y*",GeneMTB,"Neg*") -> 0 | E16: =F16-(C16+D16) -> 0 | F16: =COUNTIFS(GeneDate,">="&$I$2,GeneDate,"<="&$I$3,GeneMTB,"Neg*") -> 0 | G16: =IF($F$9=SUM(F16:F19),"","Error! Cross information between Xpert result and treatment category are not match; possibly there will be Erorr or missing information on MTB result OR RIF result") | I16: =IF(SUM(C16:E16)=F16,"","Check Total Vaue & Category")
B17: TB with NO RIF- Resistance | C17: =COUNTIFS(GeneDate,">="&$I$2,GeneDate,"<="&$I$3,GenePreviousHistory,"N*",GeneMTB,"Pos*",GeneRif,"Neg*") -> 0 | D17: =COUNTIFS(GeneDate,">="&$I$2,GeneDate,"<="&$I$3,GenePreviousHistory,"Y*",GeneMTB,"Pos*",GeneRif,"Neg*") -> 0 | E17: =F17-(C17+D17) -> 0 | F17: =COUNTIFS(GeneDate,">="&$I$2,GeneDate,"<="&$I$3,GeneMTB,"Pos*",GeneRif,"Neg*") -> 0 | I17: =IF(SUM(C17:E17)=F17,"","Check Total Vaue & Category")
B18: TB with RIF- Resistance | C18: =COUNTIFS(GeneDate,">="&$I$2,GeneDate,"<="&$I$3,GenePreviousHistory,"N*",GeneMTB,"Pos*",GeneRif,"Pos*") -> 0 | D18: =COUNTIFS(GeneDate,">="&$I$2,GeneDate,"<="&$I$3,GenePreviousHistory,"Y*",GeneMTB,"Pos*",GeneRif,"Pos*") -> 0 | E18: =F18-(C18+D18) -> 0 | F18: =COUNTIFS(GeneDate,">="&$I$2,GeneDate,"<="&$I$3,GeneMTB,"Pos*",GeneRif,"Pos*") -> 0 | I18: =IF(SUM(C18:E18)=F18,"","Check Total Vaue & Category")
B19: TB with RIF- Indeterminate | C19: =COUNTIFS(GeneDate,">="&$I$2,GeneDate,"<="&$I$3,GenePreviousHistory,"N*",GeneMTB,"Pos*",GeneRif,"IND*") -> 0 | D19: =COUNTIFS(GeneDate,">="&$I$2,GeneDate,"<="&$I$3,GenePreviousHistory,"Y*",GeneMTB,"Pos*",GeneRif,"IND*") -> 0 | E19: =F19-(C19+D19) -> 0 | F19: =COUNTIFS(GeneDate,">="&$I$2,GeneDate,"<="&$I$3,GeneMTB,"Pos*",GeneRif,"IND*") -> 0 | I19: =IF(SUM(C19:E19)=F19,"","Check Total Vaue & Category")
A21: 3. Test results and HIV status
C22: HIV (+) | D22: HIV (-) | E22: Unknown | F22: Total
A23: Sputum microscopy | B23: AFB (Positive) | C23: =COUNTIFS(GeneDate,">="&$I$2,GeneDate,"<="&$I$3,GeneMicroscope,"Pos*",GeneHIV,"Pos*",GeneMTB,"*tive") -> 0 | D23: =COUNTIFS(GeneDate,">="&$I$2,GeneDate,"<="&$I$3,GeneMicroscope,"Pos*",GeneHIV,"Neg*",GeneMTB,"*tive") -> 0 | E23: =COUNTIFS(GeneDate,">="&$I$2,GeneDate,"<="&$I$3,GeneMicroscope,"Pos*",GeneHIV,"Un*",GeneMTB,"*tive") -> 0 | F23: =COUNTIFS(GeneDate,">="&$I$2,GeneDate,"<="&$I$3,GeneMicroscope,"Pos*",GeneMTB,"*tive") -> 0 | G23: =IF($F$9=SUM(F23:F25),"","Error! Cross information between Microscope Result and HIV Status are not match; possibly there will be Erorr or missing information on Microscope Result OR HIV Status") | I23: =IF(SUM(C23:E23)=F23,"","Check Total Vaue & Category")
B24: AFB (Negative) | C24: =COUNTIFS(GeneDate,">="&$I$2,GeneDate,"<="&$I$3,GeneMicroscope,"Neg*",GeneHIV,"Pos*",GeneMTB,"*tive") -> 0 | D24: =COUNTIFS(GeneDate,">="&$I$2,GeneDate,"<="&$I$3,GeneMicroscope,"Neg*",GeneHIV,"Neg*",GeneMTB,"*tive") -> 0 | E24: =COUNTIFS(GeneDate,">="&$I$2,GeneDate,"<="&$I$3,GeneMicroscope,"Neg*",GeneHIV,"Un*",GeneMTB,"*tive") -> 0 | F24: =COUNTIFS(GeneDate,">="&$I$2,GeneDate,"<="&$I$3,GeneMicroscope,"Neg*",GeneMTB,"*tive") -> 0 | I24: =IF(SUM(C24:E24)=F24,"","Check Total Vaue & Category")
B25: Not Done | C25: =COUNTIFS(GeneDate,">="&$I$2,GeneDate,"<="&$I$3,GeneMicroscope,"Not*",GeneHIV,"Pos*",GeneMTB,"*tive") -> 0 | D25: =COUNTIFS(GeneDate,">="&$I$2,GeneDate,"<="&$I$3,GeneMicroscope,"Not*",GeneHIV,"Neg*",GeneMTB,"*tive") -> 0 | E25: =COUNTIFS(GeneDate,">="&$I$2,GeneDate,"<="&$I$3,GeneMicroscope,"Not*",GeneHIV,"Un*",GeneMTB,"*tive") -> 0 | F25: =COUNTIFS(GeneDate,">="&$I$2,GeneDate,"<="&$I$3,GeneMicroscope,"Not*",GeneMTB,"*tive") -> 0 | I25: =IF(SUM(C25:E25)=F25,"","Check Total Vaue & Category")
A26: X pert MTB/RIF | B26: Negative | C26: =COUNTIFS(GeneDate,">="&$I$2,GeneDate,"<="&$I$3,GeneHIV,"Pos*",GeneMTB,"Neg*") -> 0 | D26: =COUNTIFS(GeneDate,">="&$I$2,GeneDate,"<="&$I$3,GeneHIV,"Neg*",GeneMTB,"Neg*") -> 0 | E26: =COUNTIFS(GeneDate,">="&$I$2,GeneDate,"<="&$I$3,GeneHIV,"Un*",GeneMTB,"Neg*") -> 0 | F26: =COUNTIFS(GeneDate,">="&$I$2,GeneDate,"<="&$I$3,GeneMTB,"*tive",GeneMTB,"Neg*") -> 0 | G26: =IF($F$9=SUM(F26:F29),"","Error! Cross information between Xpert result and HIV Status are not match; possibly there will be Erorr or missing information on MTB result OR HIV Status") | I26: =IF(SUM(C26:E26)=F26,"","Check Total Vaue & Category")
B27: TB with NO RIF- Resistance | C27: =COUNTIFS(GeneDate,">="&$I$2,GeneDate,"<="&$I$3,GeneHIV,"Pos*",GeneMTB,"Pos*",GeneRif,"Neg*") -> 0 | D27: =COUNTIFS(GeneDate,">="&$I$2,GeneDate,"<="&$I$3,GeneHIV,"Neg*",GeneMTB,"Pos*",GeneRif,"Neg*") -> 0 | E27: =COUNTIFS(GeneDate,">="&$I$2,GeneDate,"<="&$I$3,GeneHIV,"Un*",GeneMTB,"Pos*",GeneRif,"Neg*") -> 0 | F27: =COUNTIFS(GeneDate,">="&$I$2,GeneDate,"<="&$I$3,GeneMTB,"Pos*",GeneRif,"Neg*") -> 0 | I27: =IF(SUM(C27:E27)=F27,"","Check Total Vaue & Category")
B28: TB with RIF- Resistance | C28: =COUNTIFS(GeneDate,">="&$I$2,GeneDate,"<="&$I$3,GeneHIV,"Pos*",GeneMTB,"Pos*",GeneRif,"Pos*") -> 0 | D28: =COUNTIFS(GeneDate,">="&$I$2,GeneDate,"<="&$I$3,GeneHIV,"Neg*",GeneMTB,"Pos*",GeneRif,"Pos*") -> 0 | E28: =COUNTIFS(GeneDate,">="&$I$2,GeneDate,"<="&$I$3,GeneHIV,"Un*",GeneMTB,"Pos*",GeneRif,"Pos*") -> 0 | F28: =COUNTIFS(GeneDate,">="&$I$2,GeneDate,"<="&$I$3,GeneMTB,"Pos*",GeneRif,"Pos*") -> 0 | I28: =IF(SUM(C28:E28)=F28,"","Check Total Vaue & Category")
B29: TB with RIF- Inderterminate | C29: =COUNTIFS(GeneDate,">="&$I$2,GeneDate,"<="&$I$3,GeneHIV,"Pos*",GeneMTB,"Pos*",GeneRif,"IND*") -> 0 | D29: =COUNTIFS(GeneDate,">="&$I$2,GeneDate,"<="&$I$3,GeneHIV,"Neg*",GeneMTB,"Pos*",GeneRif,"IND*") -> 0 | E29: =COUNTIFS(GeneDate,">="&$I$2,GeneDate,"<="&$I$3,GeneHIV,"Un*",GeneMTB,"Pos*",GeneRif,"IND*") -> 0 | F29: =COUNTIFS(GeneDate,">="&$I$2,GeneDate,"<="&$I$3,GeneMTB,"Pos*",GeneRif,"IND*") -> 0 | I29: =IF(SUM(C29:E29)=F29,"","Check Total Vaue & Category")
C31: Male | E31: Female | G31: Total
A32: TB with Rif-Resistance detected | C32: =COUNTIFS(GeneDate,">="&$I$2,GeneDate,"<="&$I$3,GeneMTB,"Pos*",GeneRif,"Pos*",GeneSex,"Male") -> 0 | E32: =COUNTIFS(GeneDate,">="&$I$2,GeneDate,"<="&$I$3,GeneMTB,"Pos*",GeneRif,"Pos*",GeneSex,"Female") -> 0 | G32: =COUNTIFS(GeneDate,">="&$I$2,GeneDate,"<="&$I$3,GeneMTB,"Pos*",GeneRif,"Pos*") -> 0
A34: 5. Compare with sputum microscopy
C35: X pert + | E35: X pert Negative | G35: Total
A36: Microscopy AFB (Positive) | C36: =COUNTIFS(GeneDate,">="&$I$2,GeneDate,"<="&$I$3,GeneMTB,"Pos*",GeneMicroscope,"Pos*") -> 0 | E36: =COUNTIFS(GeneDate,">="&$I$2,GeneDate,"<="&$I$3,GeneMTB,"Neg*",GeneMicroscope,"Pos*") -> 0 | G36: =COUNTIFS(GeneDate,">="&$I$2,GeneDate,"<="&$I$3,GeneMicroscope,"Pos*",GeneMTB,"*tive") -> 0 | H36: =IF($F$9=SUM(G36:G38),"","Error! Cross information between Xpert result and Microscope result are not match; possibly there will be Erorr or missing information on MTB result OR Microscope result") | J36: =IF(SUM(C36:F36)=G36,"","Check Total Vaue & Category")
A37: Microscopy AFB (Negative) | C37: =COUNTIFS(GeneDate,">="&$I$2,GeneDate,"<="&$I$3,GeneMTB,"Pos*",GeneMicroscope,"Neg*") -> 0 | E37: =COUNTIFS(GeneDate,">="&$I$2,GeneDate,"<="&$I$3,GeneMTB,"Neg*",GeneMicroscope,"Neg*") -> 0 | G37: =COUNTIFS(GeneDate,">="&$I$2,GeneDate,"<="&$I$3,GeneMicroscope,"Neg*",GeneMTB,"*tive") -> 0 | J37: =IF(SUM(C37:F37)=G37,"","Check Total Vaue & Category")
A38: Microscopy AFB (Not Done) | C38: =COUNTIFS(GeneDate,">="&$I$2,GeneDate,"<="&$I$3,GeneMTB,"Pos*",GeneMicroscope,"Not*") -> 0 | E38: =COUNTIFS(GeneDate,">="&$I$2,GeneDate,"<="&$I$3,GeneMTB,"Neg*",GeneMicroscope,"Not*") -> 0 | G38: =COUNTIFS(GeneDate,">="&$I$2,GeneDate,"<="&$I$3,GeneMTB,"*tive",GeneMicroscope,"Not*") -> 0 | J38: =IF(SUM(C38:F38)=G38,"","Check Total Vaue & Category")
D39: =IF(SUM(C36:D38)=SUM(F27:F29),"","Error")
A40: 6. Test kit Balance
C41: Amount | E41: Expire date
A42: Opening balance
A43: Received during this month
A44: Used | C44: =C46+F9+C47 -> 0
A45: Closing balance | C45: =SUM(C42+C43)-C44 -> 0
...

Sheet Mar16
A1: Gene X pert MTE/RIF Testing Report | I1: DD/MMM/YYYY
H2: Report Start Date | I2: 42430
A3: Monthly report for the month of | C3: =IF(MONTH($I$2)=1,"January",IF(MONTH($I$2)=2,"February",IF(MONTH($I$2)=3,"March",IF(MONTH($I$2)=4,"April",IF(MONTH($I$2)=5,"May",IF(MONTH($I$2)=6,"June",IF(MONTH($I$2)=7,"July",IF(MONTH($I$2)=8,"Auguest",IF(MONTH($I$2)=9,"September",IF(MONTH($I$2)=10,"October",IF(MONTH($I$2)=11,"November",IF(MONTH($I$2)=12,"December",A3)))))))))))) -> March | E3: Year | F3: =YEAR($I$2) -> 2016 | H3: Report End Date | I3: 42461
A4: Reporting Unit
A6: 1. Age and sex distribution of tested patient
B7: Male | D7: Female | F7: Total
B8: <15 | C8: >=15 | D8: <15 | E8: >=15
B9: =COUNTIFS(GeneDate,">="&$I$2,GeneDate,"<="&$I$3,GeneAge,"<15",GeneSex,"Male",GeneMTB,"*tive") -> 0 | C9: =COUNTIFS(GeneDate,">="&$I$2,GeneDate,"<="&$I$3,GeneAge,">=15",GeneSex,"M*",GeneMTB,"*tive") -> 0 | D9: =COUNTIFS(GeneDate,">="&$I$2,GeneDate,"<="&$I$3,GeneAge,"<15",GeneSex,"F*",GeneMTB,"*tive") -> 0 | E9: =COUNTIFS(GeneDate,">="&$I$2,GeneDate,"<="&$I$3,GeneAge,">=15",GeneSex,"F*",GeneMTB,"*tive") -> 0 | F9: =COUNTIFS(GeneDate,">="&$I$2,GeneDate,"<="&$I$3,GeneMTB,"*tive") -> 0 | G9: =IF(SUM(B9:E9)=F9,"","Check Total Vaue & Category")
A11: 2. Test results and previous history of TB
C12: New | D12: Retreatment | E12: Unknown | F12: Total
A13: Sputum microscopy | B13: AFB (Positive) | C13: =COUNTIFS(GeneDate,">="&$I$2,GeneDate,"<="&$I$3,GeneMicroscope,"Pos*",GenePreviousHistory,"N*",GeneMTB,"*tive") -> 0 | D13: =COUNTIFS(GeneDate,">="&$I$2,GeneDate,"<="&$I$3,GeneMicroscope,"Pos*",GenePreviousHistory,"Y*",GeneMTB,"*tive") -> 0 | E13: =COUNTIFS(GeneDate,">="&$I$2,GeneDate,"<="&$I$3,GeneMicroscope,"Pos*",GenePreviousHistory,"Un*",GeneMTB,"*tive") -> 0 | F13: =COUNTIFS(GeneDate,">="&$I$2,GeneDate,"<="&$I$3,GeneMicroscope,"Pos*",GeneMTB,"*tive") -> 0 | G13: =IF($F$9=SUM(F13:F15),"","Error! Possibly there were be Error or Missing information at Microscopy Result") | I13: =IF(SUM(C13:E13)=F13,"","Check Total Vaue & Category")
B14: AFB (Negative) | C14: =COUNTIFS(GeneDate,">="&$I$2,GeneDate,"<="&$I$3,GeneMicroscope,"Neg*",GenePreviousHistory,"N*",GeneMTB,"*tive") -> 0 | D14: =COUNTIFS(GeneDate,">="&$I$2,GeneDate,"<="&$I$3,GeneMicroscope,"Neg*",GenePreviousHistory,"Y*",GeneMTB,"*tive") -> 0 | E14: =COUNTIFS(GeneDate,">="&$I$2,GeneDate,"<="&$I$3,GeneMicroscope,"Neg*",GenePreviousHistory,"Un*",GeneMTB,"*tive") -> 0 | F14: =COUNTIFS(GeneDate,">="&$I$2,GeneDate,"<="&$I$3,GeneMicroscope,"Neg*",GeneMTB,"*tive") -> 0 | I14: =IF(SUM(C14:E14)=F14,"","Check Total Vaue & Category")
B15: Not Done | C15: =COUNTIFS(GeneDate,">="&$I$2,GeneDate,"<="&$I$3,GeneMicroscope,"Not*",GenePreviousHistory,"N*",GeneMTB,"*tive") -> 0 | D15: =COUNTIFS(GeneDate,">="&$I$2,GeneDate,"<="&$I$3,GeneMicroscope,"Not*",GenePreviousHistory,"Y*",GeneMTB,"*tive") -> 0 | E15: =COUNTIFS(GeneDate,">="&$I$2,GeneDate,"<="&$I$3,GeneMicroscope,"Not*",GenePreviousHistory,"Un*",GeneMTB,"*tive") -> 0 | F15: =COUNTIFS(GeneDate,">="&$I$2,GeneDate,"<="&$I$3,GeneMicroscope,"Not*",GeneMTB,"*tive") -> 0 | I15: =IF(SUM(C15:E15)=F15,"","Check Total Vaue & Category")
A16: X pert MTB/RIF | B16: Negative | C16: =COUNTIFS(GeneDate,">="&$I$2,GeneDate,"<="&$I$3,GenePreviousHistory,"N*",GeneMTB,"Neg*") -> 0 | D16: =COUNTIFS(GeneDate,">="&$I$2,GeneDate,"<="&$I$3,GenePreviousHistory,"Y*",GeneMTB,"Neg*") -> 0 | E16: =F16-(C16+D16) -> 0 | F16: =COUNTIFS(GeneDate,">="&$I$2,GeneDate,"<="&$I$3,GeneMTB,"Neg*") -> 0 | G16: =IF($F$9=SUM(F16:F19),"","Error! Cross information between Xpert result and treatment category are not match; possibly there will be Erorr or missing information on MTB result OR RIF result") | I16: =IF(SUM(C16:E16)=F16,"","Check Total Vaue & Category")
B17: TB with NO RIF- Resistance | C17: =COUNTIFS(GeneDate,">="&$I$2,GeneDate,"<="&$I$3,GenePreviousHistory,"N*",GeneMTB,"Pos*",GeneRif,"Neg*") -> 0 | D17: =COUNTIFS(GeneDate,">="&$I$2,GeneDate,"<="&$I$3,GenePreviousHistory,"Y*",GeneMTB,"Pos*",GeneRif,"Neg*") -> 0 | E17: =F17-(C17+D17) -> 0 | F17: =COUNTIFS(GeneDate,">="&$I$2,GeneDate,"<="&$I$3,GeneMTB,"Pos*",GeneRif,"Neg*") -> 0 | I17: =IF(SUM(C17:E17)=F17,"","Check Total Vaue & Category")
B18: TB with RIF- Resistance | C18: =COUNTIFS(GeneDate,">="&$I$2,GeneDate,"<="&$I$3,GenePreviousHistory,"N*",GeneMTB,"Pos*",GeneRif,"Pos*") -> 0 | D18: =COUNTIFS(GeneDate,">="&$I$2,GeneDate,"<="&$I$3,GenePreviousHistory,"Y*",GeneMTB,"Pos*",GeneRif,"Pos*") -> 0 | E18: =F18-(C18+D18) -> 0 | F18: =COUNTIFS(GeneDate,">="&$I$2,GeneDate,"<="&$I$3,GeneMTB,"Pos*",GeneRif,"Pos*") -> 0 | I18: =IF(SUM(C18:E18)=F18,"","Check Total Vaue & Category")
B19: TB with RIF- Indeterminate | C19: =COUNTIFS(GeneDate,">="&$I$2,GeneDate,"<="&$I$3,GenePreviousHistory,"N*",GeneMTB,"Pos*",GeneRif,"IND*") -> 0 | D19: =COUNTIFS(GeneDate,">="&$I$2,GeneDate,"<="&$I$3,GenePreviousHistory,"Y*",GeneMTB,"Pos*",GeneRif,"IND*") -> 0 | E19: =F19-(C19+D19) -> 0 | F19: =COUNTIFS(GeneDate,">="&$I$2,GeneDate,"<="&$I$3,GeneMTB,"Pos*",GeneRif,"IND*") -> 0 | I19: =IF(SUM(C19:E19)=F19,"","Check Total Vaue & Category")
A21: 3. Test results and HIV status
C22: HIV (+) | D22: HIV (-) | E22: Unknown | F22: Total
A23: Sputum microscopy | B23: AFB (Positive) | C23: =COUNTIFS(GeneDate,">="&$I$2,GeneDate,"<="&$I$3,GeneMicroscope,"Pos*",GeneHIV,"Pos*",GeneMTB,"*tive") -> 0 | D23: =COUNTIFS(GeneDate,">="&$I$2,GeneDate,"<="&$I$3,GeneMicroscope,"Pos*",GeneHIV,"Neg*",GeneMTB,"*tive") -> 0 | E23: =COUNTIFS(GeneDate,">="&$I$2,GeneDate,"<="&$I$3,GeneMicroscope,"Pos*",GeneHIV,"Un*",GeneMTB,"*tive") -> 0 | F23: =COUNTIFS(GeneDate,">="&$I$2,GeneDate,"<="&$I$3,GeneMicroscope,"Pos*",GeneMTB,"*tive") -> 0 | G23: =IF($F$9=SUM(F23:F25),"","Error! Cross information between Microscope Result and HIV Status are not match; possibly there will be Erorr or missing information on Microscope Result OR HIV Status") | I23: =IF(SUM(C23:E23)=F23,"","Check Total Vaue & Category")
B24: AFB (Negative) | C24: =COUNTIFS(GeneDate,">="&$I$2,GeneDate,"<="&$I$3,GeneMicroscope,"Neg*",GeneHIV,"Pos*",GeneMTB,"*tive") -> 0 | D24: =COUNTIFS(GeneDate,">="&$I$2,GeneDate,"<="&$I$3,GeneMicroscope,"Neg*",GeneHIV,"Neg*",GeneMTB,"*tive") -> 0 | E24: =COUNTIFS(GeneDate,">="&$I$2,GeneDate,"<="&$I$3,GeneMicroscope,"Neg*",GeneHIV,"Un*",GeneMTB,"*tive") -> 0 | F24: =COUNTIFS(GeneDate,">="&$I$2,GeneDate,"<="&$I$3,GeneMicroscope,"Neg*",GeneMTB,"*tive") -> 0 | I24: =IF(SUM(C24:E24)=F24,"","Check Total Vaue & Category")
B25: Not Done | C25: =COUNTIFS(GeneDate,">="&$I$2,GeneDate,"<="&$I$3,GeneMicroscope,"Not*",GeneHIV,"Pos*",GeneMTB,"*tive") -> 0 | D25: =COUNTIFS(GeneDate,">="&$I$2,GeneDate,"<="&$I$3,GeneMicroscope,"Not*",GeneHIV,"Neg*",GeneMTB,"*tive") -> 0 | E25: =COUNTIFS(GeneDate,">="&$I$2,GeneDate,"<="&$I$3,GeneMicroscope,"Not*",GeneHIV,"Un*",GeneMTB,"*tive") -> 0 | F25: =COUNTIFS(GeneDate,">="&$I$2,GeneDate,"<="&$I$3,GeneMicroscope,"Not*",GeneMTB,"*tive") -> 0 | I25: =IF(SUM(C25:E25)=F25,"","Check Total Vaue & Category")
A26: X pert MTB/RIF | B26: Negative | C26: =COUNTIFS(GeneDate,">="&$I$2,GeneDate,"<="&$I$3,GeneHIV,"Pos*",GeneMTB,"Neg*") -> 0 | D26: =COUNTIFS(GeneDate,">="&$I$2,GeneDate,"<="&$I$3,GeneHIV,"Neg*",GeneMTB,"Neg*") -> 0 | E26: =COUNTIFS(GeneDate,">="&$I$2,GeneDate,"<="&$I$3,GeneHIV,"Un*",GeneMTB,"Neg*") -> 0 | F26: =COUNTIFS(GeneDate,">="&$I$2,GeneDate,"<="&$I$3,GeneMTB,"*tive",GeneMTB,"Neg*") -> 0 | G26: =IF($F$9=SUM(F26:F29),"","Error! Cross information between Xpert result and HIV Status are not match; possibly there will be Erorr or missing information on MTB result OR HIV Status") | I26: =IF(SUM(C26:E26)=F26,"","Check Total Vaue & Category")
B27: TB with NO RIF- Resistance | C27: =COUNTIFS(GeneDate,">="&$I$2,GeneDate,"<="&$I$3,GeneHIV,"Pos*",GeneMTB,"Pos*",GeneRif,"Neg*") -> 0 | D27: =COUNTIFS(GeneDate,">="&$I$2,GeneDate,"<="&$I$3,GeneHIV,"Neg*",GeneMTB,"Pos*",GeneRif,"Neg*") -> 0 | E27: =COUNTIFS(GeneDate,">="&$I$2,GeneDate,"<="&$I$3,GeneHIV,"Un*",GeneMTB,"Pos*",GeneRif,"Neg*") -> 0 | F27: =COUNTIFS(GeneDate,">="&$I$2,GeneDate,"<="&$I$3,GeneMTB,"Pos*",GeneRif,"Neg*") -> 0 | I27: =IF(SUM(C27:E27)=F27,"","Check Total Vaue & Category")
B28: TB with RIF- Resistance | C28: =COUNTIFS(GeneDate,">="&$I$2,GeneDate,"<="&$I$3,GeneHIV,"Pos*",GeneMTB,"Pos*",GeneRif,"Pos*") -> 0 | D28: =COUNTIFS(GeneDate,">="&$I$2,GeneDate,"<="&$I$3,GeneHIV,"Neg*",GeneMTB,"Pos*",GeneRif,"Pos*") -> 0 | E28: =COUNTIFS(GeneDate,">="&$I$2,GeneDate,"<="&$I$3,GeneHIV,"Un*",GeneMTB,"Pos*",GeneRif,"Pos*") -> 0 | F28: =COUNTIFS(GeneDate,">="&$I$2,GeneDate,"<="&$I$3,GeneMTB,"Pos*",GeneRif,"Pos*") -> 0 | I28: =IF(SUM(C28:E28)=F28,"","Check Total Vaue & Category")
B29: TB with RIF- Inderterminate | C29: =COUNTIFS(GeneDate,">="&$I$2,GeneDate,"<="&$I$3,GeneHIV,"Pos*",GeneMTB,"Pos*",GeneRif,"IND*") -> 0 | D29: =COUNTIFS(GeneDate,">="&$I$2,GeneDate,"<="&$I$3,GeneHIV,"Neg*",GeneMTB,"Pos*",GeneRif,"IND*") -> 0 | E29: =COUNTIFS(GeneDate,">="&$I$2,GeneDate,"<="&$I$3,GeneHIV,"Un*",GeneMTB,"Pos*",GeneRif,"IND*") -> 0 | F29: =COUNTIFS(GeneDate,">="&$I$2,GeneDate,"<="&$I$3,GeneMTB,"Pos*",GeneRif,"IND*") -> 0 | I29: =IF(SUM(C29:E29)=F29,"","Check Total Vaue & Category")
C31: Male | E31: Female | G31: Total
A32: TB with Rif-Resistance detected | C32: =COUNTIFS(GeneDate,">="&$I$2,GeneDate,"<="&$I$3,GeneMTB,"Pos*",GeneRif,"Pos*",GeneSex,"Male") -> 0 | E32: =COUNTIFS(GeneDate,">="&$I$2,GeneDate,"<="&$I$3,GeneMTB,"Pos*",GeneRif,"Pos*",GeneSex,"Female") -> 0 | G32: =COUNTIFS(GeneDate,">="&$I$2,GeneDate,"<="&$I$3,GeneMTB,"Pos*",GeneRif,"Pos*") -> 0
A34: 5. Compare with sputum microscopy
C35: X pert + | E35: X pert Negative | G35: Total
A36: Microscopy AFB (Positive) | C36: =COUNTIFS(GeneDate,">="&$I$2,GeneDate,"<="&$I$3,GeneMTB,"Pos*",GeneMicroscope,"Pos*") -> 0 | E36: =COUNTIFS(GeneDate,">="&$I$2,GeneDate,"<="&$I$3,GeneMTB,"Neg*",GeneMicroscope,"Pos*") -> 0 | G36: =COUNTIFS(GeneDate,">="&$I$2,GeneDate,"<="&$I$3,GeneMicroscope,"Pos*",GeneMTB,"*tive") -> 0 | H36: =IF($F$9=SUM(G36:G38),"","Error! Cross information between Xpert result and Microscope result are not match; possibly there will be Erorr or missing information on MTB result OR Microscope result") | J36: =IF(SUM(C36:F36)=G36,"","Check Total Vaue & Category")
A37: Microscopy AFB (Negative) | C37: =COUNTIFS(GeneDate,">="&$I$2,GeneDate,"<="&$I$3,GeneMTB,"Pos*",GeneMicroscope,"Neg*") -> 0 | E37: =COUNTIFS(GeneDate,">="&$I$2,GeneDate,"<="&$I$3,GeneMTB,"Neg*",GeneMicroscope,"Neg*") -> 0 | G37: =COUNTIFS(GeneDate,">="&$I$2,GeneDate,"<="&$I$3,GeneMicroscope,"Neg*",GeneMTB,"*tive") -> 0 | J37: =IF(SUM(C37:F37)=G37,"","Check Total Vaue & Category")
A38: Microscopy AFB (Not Done) | C38: =COUNTIFS(GeneDate,">="&$I$2,GeneDate,"<="&$I$3,GeneMTB,"Pos*",GeneMicroscope,"Not*") -> 0 | E38: =COUNTIFS(GeneDate,">="&$I$2,GeneDate,"<="&$I$3,GeneMTB,"Neg*",GeneMicroscope,"Not*") -> 0 | G38: =COUNTIFS(GeneDate,">="&$I$2,GeneDate,"<="&$I$3,GeneMTB,"*tive",GeneMicroscope,"Not*") -> 0 | J38: =IF(SUM(C38:F38)=G38,"","Check Total Vaue & Category")
D39: =IF(SUM(C36:D38)=SUM(F27:F29),"","Error")
A40: 6. Test kit Balance
C41: Amount | E41: Expire date
A42: Opening balance
A43: Received during this month
A44: Used | C44: =C46+F9+C47 -> 0
A45: Closing balance | C45: =SUM(C42+C43)-C44 -> 0
...

Sheet 1st Qtr
A1: Gene X pert MTE/RIF Testing Report | I1: DD/MMM/YYYY
H2: Report Start Date | I2: 42370
A3: Reporting Period | C3: 1st Quarter | E3: Year | F3: =YEAR($I$2) -> 2016 | H3: Report End Date | I3: 42461
A4: Reporting Unit | B4: ​
A6: 1. Age and sex distribution of tested patient
B7: Male | D7: Female | F7: Total
B8: <15 | C8: >=15 | D8: <15 | E8: >=15
B9: =COUNTIFS(GeneDate,">="&$I$2,GeneDate,"<="&$I$3,GeneAge,"<15",GeneSex,"Male",GeneMTB,"*tive") -> 0 | C9: =COUNTIFS(GeneDate,">="&$I$2,GeneDate,"<="&$I$3,GeneAge,">=15",GeneSex,"M*",GeneMTB,"*tive") -> 0 | D9: =COUNTIFS(GeneDate,">="&$I$2,GeneDate,"<="&$I$3,GeneAge,"<15",GeneSex,"F*",GeneMTB,"*tive") -> 0 | E9: =COUNTIFS(GeneDate,">="&$I$2,GeneDate,"<="&$I$3,GeneAge,">=15",GeneSex,"F*",GeneMTB,"*tive") -> 0 | F9: =COUNTIFS(GeneDate,">="&$I$2,GeneDate,"<="&$I$3,GeneMTB,"*tive") -> 0 | G9: =IF(SUM(B9:E9)=F9,"","Check Total Vaue & Category")
A11: 2. Test results and previous history of TB
C12: New | D12: Retreatment | E12: Unknown | F12: Total
A13: Sputum microscopy | B13: AFB (Positive) | C13: =COUNTIFS(GeneDate,">="&$I$2,GeneDate,"<="&$I$3,GeneMicroscope,"Pos*",GenePreviousHistory,"N*",GeneMTB,"*tive") -> 0 | D13: =COUNTIFS(GeneDate,">="&$I$2,GeneDate,"<="&$I$3,GeneMicroscope,"Pos*",GenePreviousHistory,"Y*",GeneMTB,"*tive") -> 0 | E13: =COUNTIFS(GeneDate,">="&$I$2,GeneDate,"<="&$I$3,GeneMicroscope,"Pos*",GenePreviousHistory,"Un*",GeneMTB,"*tive") -> 0 | F13: =COUNTIFS(GeneDate,">="&$I$2,GeneDate,"<="&$I$3,GeneMicroscope,"Pos*",GeneMTB,"*tive") -> 0 | G13: =IF($F$9=SUM(F13:F15),"","Error! Possibly there were be Error or Missing information at Microscopy Result") | I13: =IF(SUM(C13:E13)=F13,"","Check Total Vaue & Category")
B14: AFB (Negative) | C14: =COUNTIFS(GeneDate,">="&$I$2,GeneDate,"<="&$I$3,GeneMicroscope,"Neg*",GenePreviousHistory,"N*",GeneMTB,"*tive") -> 0 | D14: =COUNTIFS(GeneDate,">="&$I$2,GeneDate,"<="&$I$3,GeneMicroscope,"Neg*",GenePreviousHistory,"Y*",GeneMTB,"*tive") -> 0 | E14: =COUNTIFS(GeneDate,">="&$I$2,GeneDate,"<="&$I$3,GeneMicroscope,"Neg*",GenePreviousHistory,"Un*",GeneMTB,"*tive") -> 0 | F14: =COUNTIFS(GeneDate,">="&$I$2,GeneDate,"<="&$I$3,GeneMicroscope,"Neg*",GeneMTB,"*tive") -> 0 | I14: =IF(SUM(C14:E14)=F14,"","Check Total Vaue & Category")
B15: Not Done | C15: =COUNTIFS(GeneDate,">="&$I$2,GeneDate,"<="&$I$3,GeneMicroscope,"Not*",GenePreviousHistory,"N*",GeneMTB,"*tive") -> 0 | D15: =COUNTIFS(GeneDate,">="&$I$2,GeneDate,"<="&$I$3,GeneMicroscope,"Not*",GenePreviousHistory,"Y*",GeneMTB,"*tive") -> 0 | E15: =COUNTIFS(GeneDate,">="&$I$2,GeneDate,"<="&$I$3,GeneMicroscope,"Not*",GenePreviousHistory,"Un*",GeneMTB,"*tive") -> 0 | F15: =COUNTIFS(GeneDate,">="&$I$2,GeneDate,"<="&$I$3,GeneMicroscope,"Not*",GeneMTB,"*tive") -> 0 | I15: =IF(SUM(C15:E15)=F15,"","Check Total Vaue & Category")
A16: X pert MTB/RIF | B16: Negative | C16: =COUNTIFS(GeneDate,">="&$I$2,GeneDate,"<="&$I$3,GenePreviousHistory,"N*",GeneMTB,"Neg*") -> 0 | D16: =COUNTIFS(GeneDate,">="&$I$2,GeneDate,"<="&$I$3,GenePreviousHistory,"Y*",GeneMTB,"Neg*") -> 0 | E16: =F16-(C16+D16) -> 0 | F16: =COUNTIFS(GeneDate,">="&$I$2,GeneDate,"<="&$I$3,GeneMTB,"Neg*") -> 0 | G16: =IF($F$9=SUM(F16:F19),"","Error! Cross information between Xpert result and treatment category are not match; possibly there will be Erorr or missing information on MTB result OR RIF result") | I16: =IF(SUM(C16:E16)=F16,"","Check Total Vaue & Category")
B17: TB with NO RIF- Resistance | C17: =COUNTIFS(GeneDate,">="&$I$2,GeneDate,"<="&$I$3,GenePreviousHistory,"N*",GeneMTB,"Pos*",GeneRif,"Neg*") -> 0 | D17: =COUNTIFS(GeneDate,">="&$I$2,GeneDate,"<="&$I$3,GenePreviousHistory,"Y*",GeneMTB,"Pos*",GeneRif,"Neg*") -> 0 | E17: =F17-(C17+D17) -> 0 | F17: =COUNTIFS(GeneDate,">="&$I$2,GeneDate,"<="&$I$3,GeneMTB,"Pos*",GeneRif,"Neg*") -> 0 | I17: =IF(SUM(C17:E17)=F17,"","Check Total Vaue & Category")
B18: TB with RIF- Resistance | C18: =COUNTIFS(GeneDate,">="&$I$2,GeneDate,"<="&$I$3,GenePreviousHistory,"N*",GeneMTB,"Pos*",GeneRif,"Pos*") -> 0 | D18: =COUNTIFS(GeneDate,">="&$I$2,GeneDate,"<="&$I$3,GenePreviousHistory,"Y*",GeneMTB,"Pos*",GeneRif,"Pos*") -> 0 | E18: =F18-(C18+D18) -> 0 | F18: =COUNTIFS(GeneDate,">="&$I$2,GeneDate,"<="&$I$3,GeneMTB,"Pos*",GeneRif,"Pos*") -> 0 | I18: =IF(SUM(C18:E18)=F18,"","Check Total Vaue & Category")
B19: TB with RIF- Indeterminate | C19: =COUNTIFS(GeneDate,">="&$I$2,GeneDate,"<="&$I$3,GenePreviousHistory,"N*",GeneMTB,"Pos*",GeneRif,"IND*") -> 0 | D19: =COUNTIFS(GeneDate,">="&$I$2,GeneDate,"<="&$I$3,GenePreviousHistory,"Y*",GeneMTB,"Pos*",GeneRif,"IND*") -> 0 | E19: =F19-(C19+D19) -> 0 | F19: =COUNTIFS(GeneDate,">="&$I$2,GeneDate,"<="&$I$3,GeneMTB,"Pos*",GeneRif,"IND*") -> 0 | I19: =IF(SUM(C19:E19)=F19,"","Check Total Vaue & Category")
A21: 3. Test results and HIV status
C22: HIV (+) | D22: HIV (-) | E22: Unknown | F22: Total
A23: Sputum microscopy | B23: AFB (Positive) | C23: =COUNTIFS(GeneDate,">="&$I$2,GeneDate,"<="&$I$3,GeneMicroscope,"Pos*",GeneHIV,"Pos*",GeneMTB,"*tive") -> 0 | D23: =COUNTIFS(GeneDate,">="&$I$2,GeneDate,"<="&$I$3,GeneMicroscope,"Pos*",GeneHIV,"Neg*",GeneMTB,"*tive") -> 0 | E23: =COUNTIFS(GeneDate,">="&$I$2,GeneDate,"<="&$I$3,GeneMicroscope,"Pos*",GeneHIV,"Un*",GeneMTB,"*tive") -> 0 | F23: =COUNTIFS(GeneDate,">="&$I$2,GeneDate,"<="&$I$3,GeneMicroscope,"Pos*",GeneMTB,"*tive") -> 0 | G23: =IF($F$9=SUM(F23:F25),"","Error! Cross information between Microscope Result and HIV Status are not match; possibly there will be Erorr or missing information on Microscope Result OR HIV Status") | I23: =IF(SUM(C23:E23)=F23,"","Check Total Vaue & Category")
B24: AFB (Negative) | C24: =COUNTIFS(GeneDate,">="&$I$2,GeneDate,"<="&$I$3,GeneMicroscope,"Neg*",GeneHIV,"Pos*",GeneMTB,"*tive") -> 0 | D24: =COUNTIFS(GeneDate,">="&$I$2,GeneDate,"<="&$I$3,GeneMicroscope,"Neg*",GeneHIV,"Neg*",GeneMTB,"*tive") -> 0 | E24: =COUNTIFS(GeneDate,">="&$I$2,GeneDate,"<="&$I$3,GeneMicroscope,"Neg*",GeneHIV,"Un*",GeneMTB,"*tive") -> 0 | F24: =COUNTIFS(GeneDate,">="&$I$2,GeneDate,"<="&$I$3,GeneMicroscope,"Neg*",GeneMTB,"*tive") -> 0 | I24: =IF(SUM(C24:E24)=F24,"","Check Total Vaue & Category")
B25: Not Done | C25: =COUNTIFS(GeneDate,">="&$I$2,GeneDate,"<="&$I$3,GeneMicroscope,"Not*",GeneHIV,"Pos*",GeneMTB,"*tive") -> 0 | D25: =COUNTIFS(GeneDate,">="&$I$2,GeneDate,"<="&$I$3,GeneMicroscope,"Not*",GeneHIV,"Neg*",GeneMTB,"*tive") -> 0 | E25: =COUNTIFS(GeneDate,">="&$I$2,GeneDate,"<="&$I$3,GeneMicroscope,"Not*",GeneHIV,"Un*",GeneMTB,"*tive") -> 0 | F25: =COUNTIFS(GeneDate,">="&$I$2,GeneDate,"<="&$I$3,GeneMicroscope,"Not*",GeneMTB,"*tive") -> 0 | I25: =IF(SUM(C25:E25)=F25,"","Check Total Vaue & Category")
A26: X pert MTB/RIF | B26: Negative | C26: =COUNTIFS(GeneDate,">="&$I$2,GeneDate,"<="&$I$3,GeneHIV,"Pos*",GeneMTB,"Neg*") -> 0 | D26: =COUNTIFS(GeneDate,">="&$I$2,GeneDate,"<="&$I$3,GeneHIV,"Neg*",GeneMTB,"Neg*") -> 0 | E26: =COUNTIFS(GeneDate,">="&$I$2,GeneDate,"<="&$I$3,GeneHIV,"Un*",GeneMTB,"Neg*") -> 0 | F26: =COUNTIFS(GeneDate,">="&$I$2,GeneDate,"<="&$I$3,GeneMTB,"*tive",GeneMTB,"Neg*") -> 0 | G26: =IF($F$9=SUM(F26:F29),"","Error! Cross information between Xpert result and HIV Status are not match; possibly there will be Erorr or missing information on MTB result OR HIV Status") | I26: =IF(SUM(C26:E26)=F26,"","Check Total Vaue & Category")
B27: TB with NO RIF- Resistance | C27: =COUNTIFS(GeneDate,">="&$I$2,GeneDate,"<="&$I$3,GeneHIV,"Pos*",GeneMTB,"Pos*",GeneRif,"Neg*") -> 0 | D27: =COUNTIFS(GeneDate,">="&$I$2,GeneDate,"<="&$I$3,GeneHIV,"Neg*",GeneMTB,"Pos*",GeneRif,"Neg*") -> 0 | E27: =COUNTIFS(GeneDate,">="&$I$2,GeneDate,"<="&$I$3,GeneHIV,"Un*",GeneMTB,"Pos*",GeneRif,"Neg*") -> 0 | F27: =COUNTIFS(GeneDate,">="&$I$2,GeneDate,"<="&$I$3,GeneMTB,"Pos*",GeneRif,"Neg*") -> 0 | I27: =IF(SUM(C27:E27)=F27,"","Check Total Vaue & Category")
B28: TB with RIF- Resistance | C28: =COUNTIFS(GeneDate,">="&$I$2,GeneDate,"<="&$I$3,GeneHIV,"Pos*",GeneMTB,"Pos*",GeneRif,"Pos*") -> 0 | D28: =COUNTIFS(GeneDate,">="&$I$2,GeneDate,"<="&$I$3,GeneHIV,"Neg*",GeneMTB,"Pos*",GeneRif,"Pos*") -> 0 | E28: =COUNTIFS(GeneDate,">="&$I$2,GeneDate,"<="&$I$3,GeneHIV,"Un*",GeneMTB,"Pos*",GeneRif,"Pos*") -> 0 | F28: =COUNTIFS(GeneDate,">="&$I$2,GeneDate,"<="&$I$3,GeneMTB,"Pos*",GeneRif,"Pos*") -> 0 | I28: =IF(SUM(C28:E28)=F28,"","Check Total Vaue & Category")
B29: TB with RIF- Inderterminate | C29: =COUNTIFS(GeneDate,">="&$I$2,GeneDate,"<="&$I$3,GeneHIV,"Pos*",GeneMTB,"Pos*",GeneRif,"IND*") -> 0 | D29: =COUNTIFS(GeneDate,">="&$I$2,GeneDate,"<="&$I$3,GeneHIV,"Neg*",GeneMTB,"Pos*",GeneRif,"IND*") -> 0 | E29: =COUNTIFS(GeneDate,">="&$I$2,GeneDate,"<="&$I$3,GeneHIV,"Un*",GeneMTB,"Pos*",GeneRif,"IND*") -> 0 | F29: =COUNTIFS(GeneDate,">="&$I$2,GeneDate,"<="&$I$3,GeneMTB,"Pos*",GeneRif,"IND*") -> 0 | I29: =IF(SUM(C29:E29)=F29,"","Check Total Vaue & Category")
C31: Male | E31: Female | G31: Total
A32: TB with Rif-Resistance detected | C32: =COUNTIFS(GeneDate,">="&$I$2,GeneDate,"<="&$I$3,GeneMTB,"Pos*",GeneRif,"Pos*",GeneSex,"Male") -> 0 | E32: =COUNTIFS(GeneDate,">="&$I$2,GeneDate,"<="&$I$3,GeneMTB,"Pos*",GeneRif,"Pos*",GeneSex,"Female") -> 0 | G32: =COUNTIFS(GeneDate,">="&$I$2,GeneDate,"<="&$I$3,GeneMTB,"Pos*",GeneRif,"Pos*") -> 0
A34: 5. Compare with sputum microscopy
C35: X pert + | E35: X pert Negative | G35: Total
A36: Microscopy AFB (Positive) | C36: =COUNTIFS(GeneDate,">="&$I$2,GeneDate,"<="&$I$3,GeneMTB,"Pos*",GeneMicroscope,"Pos*") -> 0 | E36: =COUNTIFS(GeneDate,">="&$I$2,GeneDate,"<="&$I$3,GeneMTB,"Neg*",GeneMicroscope,"Pos*") -> 0 | G36: =COUNTIFS(GeneDate,">="&$I$2,GeneDate,"<="&$I$3,GeneMicroscope,"Pos*",GeneMTB,"*tive") -> 0 | H36: =IF($F$9=SUM(G36:G38),"","Error! Cross information between Xpert result and Microscope result are not match; possibly there will be Erorr or missing information on MTB result OR Microscope result") | J36: =IF(SUM(C36:F36)=G36,"","Check Total Vaue & Category")
A37: Microscopy AFB (Negative) | C37: =COUNTIFS(GeneDate,">="&$I$2,GeneDate,"<="&$I$3,GeneMTB,"Pos*",GeneMicroscope,"Neg*") -> 0 | E37: =COUNTIFS(GeneDate,">="&$I$2,GeneDate,"<="&$I$3,GeneMTB,"Neg*",GeneMicroscope,"Neg*") -> 0 | G37: =COUNTIFS(GeneDate,">="&$I$2,GeneDate,"<="&$I$3,GeneMicroscope,"Neg*",GeneMTB,"*tive") -> 0 | J37: =IF(SUM(C37:F37)=G37,"","Check Total Vaue & Category")
A38: Microscopy AFB (Not Done) | C38: =COUNTIFS(GeneDate,">="&$I$2,GeneDate,"<="&$I$3,GeneMTB,"Pos*",GeneMicroscope,"Not*") -> 0 | E38: =COUNTIFS(GeneDate,">="&$I$2,GeneDate,"<="&$I$3,GeneMTB,"Neg*",GeneMicroscope,"Not*") -> 0 | G38: =COUNTIFS(GeneDate,">="&$I$2,GeneDate,"<="&$I$3,GeneMTB,"*tive",GeneMicroscope,"Not*") -> 0 | J38: =IF(SUM(C38:F38)=G38,"","Check Total Vaue & Category")
D39: =IF(SUM(C36:D38)=SUM(F27:F29),"","Error")
A40: 6. Test kit Balance
C41: Amount | E41: Expire date
A42: Opening balance
A43: Received during this month
A44: Used | C44: =C46+F9+C47 -> 0
A45: Closing balance | C45: =SUM(C42+C43)-C44 -> 0
...

Sheet Apr16
A1: Gene X pert MTE/RIF Testing Report | I1: DD/MMM/YYYY
H2: Report Start Date | I2: 42461
A3: Monthly report for the month of | C3: =IF(MONTH($I$2)=1,"January",IF(MONTH($I$2)=2,"February",IF(MONTH($I$2)=3,"March",IF(MONTH($I$2)=4,"April",IF(MONTH($I$2)=5,"May",IF(MONTH($I$2)=6,"June",IF(MONTH($I$2)=7,"July",IF(MONTH($I$2)=8,"Auguest",IF(MONTH($I$2)=9,"September",IF(MONTH($I$2)=10,"October",IF(MONTH($I$2)=11,"November",IF(MONTH($I$2)=12,"December",A3)))))))))))) -> April | E3: Year | F3: =YEAR($I$2) -> 2016 | H3: Report End Date | I3: 42491
A4: Reporting Unit
A6: 1. Age and sex distribution of tested patient
B7: Male | D7: Female | F7: Total
B8: <15 | C8: >=15 | D8: <15 | E8: >=15
B9: =COUNTIFS(GeneDate,">="&$I$2,GeneDate,"<="&$I$3,GeneAge,"<15",GeneSex,"Male",GeneMTB,"*tive") -> 0 | C9: =COUNTIFS(GeneDate,">="&$I$2,GeneDate,"<="&$I$3,GeneAge,">=15",GeneSex,"M*",GeneMTB,"*tive") -> 0 | D9: =COUNTIFS(GeneDate,">="&$I$2,GeneDate,"<="&$I$3,GeneAge,"<15",GeneSex,"F*",GeneMTB,"*tive") -> 0 | E9: =COUNTIFS(GeneDate,">="&$I$2,GeneDate,"<="&$I$3,GeneAge,">=15",GeneSex,"F*",GeneMTB,"*tive") -> 0 | F9: =COUNTIFS(GeneDate,">="&$I$2,GeneDate,"<="&$I$3,GeneMTB,"*tive") -> 0 | G9: =IF(SUM(B9:E9)=F9,"","Check Total Vaue & Category")
A11: 2. Test results and previous history of TB
C12: New | D12: Retreatment | E12: Unknown | F12: Total
A13: Sputum microscopy | B13: AFB (Positive) | C13: =COUNTIFS(GeneDate,">="&$I$2,GeneDate,"<="&$I$3,GeneMicroscope,"Pos*",GenePreviousHistory,"N*",GeneMTB,"*tive") -> 0 | D13: =COUNTIFS(GeneDate,">="&$I$2,GeneDate,"<="&$I$3,GeneMicroscope,"Pos*",GenePreviousHistory,"Y*",GeneMTB,"*tive") -> 0 | E13: =COUNTIFS(GeneDate,">="&$I$2,GeneDate,"<="&$I$3,GeneMicroscope,"Pos*",GenePreviousHistory,"Un*",GeneMTB,"*tive") -> 0 | F13: =COUNTIFS(GeneDate,">="&$I$2,GeneDate,"<="&$I$3,GeneMicroscope,"Pos*",GeneMTB,"*tive") -> 0 | G13: =IF($F$9=SUM(F13:F15),"","Error! Possibly there were be Error or Missing information at Microscopy Result") | I13: =IF(SUM(C13:E13)=F13,"","Check Total Vaue & Category")
B14: AFB (Negative) | C14: =COUNTIFS(GeneDate,">="&$I$2,GeneDate,"<="&$I$3,GeneMicroscope,"Neg*",GenePreviousHistory,"N*",GeneMTB,"*tive") -> 0 | D14: =COUNTIFS(GeneDate,">="&$I$2,GeneDate,"<="&$I$3,GeneMicroscope,"Neg*",GenePreviousHistory,"Y*",GeneMTB,"*tive") -> 0 | E14: =COUNTIFS(GeneDate,">="&$I$2,GeneDate,"<="&$I$3,GeneMicroscope,"Neg*",GenePreviousHistory,"Un*",GeneMTB,"*tive") -> 0 | F14: =COUNTIFS(GeneDate,">="&$I$2,GeneDate,"<="&$I$3,GeneMicroscope,"Neg*",GeneMTB,"*tive") -> 0 | I14: =IF(SUM(C14:E14)=F14,"","Check Total Vaue & Category")
B15: Not Done | C15: =COUNTIFS(GeneDate,">="&$I$2,GeneDate,"<="&$I$3,GeneMicroscope,"Not*",GenePreviousHistory,"N*",GeneMTB,"*tive") -> 0 | D15: =COUNTIFS(GeneDate,">="&$I$2,GeneDate,"<="&$I$3,GeneMicroscope,"Not*",GenePreviousHistory,"Y*",GeneMTB,"*tive") -> 0 | E15: =COUNTIFS(GeneDate,">="&$I$2,GeneDate,"<="&$I$3,GeneMicroscope,"Not*",GenePreviousHistory,"Un*",GeneMTB,"*tive") -> 0 | F15: =COUNTIFS(GeneDate,">="&$I$2,GeneDate,"<="&$I$3,GeneMicroscope,"Not*",GeneMTB,"*tive") -> 0 | I15: =IF(SUM(C15:E15)=F15,"","Check Total Vaue & Category")
A16: X pert MTB/RIF | B16: Negative | C16: =COUNTIFS(GeneDate,">="&$I$2,GeneDate,"<="&$I$3,GenePreviousHistory,"N*",GeneMTB,"Neg*") -> 0 | D16: =COUNTIFS(GeneDate,">="&$I$2,GeneDate,"<="&$I$3,GenePreviousHistory,"Y*",GeneMTB,"Neg*") -> 0 | E16: =F16-(C16+D16) -> 0 | F16: =COUNTIFS(GeneDate,">="&$I$2,GeneDate,"<="&$I$3,GeneMTB,"Neg*") -> 0 | G16: =IF($F$9=SUM(F16:F19),"","Error! Cross information between Xpert result and treatment category are not match; possibly there will be Erorr or missing information on MTB result OR RIF result") | I16: =IF(SUM(C16:E16)=F16,"","Check Total Vaue & Category")
B17: TB with NO RIF- Resistance | C17: =COUNTIFS(GeneDate,">="&$I$2,GeneDate,"<="&$I$3,GenePreviousHistory,"N*",GeneMTB,"Pos*",GeneRif,"Neg*") -> 0 | D17: =COUNTIFS(GeneDate,">="&$I$2,GeneDate,"<="&$I$3,GenePreviousHistory,"Y*",GeneMTB,"Pos*",GeneRif,"Neg*") -> 0 | E17: =F17-(C17+D17) -> 0 | F17: =COUNTIFS(GeneDate,">="&$I$2,GeneDate,"<="&$I$3,GeneMTB,"Pos*",GeneRif,"Neg*") -> 0 | I17: =IF(SUM(C17:E17)=F17,"","Check Total Vaue & Category")
B18: TB with RIF- Resistance | C18: =COUNTIFS(GeneDate,">="&$I$2,GeneDate,"<="&$I$3,GenePreviousHistory,"N*",GeneMTB,"Pos*",GeneRif,"Pos*") -> 0 | D18: =COUNTIFS(GeneDate,">="&$I$2,GeneDate,"<="&$I$3,GenePreviousHistory,"Y*",GeneMTB,"Pos*",GeneRif,"Pos*") -> 0 | E18: =F18-(C18+D18) -> 0 | F18: =COUNTIFS(GeneDate,">="&$I$2,GeneDate,"<="&$I$3,GeneMTB,"Pos*",GeneRif,"Pos*") -> 0 | I18: =IF(SUM(C18:E18)=F18,"","Check Total Vaue & Category")
B19: TB with RIF- Indeterminate | C19: =COUNTIFS(GeneDate,">="&$I$2,GeneDate,"<="&$I$3,GenePreviousHistory,"N*",GeneMTB,"Pos*",GeneRif,"IND*") -> 0 | D19: =COUNTIFS(GeneDate,">="&$I$2,GeneDate,"<="&$I$3,GenePreviousHistory,"Y*",GeneMTB,"Pos*",GeneRif,"IND*") -> 0 | E19: =F19-(C19+D19) -> 0 | F19: =COUNTIFS(GeneDate,">="&$I$2,GeneDate,"<="&$I$3,GeneMTB,"Pos*",GeneRif,"IND*") -> 0 | I19: =IF(SUM(C19:E19)=F19,"","Check Total Vaue & Category")
A21: 3. Test results and HIV status
C22: HIV (+) | D22: HIV (-) | E22: Unknown | F22: Total
A23: Sputum microscopy | B23: AFB (Positive) | C23: =COUNTIFS(GeneDate,">="&$I$2,GeneDate,"<="&$I$3,GeneMicroscope,"Pos*",GeneHIV,"Pos*",GeneMTB,"*tive") -> 0 | D23: =COUNTIFS(GeneDate,">="&$I$2,GeneDate,"<="&$I$3,GeneMicroscope,"Pos*",GeneHIV,"Neg*",GeneMTB,"*tive") -> 0 | E23: =COUNTIFS(GeneDate,">="&$I$2,GeneDate,"<="&$I$3,GeneMicroscope,"Pos*",GeneHIV,"Un*",GeneMTB,"*tive") -> 0 | F23: =COUNTIFS(GeneDate,">="&$I$2,GeneDate,"<="&$I$3,GeneMicroscope,"Pos*",GeneMTB,"*tive") -> 0 | G23: =IF($F$9=SUM(F23:F25),"","Error! Cross information between Microscope Result and HIV Status are not match; possibly there will be Erorr or missing information on Microscope Result OR HIV Status") | I23: =IF(SUM(C23:E23)=F23,"","Check Total Vaue & Category")
B24: AFB (Negative) | C24: =COUNTIFS(GeneDate,">="&$I$2,GeneDate,"<="&$I$3,GeneMicroscope,"Neg*",GeneHIV,"Pos*",GeneMTB,"*tive") -> 0 | D24: =COUNTIFS(GeneDate,">="&$I$2,GeneDate,"<="&$I$3,GeneMicroscope,"Neg*",GeneHIV,"Neg*",GeneMTB,"*tive") -> 0 | E24: =COUNTIFS(GeneDate,">="&$I$2,GeneDate,"<="&$I$3,GeneMicroscope,"Neg*",GeneHIV,"Un*",GeneMTB,"*tive") -> 0 | F24: =COUNTIFS(GeneDate,">="&$I$2,GeneDate,"<="&$I$3,GeneMicroscope,"Neg*",GeneMTB,"*tive") -> 0 | I24: =IF(SUM(C24:E24)=F24,"","Check Total Vaue & Category")
B25: Not Done | C25: =COUNTIFS(GeneDate,">="&$I$2,GeneDate,"<="&$I$3,GeneMicroscope,"Not*",GeneHIV,"Pos*",GeneMTB,"*tive") -> 0 | D25: =COUNTIFS(GeneDate,">="&$I$2,GeneDate,"<="&$I$3,GeneMicroscope,"Not*",GeneHIV,"Neg*",GeneMTB,"*tive") -> 0 | E25: =COUNTIFS(GeneDate,">="&$I$2,GeneDate,"<="&$I$3,GeneMicroscope,"Not*",GeneHIV,"Un*",GeneMTB,"*tive") -> 0 | F25: =COUNTIFS(GeneDate,">="&$I$2,GeneDate,"<="&$I$3,GeneMicroscope,"Not*",GeneMTB,"*tive") -> 0 | I25: =IF(SUM(C25:E25)=F25,"","Check Total Vaue & Category")
A26: X pert MTB/RIF | B26: Negative | C26: =COUNTIFS(GeneDate,">="&$I$2,GeneDate,"<="&$I$3,GeneHIV,"Pos*",GeneMTB,"Neg*") -> 0 | D26: =COUNTIFS(GeneDate,">="&$I$2,GeneDate,"<="&$I$3,GeneHIV,"Neg*",GeneMTB,"Neg*") -> 0 | E26: =COUNTIFS(GeneDate,">="&$I$2,GeneDate,"<="&$I$3,GeneHIV,"Un*",GeneMTB,"Neg*") -> 0 | F26: =COUNTIFS(GeneDate,">="&$I$2,GeneDate,"<="&$I$3,GeneMTB,"*tive",GeneMTB,"Neg*") -> 0 | G26: =IF($F$9=SUM(F26:F29),"","Error! Cross information between Xpert result and HIV Status are not match; possibly there will be Erorr or missing information on MTB result OR HIV Status") | I26: =IF(SUM(C26:E26)=F26,"","Check Total Vaue & Category")
B27: TB with NO RIF- Resistance | C27: =COUNTIFS(GeneDate,">="&$I$2,GeneDate,"<="&$I$3,GeneHIV,"Pos*",GeneMTB,"Pos*",GeneRif,"Neg*") -> 0 | D27: =COUNTIFS(GeneDate,">="&$I$2,GeneDate,"<="&$I$3,GeneHIV,"Neg*",GeneMTB,"Pos*",GeneRif,"Neg*") -> 0 | E27: =COUNTIFS(GeneDate,">="&$I$2,GeneDate,"<="&$I$3,GeneHIV,"Un*",GeneMTB,"Pos*",GeneRif,"Neg*") -> 0 | F27: =COUNTIFS(GeneDate,">="&$I$2,GeneDate,"<="&$I$3,GeneMTB,"Pos*",GeneRif,"Neg*") -> 0 | I27: =IF(SUM(C27:E27)=F27,"","Check Total Vaue & Category")
B28: TB with RIF- Resistance | C28: =COUNTIFS(GeneDate,">="&$I$2,GeneDate,"<="&$I$3,GeneHIV,"Pos*",GeneMTB,"Pos*",GeneRif,"Pos*") -> 0 | D28: =COUNTIFS(GeneDate,">="&$I$2,GeneDate,"<="&$I$3,GeneHIV,"Neg*",GeneMTB,"Pos*",GeneRif,"Pos*") -> 0 | E28: =COUNTIFS(GeneDate,">="&$I$2,GeneDate,"<="&$I$3,GeneHIV,"Un*",GeneMTB,"Pos*",GeneRif,"Pos*") -> 0 | F28: =COUNTIFS(GeneDate,">="&$I$2,GeneDate,"<="&$I$3,GeneMTB,"Pos*",GeneRif,"Pos*") -> 0 | I28: =IF(SUM(C28:E28)=F28,"","Check Total Vaue & Category")
B29: TB with RIF- Inderterminate | C29: =COUNTIFS(GeneDate,">="&$I$2,GeneDate,"<="&$I$3,GeneHIV,"Pos*",GeneMTB,"Pos*",GeneRif,"IND*") -> 0 | D29: =COUNTIFS(GeneDate,">="&$I$2,GeneDate,"<="&$I$3,GeneHIV,"Neg*",GeneMTB,"Pos*",GeneRif,"IND*") -> 0 | E29: =COUNTIFS(GeneDate,">="&$I$2,GeneDate,"<="&$I$3,GeneHIV,"Un*",GeneMTB,"Pos*",GeneRif,"IND*") -> 0 | F29: =COUNTIFS(GeneDate,">="&$I$2,GeneDate,"<="&$I$3,GeneMTB,"Pos*",GeneRif,"IND*") -> 0 | I29: =IF(SUM(C29:E29)=F29,"","Check Total Vaue & Category")
C31: Male | E31: Female | G31: Total
A32: TB with Rif-Resistance detected | C32: =COUNTIFS(GeneDate,">="&$I$2,GeneDate,"<="&$I$3,GeneMTB,"Pos*",GeneRif,"Pos*",GeneSex,"Male") -> 0 | E32: =COUNTIFS(GeneDate,">="&$I$2,GeneDate,"<="&$I$3,GeneMTB,"Pos*",GeneRif,"Pos*",GeneSex,"Female") -> 0 | G32: =COUNTIFS(GeneDate,">="&$I$2,GeneDate,"<="&$I$3,GeneMTB,"Pos*",GeneRif,"Pos*") -> 0
A34: 5. Compare with sputum microscopy
C35: X pert + | E35: X pert Negative | G35: Total
A36: Microscopy AFB (Positive) | C36: =COUNTIFS(GeneDate,">="&$I$2,GeneDate,"<="&$I$3,GeneMTB,"Pos*",GeneMicroscope,"Pos*") -> 0 | E36: =COUNTIFS(GeneDate,">="&$I$2,GeneDate,"<="&$I$3,GeneMTB,"Neg*",GeneMicroscope,"Pos*") -> 0 | G36: =COUNTIFS(GeneDate,">="&$I$2,GeneDate,"<="&$I$3,GeneMicroscope,"Pos*",GeneMTB,"*tive") -> 0 | H36: =IF($F$9=SUM(G36:G38),"","Error! Cross information between Xpert result and Microscope result are not match; possibly there will be Erorr or missing information on MTB result OR Microscope result") | J36: =IF(SUM(C36:F36)=G36,"","Check Total Vaue & Category")
A37: Microscopy AFB (Negative) | C37: =COUNTIFS(GeneDate,">="&$I$2,GeneDate,"<="&$I$3,GeneMTB,"Pos*",GeneMicroscope,"Neg*") -> 0 | E37: =COUNTIFS(GeneDate,">="&$I$2,GeneDate,"<="&$I$3,GeneMTB,"Neg*",GeneMicroscope,"Neg*") -> 0 | G37: =COUNTIFS(GeneDate,">="&$I$2,GeneDate,"<="&$I$3,GeneMicroscope,"Neg*",GeneMTB,"*tive") -> 0 | J37: =IF(SUM(C37:F37)=G37,"","Check Total Vaue & Category")
A38: Microscopy AFB (Not Done) | C38: =COUNTIFS(GeneDate,">="&$I$2,GeneDate,"<="&$I$3,GeneMTB,"Pos*",GeneMicroscope,"Not*") -> 0 | E38: =COUNTIFS(GeneDate,">="&$I$2,GeneDate,"<="&$I$3,GeneMTB,"Neg*",GeneMicroscope,"Not*") -> 0 | G38: =COUNTIFS(GeneDate,">="&$I$2,GeneDate,"<="&$I$3,GeneMTB,"*tive",GeneMicroscope,"Not*") -> 0 | J38: =IF(SUM(C38:F38)=G38,"","Check Total Vaue & Category")
D39: =IF(SUM(C36:D38)=SUM(F27:F29),"","Error")
A40: 6. Test kit Balance
C41: Amount | E41: Expire date
A42: Opening balance
A43: Received during this month
A44: Used | C44: =C46+F9+C47 -> 0
A45: Closing balance | C45: =SUM(C42+C43)-C44 -> 0
...

Sheet May16
A1: Gene X pert MTE/RIF Testing Report | I1: DD/MMM/YYYY
H2: Report Start Date | I2: 42491
A3: Monthly report for the month of | C3: =IF(MONTH($I$2)=1,"January",IF(MONTH($I$2)=2,"February",IF(MONTH($I$2)=3,"March",IF(MONTH($I$2)=4,"April",IF(MONTH($I$2)=5,"May",IF(MONTH($I$2)=6,"June",IF(MONTH($I$2)=7,"July",IF(MONTH($I$2)=8,"Auguest",IF(MONTH($I$2)=9,"September",IF(MONTH($I$2)=10,"October",IF(MONTH($I$2)=11,"November",IF(MONTH($I$2)=12,"December",A3)))))))))))) -> May | E3: Year | F3: =YEAR($I$2) -> 2016 | H3: Report End Date | I3: 42522
A4: Reporting Unit
A6: 1. Age and sex distribution of tested patient
B7: Male | D7: Female | F7: Total
B8: <15 | C8: >=15 | D8: <15 | E8: >=15
B9: =COUNTIFS(GeneDate,">="&$I$2,GeneDate,"<="&$I$3,GeneAge,"<15",GeneSex,"Male",GeneMTB,"*tive") -> 0 | C9: =COUNTIFS(GeneDate,">="&$I$2,GeneDate,"<="&$I$3,GeneAge,">=15",GeneSex,"M*",GeneMTB,"*tive") -> 0 | D9: =COUNTIFS(GeneDate,">="&$I$2,GeneDate,"<="&$I$3,GeneAge,"<15",GeneSex,"F*",GeneMTB,"*tive") -> 0 | E9: =COUNTIFS(GeneDate,">="&$I$2,GeneDate,"<="&$I$3,GeneAge,">=15",GeneSex,"F*",GeneMTB,"*tive") -> 0 | F9: =COUNTIFS(GeneDate,">="&$I$2,GeneDate,"<="&$I$3,GeneMTB,"*tive") -> 0 | G9: =IF(SUM(B9:E9)=F9,"","Check Total Vaue & Category")
A11: 2. Test results and previous history of TB
C12: New | D12: Retreatment | E12: Unknown | F12: Total
A13: Sputum microscopy | B13: AFB (Positive) | C13: =COUNTIFS(GeneDate,">="&$I$2,GeneDate,"<="&$I$3,GeneMicroscope,"Pos*",GenePreviousHistory,"N*",GeneMTB,"*tive") -> 0 | D13: =COUNTIFS(GeneDate,">="&$I$2,GeneDate,"<="&$I$3,GeneMicroscope,"Pos*",GenePreviousHistory,"Y*",GeneMTB,"*tive") -> 0 | E13: =COUNTIFS(GeneDate,">="&$I$2,GeneDate,"<="&$I$3,GeneMicroscope,"Pos*",GenePreviousHistory,"Un*",GeneMTB,"*tive") -> 0 | F13: =COUNTIFS(GeneDate,">="&$I$2,GeneDate,"<="&$I$3,GeneMicroscope,"Pos*",GeneMTB,"*tive") -> 0 | G13: =IF($F$9=SUM(F13:F15),"","Error! Possibly there were be Error or Missing information at Microscopy Result") | I13: =IF(SUM(C13:E13)=F13,"","Check Total Vaue & Category")
B14: AFB (Negative) | C14: =COUNTIFS(GeneDate,">="&$I$2,GeneDate,"<="&$I$3,GeneMicroscope,"Neg*",GenePreviousHistory,"N*",GeneMTB,"*tive") -> 0 | D14: =COUNTIFS(GeneDate,">="&$I$2,GeneDate,"<="&$I$3,GeneMicroscope,"Neg*",GenePreviousHistory,"Y*",GeneMTB,"*tive") -> 0 | E14: =COUNTIFS(GeneDate,">="&$I$2,GeneDate,"<="&$I$3,GeneMicroscope,"Neg*",GenePreviousHistory,"Un*",GeneMTB,"*tive") -> 0 | F14: =COUNTIFS(GeneDate,">="&$I$2,GeneDate,"<="&$I$3,GeneMicroscope,"Neg*",GeneMTB,"*tive") -> 0 | I14: =IF(SUM(C14:E14)=F14,"","Check Total Vaue & Category")
