Workbook
Name devicelist: INDEX(#REF!, 1):INDEX(#REF!, MIN(COUNTA(#REF!),#REF!))
Name GeneAge: Results!$J$1:$J$17245
Name GeneDate: Results!$E$1:$E$17245
Name GeneDeployment: Results!$D$1:$D$17245
Name GeneHIV: Results!$H$1:$H$17245
Name GeneLab: Results!$D$1:$D$17245
Name GeneMTB: Results!$F$1:$F$17245
Name GeneRif: Results!$G$1:$G$17245
Name GeneSex: Results!$I$1:$I$17245
Name list: INDEX(#REF!, 1):INDEX(#REF!, MIN(COUNTA(#REF!),#REF!))

Sheet Results
A1: <Table>
A2: # | B2: Patient ID | C2: Sample ID | D2: Device | E2: Test Date | F2: MTB | G2: Rif | H2: HIV | I2: Gender | J2: Age | K2: Previously Treated for TB | L2: Microscopy Result | M2: Patient City | N2: Treatment Unit | O2: Test Reason | P2: CXR Abnormalities | Q2: Error Code | R2: Error Notes | S2: Test Notes | T2: Tested Month | U2: Tested Quarter | V2: Tested Year
A3: <#> | B3: <patientId> | C3: <sampleId> | D3: <deviceName> | E3: <testDate> | F3: <result1> | G3: <result2> | H3: <hivStatus> | I3: <gender> | J3: <patientAgeYears> | K3: <previouslyTreated> | L3: <microscopyResult> | M3: <patientCity> | N3: <tag> | O3: <testReason> | P3: <cxrAbnormalities> | Q3: <errorCode> | R3: <errorNotes> | S3: <notes> | T3: =TEXT(E3, "MMMM") -> <testDate> | U3: =CHOOSE(ROUNDUP(MONTH(E3)/3, 0), "1st Quarter", "2nd Quarter", "3rd Quarter", "4th Quarter") -> #VALUE! | V3: =YEAR(E3) -> #VALUE!

Sheet Jan
A1: GeneXpert MTB/RIF Testing Report
C2: Quarter | D2: Month | F2: Year
A3: Reporting Period | C3: 1st Quarter | D3: January | F3: =YEAR(Results!E3) -> #VALUE!
A4: Reporting Unit
H5: Note: Press Ctrl + Alt + Shift + F9 to see the results in the cells.
A6: 1. Age and sex distribution of tested patients
B7: Male | D7: Female | F7: Total
B8: <15 | C8: >=15 | D8: <15 | E8: >=15
B9: =COUNTIFS(Results!$D:$D,IF($C$4<>"",$C$4,"*"),Results!$U:$U,IF($C$3<>"",$C$3,"*"),Results!$T:$T,IF($D$3<>"",$D$3,"*"),Results!$V:$V,IF($F$3<>"",$F$3,"*"),Results!$I:$I,"=Male",Results!$J:$J,"<15")+COUNTIFS(Results!$D:$D,IF($C$4<>"",$C$4,"*"),Results!$U:$U,IF($C$3<>"",$C$3,"*"),Results!$T:$T,IF($D$3<>"",$D$3,"*"),Results!$V:$V,IF($F$3<>"",$F$3,"*"),Results!$I:$I,"=M",Results!$J:$J,"<15") -> 0 | C9: =COUNTIFS(Results!$D:$D,IF($C$4<>"",$C$4,"*"),Results!$U:$U,IF($C$3<>"",$C$3,"*"),Results!$T:$T,IF($D$3<>"",$D$3,"*"),Results!$V:$V,IF($F$3<>"",$F$3,"*"),Results!$I:$I,"=Male",Results!$J:$J,">=15")+COUNTIFS(Results!$D:$D,IF($C$4<>"",$C$4,"*"),Results!$U:$U,IF($C$3<>"",$C$3,"*"),Results!$T:$T,IF($D$3<>"",$D$3,"*"),Results!$V:$V,IF($F$3<>"",$F$3,"*"),Results!$I:$I,"=M",Results!$J:$J,">=15") -> 0 | D9: =COUNTIFS(Results!$D:$D,IF($C$4<>"",$C$4,"*"),Results!$U:$U,IF($C$3<>"",$C$3,"*"),Results!$T:$T,IF($D$3<>"",$D$3,"*"),Results!$V:$V,IF($F$3<>"",$F$3,"*"),Results!$I:$I,"=Female",Results!$J:$J,"<15")+COUNTIFS(Results!$D:$D,IF($C$4<>"",$C$4,"*"),Results!$U:$U,IF($C$3<>"",$C$3,"*"),Results!$T:$T,IF($D$3<>"",$D$3,"*"),Results!$V:$V,IF($F$3<>"",$F$3,"*"),Results!$I:$I,"=F",Results!$J:$J,"<15") -> 0 | E9: =COUNTIFS(Results!$D:$D,IF($C$4<>"",$C$4,"*"),Results!$U:$U,IF($C$3<>"",$C$3,"*"),Results!$T:$T,IF($D$3<>"",$D$3,"*"),Results!$V:$V,IF($F$3<>"",$F$3,"*"),Results!$I:$I,"=Female",Results!$J:$J,">=15")+COUNTIFS(Results!$D:$D,IF($C$4<>"",$C$4,"*"),Results!$U:$U,IF($C$3<>"",$C$3,"*"),Results!$T:$T,IF($D$3<>"",$D$3,"*"),Results!$V:$V,IF($F$3<>"",$F$3,"*"),Results!$I:$I,"=F",Results!$J:$J,">=15") -> 0 | F9: =B9+C9+D9+E9 -> 0
A11: 2. Age and sex distribution of completed test
B12: Male | D12: Female | F12: Total
B13: <15 | C13: >=15 | D13: <15 | E13: >=15
B14: =COUNTIFS(Results!$D:$D,IF($C$4<>"",$C$4,"*"),Results!$U:$U,IF($C$3<>"",$C$3,"*"),Results!$T:$T,IF($D$3<>"",$D$3,"*"),Results!$V:$V,IF($F$3<>"",$F$3,"*"),Results!$F:$F,"<>Error",Results!$F:$F,"<>Invalid",Results!$F:$F,"<>No result",Results!$I:$I,"=Male",Results!$J:$J,"<15")+COUNTIFS(Results!$D:$D,IF($C$4<>"",$C$4,"*"),Results!$U:$U,IF($C$3<>"",$C$3,"*"),Results!$T:$T,IF($D$3<>"",$D$3,"*"),Results!$V:$V,IF($F$3<>"",$F$3,"*"),Results!$F:$F,"<>Error",Results!$F:$F,"<>Invalid",Results!$F:$F,"<>No result",Results!$I:$I,"=M",Results!$J:$J,"<15") -> 0 | C14: =COUNTIFS(Results!$D:$D,IF($C$4<>"",$C$4,"*"),Results!$U:$U,IF($C$3<>"",$C$3,"*"),Results!$T:$T,IF($D$3<>"",$D$3,"*"),Results!$V:$V,IF($F$3<>"",$F$3,"*"),Results!$F:$F,"<>Error",Results!$F:$F,"<>Invalid",Results!$F:$F,"<>No result",Results!$I:$I,"=Male",Results!$J:$J,">=15")+COUNTIFS(Results!$D:$D,IF($C$4<>"",$C$4,"*"),Results!$U:$U,IF($C$3<>"",$C$3,"*"),Results!$T:$T,IF($D$3<>"",$D$3,"*"),Results!$V:$V,IF($F$3<>"",$F$3,"*"),Results!$F:$F,"<>Error",Results!$F:$F,"<>Invalid",Results!$F:$F,"<>No result",Results!$I:$I,"=M",Results!$J:$J,">=15") -> 0 | D14: =COUNTIFS(Results!$D:$D,IF($C$4<>"",$C$4,"*"),Results!$U:$U,IF($C$3<>"",$C$3,"*"),Results!$T:$T,IF($D$3<>"",$D$3,"*"),Results!$V:$V,IF($F$3<>"",$F$3,"*"),Results!$F:$F,"<>Error",Results!$F:$F,"<>Invalid",Results!$F:$F,"<>No result",Results!$I:$I,"=Female",Results!$J:$J,"<15")+COUNTIFS(Results!$D:$D,IF($C$4<>"",$C$4,"*"),Results!$U:$U,IF($C$3<>"",$C$3,"*"),Results!$T:$T,IF($D$3<>"",$D$3,"*"),Results!$V:$V,IF($F$3<>"",$F$3,"*"),Results!$F:$F,"<>Error",Results!$F:$F,"<>Invalid",Results!$F:$F,"<>No result",Results!$I:$I,"=F",Results!$J:$J,"<15") -> 0 | E14: =COUNTIFS(Results!$D:$D,IF($C$4<>"",$C$4,"*"),Results!$U:$U,IF($C$3<>"",$C$3,"*"),Results!$T:$T,IF($D$3<>"",$D$3,"*"),Results!$V:$V,IF($F$3<>"",$F$3,"*"),Results!$F:$F,"<>Error",Results!$F:$F,"<>Invalid",Results!$F:$F,"<>No result",Results!$I:$I,"=Female",Results!$J:$J,">=15")+COUNTIFS(Results!$D:$D,IF($C$4<>"",$C$4,"*"),Results!$U:$U,IF($C$3<>"",$C$3,"*"),Results!$T:$T,IF($D$3<>"",$D$3,"*"),Results!$V:$V,IF($F$3<>"",$F$3,"*"),Results!$F:$F,"<>Error",Results!$F:$F,"<>Invalid",Results!$F:$F,"<>No result",Results!$I:$I,"=F",Results!$J:$J,">=15") -> 0 | F14: =B14+C14+D14+E14 -> 0
A16: 3. Test results and previous history of TB
C17: New | D17: Retreatment | E17: Unknown | F17: Total
A18: Xpert MTB/RIF | B18: Negative | C18: =COUNTIFS(Results!$D:$D,IF($C$4<>"",$C$4,"*"),Results!$U:$U,IF($C$3<>"",$C$3,"*"),Results!$T:$T,IF($D$3<>"",$D$3,"*"),Results!$V:$V,IF($F$3<>"",$F$3,"*"),Results!$F:$F,"Negative",Results!$K:$K,"No") -> 0 | D18: =COUNTIFS(Results!$D:$D,IF($C$4<>"",$C$4,"*"),Results!$U:$U,IF($C$3<>"",$C$3,"*"),Results!$T:$T,IF($D$3<>"",$D$3,"*"),Results!$V:$V,IF($F$3<>"",$F$3,"*"),Results!$F:$F,"Negative",Results!$K:$K,"Yes") -> 0 | E18: =COUNTIFS(Results!$D:$D,IF($C$4<>"",$C$4,"*"),Results!$U:$U,IF($C$3<>"",$C$3,"*"),Results!$T:$T,IF($D$3<>"",$D$3,"*"),Results!$V:$V,IF($F$3<>"",$F$3,"*"),Results!$F:$F,"=Negative",Results!$K:$K,"Unknown")+COUNTIFS(Results!$D:$D,IF($C$4<>"",$C$4,"*"),Results!$U:$U,IF($C$3<>"",$C$3,"*"),Results!$T:$T,IF($D$3<>"",$D$3,"*"),Results!$V:$V,IF($F$3<>"",$F$3,"*"),Results!$F:$F,"=Negative",Results!$K:$K,"N/A")+COUNTIFS(Results!$D:$D,IF($C$4<>"",$C$4,"*"),Results!$U:$U,IF($C$3<>"",$C$3,"*"),Results!$T:$T,IF($D$3<>"",$D$3,"*"),Results!$V:$V,IF($F$3<>"",$F$3,"*"),Results!$F:$F,"=Negative",Results!$K:$K,"") -> 0 | F18: =C18+D18+E18 -> 0
B19: TB with No RIF- Resistance | C19: =COUNTIFS(Results!$D:$D,IF($C$4<>"",$C$4,"*"),Results!$U:$U,IF($C$3<>"",$C$3,"*"),Results!$T:$T,IF($D$3<>"",$D$3,"*"),Results!$V:$V,IF($F$3<>"",$F$3,"*"),Results!$F:$F,"Positive",Results!$G:$G,"Negative",Results!$K:$K,"No") -> 0 | D19: =COUNTIFS(Results!$D:$D,IF($C$4<>"",$C$4,"*"),Results!$U:$U,IF($C$3<>"",$C$3,"*"),Results!$T:$T,IF($D$3<>"",$D$3,"*"),Results!$V:$V,IF($F$3<>"",$F$3,"*"),Results!$F:$F,"Positive",Results!$G:$G,"Negative",Results!$K:$K,"Yes") -> 0 | E19: =COUNTIFS(Results!$D:$D,IF($C$4<>"",$C$4,"*"),Results!$U:$U,IF($C$3<>"",$C$3,"*"),Results!$T:$T,IF($D$3<>"",$D$3,"*"),Results!$V:$V,IF($F$3<>"",$F$3,"*"),Results!$F:$F,"Positive",Results!$G:$G,"=Negative",Results!$K:$K,"Unknown")+COUNTIFS(Results!$D:$D,IF($C$4<>"",$C$4,"*"),Results!$U:$U,IF($C$3<>"",$C$3,"*"),Results!$T:$T,IF($D$3<>"",$D$3,"*"),Results!$V:$V,IF($F$3<>"",$F$3,"*"),Results!$F:$F,"Positive",Results!$G:$G,"=Negative",Results!$K:$K,"N/A")+COUNTIFS(Results!$D:$D,IF($C$4<>"",$C$4,"*"),Results!$U:$U,IF($C$3<>"",$C$3,"*"),Results!$T:$T,IF($D$3<>"",$D$3,"*"),Results!$V:$V,IF($F$3<>"",$F$3,"*"),Results!$F:$F,"Positive",Results!$G:$G,"=Negative",Results!$K:$K,"") -> 0 | F19: =C19+D19+E19 -> 0
B20: TB with RIF- Resistance | C20: =COUNTIFS(Results!$D:$D,IF($C$4<>"",$C$4,"*"),Results!$U:$U,IF($C$3<>"",$C$3,"*"),Results!$T:$T,IF($D$3<>"",$D$3,"*"),Results!$V:$V,IF($F$3<>"",$F$3,"*"),Results!$F:$F,"Positive",Results!$G:$G,"Positive",Results!$K:$K,"No") -> 0 | D20: =COUNTIFS(Results!$D:$D,IF($C$4<>"",$C$4,"*"),Results!$U:$U,IF($C$3<>"",$C$3,"*"),Results!$T:$T,IF($D$3<>"",$D$3,"*"),Results!$V:$V,IF($F$3<>"",$F$3,"*"),Results!$F:$F,"Positive",Results!$G:$G,"Positive",Results!$K:$K,"Yes") -> 0 | E20: =COUNTIFS(Results!$D:$D,IF($C$4<>"",$C$4,"*"),Results!$U:$U,IF($C$3<>"",$C$3,"*"),Results!$T:$T,IF($D$3<>"",$D$3,"*"),Results!$V:$V,IF($F$3<>"",$F$3,"*"),Results!$F:$F,"Positive",Results!$G:$G,"=Positive",Results!$K:$K,"Unknown")+COUNTIFS(Results!$D:$D,IF($C$4<>"",$C$4,"*"),Results!$U:$U,IF($C$3<>"",$C$3,"*"),Results!$T:$T,IF($D$3<>"",$D$3,"*"),Results!$V:$V,IF($F$3<>"",$F$3,"*"),Results!$F:$F,"Positive",Results!$G:$G,"=Positive",Results!$K:$K,"N/A")+COUNTIFS(Results!$D:$D,IF($C$4<>"",$C$4,"*"),Results!$U:$U,IF($C$3<>"",$C$3,"*"),Results!$T:$T,IF($D$3<>"",$D$3,"*"),Results!$V:$V,IF($F$3<>"",$F$3,"*"),Results!$F:$F,"Positive",Results!$G:$G,"=Positive",Results!$K:$K,"") -> 0 | F20: =C20+D20+E20 -> 0
B21: TB with RIF- Indeterminate | C21: =COUNTIFS(Results!$D:$D,IF($C$4<>"",$C$4,"*"),Results!$U:$U,IF($C$3<>"",$C$3,"*"),Results!$T:$T,IF($D$3<>"",$D$3,"*"),Results!$V:$V,IF($F$3<>"",$F$3,"*"),Results!$F:$F,"Positive",Results!$G:$G,"Indeterminate",Results!$K:$K,"No") -> 0 | D21: =COUNTIFS(Results!$D:$D,IF($C$4<>"",$C$4,"*"),Results!$U:$U,IF($C$3<>"",$C$3,"*"),Results!$T:$T,IF($D$3<>"",$D$3,"*"),Results!$V:$V,IF($F$3<>"",$F$3,"*"),Results!$F:$F,"Positive",Results!$G:$G,"Indeterminate",Results!$K:$K,"Yes") -> 0 | E21: =COUNTIFS(Results!$D:$D,IF($C$4<>"",$C$4,"*"),Results!$U:$U,IF($C$3<>"",$C$3,"*"),Results!$T:$T,IF($D$3<>"",$D$3,"*"),Results!$V:$V,IF($F$3<>"",$F$3,"*"),Results!$F:$F,"Positive",Results!$G:$G,"=Indeterminate",Results!$K:$K,"Unknown")+COUNTIFS(Results!$D:$D,IF($C$4<>"",$C$4,"*"),Results!$U:$U,IF($C$3<>"",$C$3,"*"),Results!$T:$T,IF($D$3<>"",$D$3,"*"),Results!$V:$V,IF($F$3<>"",$F$3,"*"),Results!$F:$F,"Positive",Results!$G:$G,"=Indeterminate",Results!$K:$K,"N/A")+COUNTIFS(Results!$D:$D,IF($C$4<>"",$C$4,"*"),Results!$U:$U,IF($C$3<>"",$C$3,"*"),Results!$T:$T,IF($D$3<>"",$D$3,"*"),Results!$V:$V,IF($F$3<>"",$F$3,"*"),Results!$F:$F,"Positive",Results!$G:$G,"=Indeterminate",Results!$K:$K,"") -> 0 | F21: =C21+D21+E21 -> 0
B22: TB - Trace with RIF- Indeterminate | C22: =COUNTIFS(Results!$D:$D,IF($C$4<>"",$C$4,"*"),Results!$U:$U,IF($C$3<>"",$C$3,"*"),Results!$T:$T,IF($D$3<>"",$D$3,"*"),Results!$V:$V,IF($F$3<>"",$F$3,"*"),Results!$F:$F,"Trace",Results!$G:$G,"Indeterminate",Results!$K:$K,"No") -> 0 | D22: =COUNTIFS(Results!$D:$D,IF($C$4<>"",$C$4,"*"),Results!$U:$U,IF($C$3<>"",$C$3,"*"),Results!$T:$T,IF($D$3<>"",$D$3,"*"),Results!$V:$V,IF($F$3<>"",$F$3,"*"),Results!$F:$F,"Trace",Results!$G:$G,"Indeterminate",Results!$K:$K,"Yes") -> 0 | E22: =COUNTIFS(Results!$D:$D,IF($C$4<>"",$C$4,"*"),Results!$U:$U,IF($C$3<>"",$C$3,"*"),Results!$T:$T,IF($D$3<>"",$D$3,"*"),Results!$V:$V,IF($F$3<>"",$F$3,"*"),Results!$F:$F,"Trace",Results!$G:$G,"=Indeterminate",Results!$K:$K,"Unknown")+COUNTIFS(Results!$D:$D,IF($C$4<>"",$C$4,"*"),Results!$U:$U,IF($C$3<>"",$C$3,"*"),Results!$T:$T,IF($D$3<>"",$D$3,"*"),Results!$V:$V,IF($F$3<>"",$F$3,"*"),Results!$F:$F,"Trace",Results!$G:$G,"=Indeterminate",Results!$K:$K,"N/A")+COUNTIFS(Results!$D:$D,IF($C$4<>"",$C$4,"*"),Results!$U:$U,IF($C$3<>"",$C$3,"*"),Results!$T:$T,IF($D$3<>"",$D$3,"*"),Results!$V:$V,IF($F$3<>"",$F$3,"*"),Results!$F:$F,"Trace",Results!$G:$G,"=Indeterminate",Results!$K:$K,"") -> 0 | F22: =C22+D22+E22 -> 0
A23: Total | C23: =SUM(C18:C22) -> 0 | D23: =SUM(D18:D22) -> 0 | E23: =SUM(E18:E22) -> 0 | F23: =SUM(F18:F22) -> 0
A25: 4. Test results and HIV status
C26: HIV (+) | D26: HIV (-) | E26: Unknown | F26: Total
A27: Xpert MTB/RIF | B27: Negative | C27: =COUNTIFS(Results!$D:$D,IF($C$4<>"",$C$4,"*"),Results!$U:$U,IF($C$3<>"",$C$3,"*"),Results!$T:$T,IF($D$3<>"",$D$3,"*"),Results!$V:$V,IF($F$3<>"",$F$3,"*"),Results!$F:$F,"Negative",Results!$H:$H,"Positive") -> 0 | D27: =COUNTIFS(Results!$D:$D,IF($C$4<>"",$C$4,"*"),Results!$U:$U,IF($C$3<>"",$C$3,"*"),Results!$T:$T,IF($D$3<>"",$D$3,"*"),Results!$V:$V,IF($F$3<>"",$F$3,"*"),Results!$F:$F,"Negative",Results!$H:$H,"Negative") -> 0 | E27: =COUNTIFS(Results!$D:$D,IF($C$4<>"",$C$4,"*"),Results!$U:$U,IF($C$3<>"",$C$3,"*"),Results!$T:$T,IF($D$3<>"",$D$3,"*"),Results!$V:$V,IF($F$3<>"",$F$3,"*"),Results!$F:$F,"=Negative",Results!$H:$H,"Unknown")+COUNTIFS(Results!$D:$D,IF($C$4<>"",$C$4,"*"),Results!$U:$U,IF($C$3<>"",$C$3,"*"),Results!$T:$T,IF($D$3<>"",$D$3,"*"),Results!$V:$V,IF($F$3<>"",$F$3,"*"),Results!$F:$F,"=Negative",Results!$H:$H,"=Not On Form")+COUNTIFS(Results!$D:$D,IF($C$4<>"",$C$4,"*"),Results!$U:$U,IF($C$3<>"",$C$3,"*"),Results!$T:$T,IF($D$3<>"",$D$3,"*"),Results!$V:$V,IF($F$3<>"",$F$3,"*"),Results!$F:$F,"=Negative",Results!$H:$H,"") -> 0 | F27: =C27+D27+E27 -> 0
B28: TB with NO RIF- Resistance | C28: =COUNTIFS(Results!$D:$D,IF($C$4<>"",$C$4,"*"),Results!$U:$U,IF($C$3<>"",$C$3,"*"),Results!$T:$T,IF($D$3<>"",$D$3,"*"),Results!$V:$V,IF($F$3<>"",$F$3,"*"),Results!$F:$F,"Positive",Results!$G:$G,"Negative",Results!$H:$H,"Positive") -> 0 | D28: =COUNTIFS(Results!$D:$D,IF($C$4<>"",$C$4,"*"),Results!$U:$U,IF($C$3<>"",$C$3,"*"),Results!$T:$T,IF($D$3<>"",$D$3,"*"),Results!$V:$V,IF($F$3<>"",$F$3,"*"),Results!$F:$F,"Positive",Results!$G:$G,"Negative",Results!$H:$H,"Negative") -> 0 | E28: =COUNTIFS(Results!$D:$D,IF($C$4<>"",$C$4,"*"),Results!$U:$U,IF($C$3<>"",$C$3,"*"),Results!$T:$T,IF($D$3<>"",$D$3,"*"),Results!$V:$V,IF($F$3<>"",$F$3,"*"),Results!$F:$F,"Positive",Results!$G:$G,"=Negative",Results!$H:$H,"Unknown")+COUNTIFS(Results!$D:$D,IF($C$4<>"",$C$4,"*"),Results!$U:$U,IF($C$3<>"",$C$3,"*"),Results!$T:$T,IF($D$3<>"",$D$3,"*"),Results!$V:$V,IF($F$3<>"",$F$3,"*"),Results!$F:$F,"Positive",Results!$G:$G,"=Negative",Results!$H:$H,"=Not On Form")+COUNTIFS(Results!$D:$D,IF($C$4<>"",$C$4,"*"),Results!$U:$U,IF($C$3<>"",$C$3,"*"),Results!$T:$T,IF($D$3<>"",$D$3,"*"),Results!$V:$V,IF($F$3<>"",$F$3,"*"),Results!$F:$F,"Positive",Results!$G:$G,"=Negative",Results!$H:$H,"") -> 0 | F28: =C28+D28+E28 -> 0
B29: TB with RIF- Resistance | C29: =COUNTIFS(Results!$D:$D,IF($C$4<>"",$C$4,"*"),Results!$U:$U,IF($C$3<>"",$C$3,"*"),Results!$T:$T,IF($D$3<>"",$D$3,"*"),Results!$V:$V,IF($F$3<>"",$F$3,"*"),Results!$F:$F,"Positive",Results!$G:$G,"Positive",Results!$H:$H,"Positive") -> 0 | D29: =COUNTIFS(Results!$D:$D,IF($C$4<>"",$C$4,"*"),Results!$U:$U,IF($C$3<>"",$C$3,"*"),Results!$T:$T,IF($D$3<>"",$D$3,"*"),Results!$V:$V,IF($F$3<>"",$F$3,"*"),Results!$F:$F,"Positive",Results!$G:$G,"Positive",Results!$H:$H,"Negative") -> 0 | E29: =COUNTIFS(Results!$D:$D,IF($C$4<>"",$C$4,"*"),Results!$U:$U,IF($C$3<>"",$C$3,"*"),Results!$T:$T,IF($D$3<>"",$D$3,"*"),Results!$V:$V,IF($F$3<>"",$F$3,"*"),Results!$F:$F,"Positive",Results!$G:$G,"=Positive",Results!$H:$H,"Unknown")+COUNTIFS(Results!$D:$D,IF($C$4<>"",$C$4,"*"),Results!$U:$U,IF($C$3<>"",$C$3,"*"),Results!$T:$T,IF($D$3<>"",$D$3,"*"),Results!$V:$V,IF($F$3<>"",$F$3,"*"),Results!$F:$F,"Positive",Results!$G:$G,"=Positive",Results!$H:$H,"=Not On Form")+COUNTIFS(Results!$D:$D,IF($C$4<>"",$C$4,"*"),Results!$U:$U,IF($C$3<>"",$C$3,"*"),Results!$T:$T,IF($D$3<>"",$D$3,"*"),Results!$V:$V,IF($F$3<>"",$F$3,"*"),Results!$F:$F,"Positive",Results!$G:$G,"=Positive",Results!$H:$H,"") -> 0 | F29: =C29+D29+E29 -> 0
B30: TB with RIF- Indeterminate | C30: =COUNTIFS(Results!$D:$D,IF($C$4<>"",$C$4,"*"),Results!$U:$U,IF($C$3<>"",$C$3,"*"),Results!$T:$T,IF($D$3<>"",$D$3,"*"),Results!$V:$V,IF($F$3<>"",$F$3,"*"),Results!$F:$F,"Positive",Results!$G:$G,"Indeterminate",Results!$H:$H,"Positive") -> 0 | D30: =COUNTIFS(Results!$D:$D,IF($C$4<>"",$C$4,"*"),Results!$U:$U,IF($C$3<>"",$C$3,"*"),Results!$T:$T,IF($D$3<>"",$D$3,"*"),Results!$V:$V,IF($F$3<>"",$F$3,"*"),Results!$F:$F,"Positive",Results!$G:$G,"Indeterminate",Results!$H:$H,"Negative") -> 0 | E30: =COUNTIFS(Results!$D:$D,IF($C$4<>"",$C$4,"*"),Results!$U:$U,IF($C$3<>"",$C$3,"*"),Results!$T:$T,IF($D$3<>"",$D$3,"*"),Results!$V:$V,IF($F$3<>"",$F$3,"*"),Results!$F:$F,"Positive",Results!$G:$G,"=Indeterminate",Results!$H:$H,"Unknown")+COUNTIFS(Results!$D:$D,IF($C$4<>"",$C$4,"*"),Results!$U:$U,IF($C$3<>"",$C$3,"*"),Results!$T:$T,IF($D$3<>"",$D$3,"*"),Results!$V:$V,IF($F$3<>"",$F$3,"*"),Results!$F:$F,"Positive",Results!$G:$G,"=Indeterminate",Results!$H:$H,"=Not On Form")+COUNTIFS(Results!$D:$D,IF($C$4<>"",$C$4,"*"),Results!$U:$U,IF($C$3<>"",$C$3,"*"),Results!$T:$T,IF($D$3<>"",$D$3,"*"),Results!$V:$V,IF($F$3<>"",$F$3,"*"),Results!$F:$F,"Positive",Results!$G:$G,"=Indeterminate",Results!$H:$H,"") -> 0 | F30: =C30+D30+E30 -> 0
B31: TB - Trace with RIF- Indeterminate | C31: =COUNTIFS(Results!$D:$D,IF($C$4<>"",$C$4,"*"),Results!$U:$U,IF($C$3<>"",$C$3,"*"),Results!$T:$T,IF($D$3<>"",$D$3,"*"),Results!$V:$V,IF($F$3<>"",$F$3,"*"),Results!$F:$F,"Trace",Results!$G:$G,"Indeterminate",Results!$H:$H,"Positive") -> 0 | D31: =COUNTIFS(Results!$D:$D,IF($C$4<>"",$C$4,"*"),Results!$U:$U,IF($C$3<>"",$C$3,"*"),Results!$T:$T,IF($D$3<>"",$D$3,"*"),Results!$V:$V,IF($F$3<>"",$F$3,"*"),Results!$F:$F,"Trace",Results!$G:$G,"Indeterminate",Results!$H:$H,"Negative") -> 0 | E31: =COUNTIFS(Results!$D:$D,IF($C$4<>"",$C$4,"*"),Results!$U:$U,IF($C$3<>"",$C$3,"*"),Results!$T:$T,IF($D$3<>"",$D$3,"*"),Results!$V:$V,IF($F$3<>"",$F$3,"*"),Results!$F:$F,"Trace",Results!$G:$G,"=Indeterminate",Results!$H:$H,"Unknown")+COUNTIFS(Results!$D:$D,IF($C$4<>"",$C$4,"*"),Results!$U:$U,IF($C$3<>"",$C$3,"*"),Results!$T:$T,IF($D$3<>"",$D$3,"*"),Results!$V:$V,IF($F$3<>"",$F$3,"*"),Results!$F:$F,"Trace",Results!$G:$G,"=Indeterminate",Results!$H:$H,"=Not On Form")+COUNTIFS(Results!$D:$D,IF($C$4<>"",$C$4,"*"),Results!$U:$U,IF($C$3<>"",$C$3,"*"),Results!$T:$T,IF($D$3<>"",$D$3,"*"),Results!$V:$V,IF($F$3<>"",$F$3,"*"),Results!$F:$F,"Positive",Results!$G:$G,"=Indeterminate",Results!$H:$H,"") -> 0 | F31: =C31+D31+E31 -> 0
A32: Total | C32: =SUM(C27:C31) -> 0 | D32: =SUM(D27:D31) -> 0 | E32: =SUM(E27:E31) -> 0 | F32: =SUM(F27:F31) -> 0
A34: 5. Test results and Test reason
C35: Dx | D35: Fu | E35: MDR | F35: DM | G35: Na | H35: Total
A36: Xpert MTB/RIF | B36: Negative | C36: =COUNTIFS(Results!$D:$D,IF($C$4<>"",$C$4,"*"),Results!$U:$U,IF($C$3<>"",$C$3,"*"),Results!$T:$T,IF($D$3<>"",$D$3,"*"),Results!$V:$V,IF($F$3<>"",$F$3,"*"),Results!$F:$F,"Negative",Results!$O:$O,"dx") -> 0 | D36: =COUNTIFS(Results!$D:$D,IF($C$4<>"",$C$4,"*"),Results!$U:$U,IF($C$3<>"",$C$3,"*"),Results!$T:$T,IF($D$3<>"",$D$3,"*"),Results!$V:$V,IF($F$3<>"",$F$3,"*"),Results!$F:$F,"Negative",Results!$O:$O,"fu") -> 0 | E36: =COUNTIFS(Results!$D:$D,IF($C$4<>"",$C$4,"*"),Results!$U:$U,IF($C$3<>"",$C$3,"*"),Results!$T:$T,IF($D$3<>"",$D$3,"*"),Results!$V:$V,IF($F$3<>"",$F$3,"*"),Results!$F:$F,"Negative",Results!$O:$O,"mdr") -> 0 | F36: =COUNTIFS(Results!$D:$D,IF($C$4<>"",$C$4,"*"),Results!$U:$U,IF($C$3<>"",$C$3,"*"),Results!$T:$T,IF($D$3<>"",$D$3,"*"),Results!$V:$V,IF($F$3<>"",$F$3,"*"),Results!$F:$F,"Negative",Results!$O:$O,"dm") -> 0 | G36: =COUNTIFS(Results!$D:$D,IF($C$4<>"",$C$4,"*"),Results!$U:$U,IF($C$3<>"",$C$3,"*"),Results!$T:$T,IF($D$3<>"",$D$3,"*"),Results!$V:$V,IF($F$3<>"",$F$3,"*"),Results!$F:$F,"Negative",Results!$O:$O,"na") -> 0 | H36: =SUM(C36:G36) -> 0
B37: TB with NO RIF- Resistance | C37: =COUNTIFS(Results!$D:$D,IF($C$4<>"",$C$4,"*"),Results!$U:$U,IF($C$3<>"",$C$3,"*"),Results!$T:$T,IF($D$3<>"",$D$3,"*"),Results!$V:$V,IF($F$3<>"",$F$3,"*"),Results!$F:$F,"Positive",Results!$G:$G,"Negative",Results!$O:$O,"dx") -> 0 | D37: =COUNTIFS(Results!$D:$D,IF($C$4<>"",$C$4,"*"),Results!$U:$U,IF($C$3<>"",$C$3,"*"),Results!$T:$T,IF($D$3<>"",$D$3,"*"),Results!$V:$V,IF($F$3<>"",$F$3,"*"),Results!$F:$F,"Positive",Results!$G:$G,"Negative",Results!$O:$O,"fu") -> 0 | E37: =COUNTIFS(Results!$D:$D,IF($C$4<>"",$C$4,"*"),Results!$U:$U,IF($C$3<>"",$C$3,"*"),Results!$T:$T,IF($D$3<>"",$D$3,"*"),Results!$V:$V,IF($F$3<>"",$F$3,"*"),Results!$F:$F,"Positive",Results!$G:$G,"Negative",Results!$O:$O,"mdr") -> 0 | F37: =COUNTIFS(Results!$D:$D,IF($C$4<>"",$C$4,"*"),Results!$U:$U,IF($C$3<>"",$C$3,"*"),Results!$T:$T,IF($D$3<>"",$D$3,"*"),Results!$V:$V,IF($F$3<>"",$F$3,"*"),Results!$F:$F,"Positive",Results!$G:$G,"Negative",Results!$O:$O,"dm") -> 0 | G37: =COUNTIFS(Results!$D:$D,IF($C$4<>"",$C$4,"*"),Results!$U:$U,IF($C$3<>"",$C$3,"*"),Results!$T:$T,IF($D$3<>"",$D$3,"*"),Results!$V:$V,IF($F$3<>"",$F$3,"*"),Results!$F:$F,"Positive",Results!$G:$G,"Negative",Results!$O:$O,"na") -> 0 | H37: =SUM(C37:G37) -> 0
B38: TB with RIF- Resistance | C38: =COUNTIFS(Results!$D:$D,IF($C$4<>"",$C$4,"*"),Results!$U:$U,IF($C$3<>"",$C$3,"*"),Results!$T:$T,IF($D$3<>"",$D$3,"*"),Results!$V:$V,IF($F$3<>"",$F$3,"*"),Results!$F:$F,"Positive",Results!$G:$G,"Positive",Results!$O:$O,"dx") -> 0 | D38: =COUNTIFS(Results!$D:$D,IF($C$4<>"",$C$4,"*"),Results!$U:$U,IF($C$3<>"",$C$3,"*"),Results!$T:$T,IF($D$3<>"",$D$3,"*"),Results!$V:$V,IF($F$3<>"",$F$3,"*"),Results!$F:$F,"Positive",Results!$G:$G,"Positive",Results!$O:$O,"fu") -> 0 | E38: =COUNTIFS(Results!$D:$D,IF($C$4<>"",$C$4,"*"),Results!$U:$U,IF($C$3<>"",$C$3,"*"),Results!$T:$T,IF($D$3<>"",$D$3,"*"),Results!$V:$V,IF($F$3<>"",$F$3,"*"),Results!$F:$F,"Positive",Results!$G:$G,"Positive",Results!$O:$O,"mdr") -> 0 | F38: =COUNTIFS(Results!$D:$D,IF($C$4<>"",$C$4,"*"),Results!$U:$U,IF($C$3<>"",$C$3,"*"),Results!$T:$T,IF($D$3<>"",$D$3,"*"),Results!$V:$V,IF($F$3<>"",$F$3,"*"),Results!$F:$F,"Positive",Results!$G:$G,"Positive",Results!$O:$O,"dm") -> 0 | G38: =COUNTIFS(Results!$D:$D,IF($C$4<>"",$C$4,"*"),Results!$U:$U,IF($C$3<>"",$C$3,"*"),Results!$T:$T,IF($D$3<>"",$D$3,"*"),Results!$V:$V,IF($F$3<>"",$F$3,"*"),Results!$F:$F,"Positive",Results!$G:$G,"Positive",Results!$O:$O,"na") -> 0 | H38: =SUM(C38:G38) -> 0
B39: TB with RIF- Indeterminate | C39: =COUNTIFS(Results!$D:$D,IF($C$4<>"",$C$4,"*"),Results!$U:$U,IF($C$3<>"",$C$3,"*"),Results!$T:$T,IF($D$3<>"",$D$3,"*"),Results!$V:$V,IF($F$3<>"",$F$3,"*"),Results!$F:$F,"Positive",Results!$G:$G,"Indeterminate",Results!$O:$O,"dx") -> 0 | D39: =COUNTIFS(Results!$D:$D,IF($C$4<>"",$C$4,"*"),Results!$U:$U,IF($C$3<>"",$C$3,"*"),Results!$T:$T,IF($D$3<>"",$D$3,"*"),Results!$V:$V,IF($F$3<>"",$F$3,"*"),Results!$F:$F,"Positive",Results!$G:$G,"Indeterminate",Results!$O:$O,"fu") -> 0 | E39: =COUNTIFS(Results!$D:$D,IF($C$4<>"",$C$4,"*"),Results!$U:$U,IF($C$3<>"",$C$3,"*"),Results!$T:$T,IF($D$3<>"",$D$3,"*"),Results!$V:$V,IF($F$3<>"",$F$3,"*"),Results!$F:$F,"Positive",Results!$G:$G,"Indeterminate",Results!$O:$O,"mdr") -> 0 | F39: =COUNTIFS(Results!$D:$D,IF($C$4<>"",$C$4,"*"),Results!$U:$U,IF($C$3<>"",$C$3,"*"),Results!$T:$T,IF($D$3<>"",$D$3,"*"),Results!$V:$V,IF($F$3<>"",$F$3,"*"),Results!$F:$F,"Positive",Results!$G:$G,"Indeterminate",Results!$O:$O,"dm") -> 0 | G39: =COUNTIFS(Results!$D:$D,IF($C$4<>"",$C$4,"*"),Results!$U:$U,IF($C$3<>"",$C$3,"*"),Results!$T:$T,IF($D$3<>"",$D$3,"*"),Results!$V:$V,IF($F$3<>"",$F$3,"*"),Results!$F:$F,"Positive",Results!$G:$G,"Indeterminate",Results!$O:$O,"na") -> 0 | H39: =SUM(C39:G39) -> 0
B40: TB - Trace with RIF- Indeterminate | C40: =COUNTIFS(Results!$D:$D,IF($C$4<>"",$C$4,"*"),Results!$U:$U,IF($C$3<>"",$C$3,"*"),Results!$T:$T,IF($D$3<>"",$D$3,"*"),Results!$V:$V,IF($F$3<>"",$F$3,"*"),Results!$F:$F,"Trace",Results!$G:$G,"Indeterminate",Results!$O:$O,"dx") -> 0 | D40: =COUNTIFS(Results!$D:$D,IF($C$4<>"",$C$4,"*"),Results!$U:$U,IF($C$3<>"",$C$3,"*"),Results!$T:$T,IF($D$3<>"",$D$3,"*"),Results!$V:$V,IF($F$3<>"",$F$3,"*"),Results!$F:$F,"Trace",Results!$G:$G,"Indeterminate",Results!$O:$O,"fu") -> 0 | E40: =COUNTIFS(Results!$D:$D,IF($C$4<>"",$C$4,"*"),Results!$U:$U,IF($C$3<>"",$C$3,"*"),Results!$T:$T,IF($D$3<>"",$D$3,"*"),Results!$V:$V,IF($F$3<>"",$F$3,"*"),Results!$F:$F,"Trace",Results!$G:$G,"Indeterminate",Results!$O:$O,"mdr") -> 0 | F40: =COUNTIFS(Results!$D:$D,IF($C$4<>"",$C$4,"*"),Results!$U:$U,IF($C$3<>"",$C$3,"*"),Results!$T:$T,IF($D$3<>"",$D$3,"*"),Results!$V:$V,IF($F$3<>"",$F$3,"*"),Results!$F:$F,"Trace",Results!$G:$G,"Indeterminate",Results!$O:$O,"dm") -> 0 | G40: =COUNTIFS(Results!$D:$D,IF($C$4<>"",$C$4,"*"),Results!$U:$U,IF($C$3<>"",$C$3,"*"),Results!$T:$T,IF($D$3<>"",$D$3,"*"),Results!$V:$V,IF($F$3<>"",$F$3,"*"),Results!$F:$F,"Trace",Results!$G:$G,"Indeterminate",Results!$O:$O,"na") -> 0 | H40: =SUM(C40:G40) -> 0
A41: Total | C41: =SUM(C36:C40) -> 0 | D41: =SUM(D36:D40) -> 0 | E41: =SUM(E36:E40) -> 0 | F41: =SUM(F36:F40) -> 0 | G41: =SUM(G36:G40) -> 0 | H41: =SUM(H36:H40) -> 0
C43: Male | E43: Female | G43: Total
A44: 6. TB with Rif-Resistance detected | C44: =COUNTIFS(Results!$D:$D,IF($C$4<>"",$C$4,"*"),Results!$U:$U,IF($C$3<>"",$C$3,"*"),Results!$T:$T,IF($D$3<>"",$D$3,"*"),Results!$V:$V,IF($F$3<>"",$F$3,"*"),Results!$I:$I,"=Male",Results!$F:$F,"=Positive",Results!$G:$G,"=Positive")+COUNTIFS(Results!$D:$D,IF($C$4<>"",$C$4,"*"),Results!$U:$U,IF($C$3<>"",$C$3,"*"),Results!$T:$T,IF($D$3<>"",$D$3,"*"),Results!$V:$V,IF($F$3<>"",$F$3,"*"),Results!$I:$I,"=M",Results!$F:$F,"=Positive",Results!$G:$G,"=Positive") -> 0 | D44: 0 | E44: =COUNTIFS(Results!$D:$D,IF($C$4<>"",$C$4,"*"),Results!$U:$U,IF($C$3<>"",$C$3,"*"),Results!$T:$T,IF($D$3<>"",$D$3,"*"),Results!$V:$V,IF($F$3<>"",$F$3,"*"),Results!$I:$I,"=Female",Results!$F:$F,"=Positive",Results!$G:$G,"=Positive")+COUNTIFS(Results!$D:$D,IF($C$4<>"",$C$4,"*"),Results!$U:$U,IF($C$3<>"",$C$3,"*"),Results!$T:$T,IF($D$3<>"",$D$3,"*"),Results!$V:$V,IF($F$3<>"",$F$3,"*"),Results!$I:$I,"=F",Results!$F:$F,"=Positive",Results!$G:$G,"=Positive") -> 0 | F44: 0 | G44: =C44+E44 -> 0
A46: 7. Compare with sputum microscopy
...

Sheet Feb
A1: GeneXpert MTB/RIF Testing Report
C2: Quarter | D2: Month | F2: Year
A3: Reporting Period | C3: 1st Quarter | D3: February | F3: =YEAR(Results!E3) -> #VALUE!
A4: Reporting Unit
H5: Note: Press Ctrl + Alt + Shift + F9 to see the results in the cells.
A6: 1. Age and sex distribution of tested patients
B7: Male | D7: Female | F7: Total
B8: <15 | C8: >=15 | D8: <15 | E8: >=15
B9: =COUNTIFS(Results!$D:$D,IF($C$4<>"",$C$4,"*"),Results!$U:$U,IF($C$3<>"",$C$3,"*"),Results!$T:$T,IF($D$3<>"",$D$3,"*"),Results!$V:$V,IF($F$3<>"",$F$3,"*"),Results!$I:$I,"=Male",Results!$J:$J,"<15")+COUNTIFS(Results!$D:$D,IF($C$4<>"",$C$4,"*"),Results!$U:$U,IF($C$3<>"",$C$3,"*"),Results!$T:$T,IF($D$3<>"",$D$3,"*"),Results!$V:$V,IF($F$3<>"",$F$3,"*"),Results!$I:$I,"=M",Results!$J:$J,"<15") -> 0 | C9: =COUNTIFS(Results!$D:$D,IF($C$4<>"",$C$4,"*"),Results!$U:$U,IF($C$3<>"",$C$3,"*"),Results!$T:$T,IF($D$3<>"",$D$3,"*"),Results!$V:$V,IF($F$3<>"",$F$3,"*"),Results!$I:$I,"=Male",Results!$J:$J,">=15")+COUNTIFS(Results!$D:$D,IF($C$4<>"",$C$4,"*"),Results!$U:$U,IF($C$3<>"",$C$3,"*"),Results!$T:$T,IF($D$3<>"",$D$3,"*"),Results!$V:$V,IF($F$3<>"",$F$3,"*"),Results!$I:$I,"=M",Results!$J:$J,">=15") -> 0 | D9: =COUNTIFS(Results!$D:$D,IF($C$4<>"",$C$4,"*"),Results!$U:$U,IF($C$3<>"",$C$3,"*"),Results!$T:$T,IF($D$3<>"",$D$3,"*"),Results!$V:$V,IF($F$3<>"",$F$3,"*"),Results!$I:$I,"=Female",Results!$J:$J,"<15")+COUNTIFS(Results!$D:$D,IF($C$4<>"",$C$4,"*"),Results!$U:$U,IF($C$3<>"",$C$3,"*"),Results!$T:$T,IF($D$3<>"",$D$3,"*"),Results!$V:$V,IF($F$3<>"",$F$3,"*"),Results!$I:$I,"=F",Results!$J:$J,"<15") -> 0 | E9: =COUNTIFS(Results!$D:$D,IF($C$4<>"",$C$4,"*"),Results!$U:$U,IF($C$3<>"",$C$3,"*"),Results!$T:$T,IF($D$3<>"",$D$3,"*"),Results!$V:$V,IF($F$3<>"",$F$3,"*"),Results!$I:$I,"=Female",Results!$J:$J,">=15")+COUNTIFS(Results!$D:$D,IF($C$4<>"",$C$4,"*"),Results!$U:$U,IF($C$3<>"",$C$3,"*"),Results!$T:$T,IF($D$3<>"",$D$3,"*"),Results!$V:$V,IF($F$3<>"",$F$3,"*"),Results!$I:$I,"=F",Results!$J:$J,">=15") -> 0 | F9: =B9+C9+D9+E9 -> 0
A11: 2. Age and sex distribution of completed test
B12: Male | D12: Female | F12: Total
B13: <15 | C13: >=15 | D13: <15 | E13: >=15
B14: =COUNTIFS(Results!$D:$D,IF($C$4<>"",$C$4,"*"),Results!$U:$U,IF($C$3<>"",$C$3,"*"),Results!$T:$T,IF($D$3<>"",$D$3,"*"),Results!$V:$V,IF($F$3<>"",$F$3,"*"),Results!$F:$F,"<>Error",Results!$F:$F,"<>Invalid",Results!$F:$F,"<>No result",Results!$I:$I,"=Male",Results!$J:$J,"<15")+COUNTIFS(Results!$D:$D,IF($C$4<>"",$C$4,"*"),Results!$U:$U,IF($C$3<>"",$C$3,"*"),Results!$T:$T,IF($D$3<>"",$D$3,"*"),Results!$V:$V,IF($F$3<>"",$F$3,"*"),Results!$F:$F,"<>Error",Results!$F:$F,"<>Invalid",Results!$F:$F,"<>No result",Results!$I:$I,"=M",Results!$J:$J,"<15") -> 0 | C14: =COUNTIFS(Results!$D:$D,IF($C$4<>"",$C$4,"*"),Results!$U:$U,IF($C$3<>"",$C$3,"*"),Results!$T:$T,IF($D$3<>"",$D$3,"*"),Results!$V:$V,IF($F$3<>"",$F$3,"*"),Results!$F:$F,"<>Error",Results!$F:$F,"<>Invalid",Results!$F:$F,"<>No result",Results!$I:$I,"=Male",Results!$J:$J,">=15")+COUNTIFS(Results!$D:$D,IF($C$4<>"",$C$4,"*"),Results!$U:$U,IF($C$3<>"",$C$3,"*"),Results!$T:$T,IF($D$3<>"",$D$3,"*"),Results!$V:$V,IF($F$3<>"",$F$3,"*"),Results!$F:$F,"<>Error",Results!$F:$F,"<>Invalid",Results!$F:$F,"<>No result",Results!$I:$I,"=M",Results!$J:$J,">=15") -> 0 | D14: =COUNTIFS(Results!$D:$D,IF($C$4<>"",$C$4,"*"),Results!$U:$U,IF($C$3<>"",$C$3,"*"),Results!$T:$T,IF($D$3<>"",$D$3,"*"),Results!$V:$V,IF($F$3<>"",$F$3,"*"),Results!$F:$F,"<>Error",Results!$F:$F,"<>Invalid",Results!$F:$F,"<>No result",Results!$I:$I,"=Female",Results!$J:$J,"<15")+COUNTIFS(Results!$D:$D,IF($C$4<>"",$C$4,"*"),Results!$U:$U,IF($C$3<>"",$C$3,"*"),Results!$T:$T,IF($D$3<>"",$D$3,"*"),Results!$V:$V,IF($F$3<>"",$F$3,"*"),Results!$F:$F,"<>Error",Results!$F:$F,"<>Invalid",Results!$F:$F,"<>No result",Results!$I:$I,"=F",Results!$J:$J,"<15") -> 0 | E14: =COUNTIFS(Results!$D:$D,IF($C$4<>"",$C$4,"*"),Results!$U:$U,IF($C$3<>"",$C$3,"*"),Results!$T:$T,IF($D$3<>"",$D$3,"*"),Results!$V:$V,IF($F$3<>"",$F$3,"*"),Results!$F:$F,"<>Error",Results!$F:$F,"<>Invalid",Results!$F:$F,"<>No result",Results!$I:$I,"=Female",Results!$J:$J,">=15")+COUNTIFS(Results!$D:$D,IF($C$4<>"",$C$4,"*"),Results!$U:$U,IF($C$3<>"",$C$3,"*"),Results!$T:$T,IF($D$3<>"",$D$3,"*"),Results!$V:$V,IF($F$3<>"",$F$3,"*"),Results!$F:$F,"<>Error",Results!$F:$F,"<>Invalid",Results!$F:$F,"<>No result",Results!$I:$I,"=F",Results!$J:$J,">=15") -> 0 | F14: =B14+C14+D14+E14 -> 0
A16: 3. Test results and previous history of TB
C17: New | D17: Retreatment | E17: Unknown | F17: Total
A18: Xpert MTB/RIF | B18: Negative | C18: =COUNTIFS(Results!$D:$D,IF($C$4<>"",$C$4,"*"),Results!$U:$U,IF($C$3<>"",$C$3,"*"),Results!$T:$T,IF($D$3<>"",$D$3,"*"),Results!$V:$V,IF($F$3<>"",$F$3,"*"),Results!$F:$F,"Negative",Results!$K:$K,"No") -> 0 | D18: =COUNTIFS(Results!$D:$D,IF($C$4<>"",$C$4,"*"),Results!$U:$U,IF($C$3<>"",$C$3,"*"),Results!$T:$T,IF($D$3<>"",$D$3,"*"),Results!$V:$V,IF($F$3<>"",$F$3,"*"),Results!$F:$F,"Negative",Results!$K:$K,"Yes") -> 0 | E18: =COUNTIFS(Results!$D:$D,IF($C$4<>"",$C$4,"*"),Results!$U:$U,IF($C$3<>"",$C$3,"*"),Results!$T:$T,IF($D$3<>"",$D$3,"*"),Results!$V:$V,IF($F$3<>"",$F$3,"*"),Results!$F:$F,"=Negative",Results!$K:$K,"Unknown")+COUNTIFS(Results!$D:$D,IF($C$4<>"",$C$4,"*"),Results!$U:$U,IF($C$3<>"",$C$3,"*"),Results!$T:$T,IF($D$3<>"",$D$3,"*"),Results!$V:$V,IF($F$3<>"",$F$3,"*"),Results!$F:$F,"=Negative",Results!$K:$K,"N/A")+COUNTIFS(Results!$D:$D,IF($C$4<>"",$C$4,"*"),Results!$U:$U,IF($C$3<>"",$C$3,"*"),Results!$T:$T,IF($D$3<>"",$D$3,"*"),Results!$V:$V,IF($F$3<>"",$F$3,"*"),Results!$F:$F,"=Negative",Results!$K:$K,"") -> 0 | F18: =C18+D18+E18 -> 0
B19: TB with No RIF- Resistance | C19: =COUNTIFS(Results!$D:$D,IF($C$4<>"",$C$4,"*"),Results!$U:$U,IF($C$3<>"",$C$3,"*"),Results!$T:$T,IF($D$3<>"",$D$3,"*"),Results!$V:$V,IF($F$3<>"",$F$3,"*"),Results!$F:$F,"Positive",Results!$G:$G,"Negative",Results!$K:$K,"No") -> 0 | D19: =COUNTIFS(Results!$D:$D,IF($C$4<>"",$C$4,"*"),Results!$U:$U,IF($C$3<>"",$C$3,"*"),Results!$T:$T,IF($D$3<>"",$D$3,"*"),Results!$V:$V,IF($F$3<>"",$F$3,"*"),Results!$F:$F,"Positive",Results!$G:$G,"Negative",Results!$K:$K,"Yes") -> 0 | E19: =COUNTIFS(Results!$D:$D,IF($C$4<>"",$C$4,"*"),Results!$U:$U,IF($C$3<>"",$C$3,"*"),Results!$T:$T,IF($D$3<>"",$D$3,"*"),Results!$V:$V,IF($F$3<>"",$F$3,"*"),Results!$F:$F,"Positive",Results!$G:$G,"=Negative",Results!$K:$K,"Unknown")+COUNTIFS(Results!$D:$D,IF($C$4<>"",$C$4,"*"),Results!$U:$U,IF($C$3<>"",$C$3,"*"),Results!$T:$T,IF($D$3<>"",$D$3,"*"),Results!$V:$V,IF($F$3<>"",$F$3,"*"),Results!$F:$F,"Positive",Results!$G:$G,"=Negative",Results!$K:$K,"N/A")+COUNTIFS(Results!$D:$D,IF($C$4<>"",$C$4,"*"),Results!$U:$U,IF($C$3<>"",$C$3,"*"),Results!$T:$T,IF($D$3<>"",$D$3,"*"),Results!$V:$V,IF($F$3<>"",$F$3,"*"),Results!$F:$F,"Positive",Results!$G:$G,"=Negative",Results!$K:$K,"") -> 0 | F19: =C19+D19+E19 -> 0
B20: TB with RIF- Resistance | C20: =COUNTIFS(Results!$D:$D,IF($C$4<>"",$C$4,"*"),Results!$U:$U,IF($C$3<>"",$C$3,"*"),Results!$T:$T,IF($D$3<>"",$D$3,"*"),Results!$V:$V,IF($F$3<>"",$F$3,"*"),Results!$F:$F,"Positive",Results!$G:$G,"Positive",Results!$K:$K,"No") -> 0 | D20: =COUNTIFS(Results!$D:$D,IF($C$4<>"",$C$4,"*"),Results!$U:$U,IF($C$3<>"",$C$3,"*"),Results!$T:$T,IF($D$3<>"",$D$3,"*"),Results!$V:$V,IF($F$3<>"",$F$3,"*"),Results!$F:$F,"Positive",Results!$G:$G,"Positive",Results!$K:$K,"Yes") -> 0 | E20: =COUNTIFS(Results!$D:$D,IF($C$4<>"",$C$4,"*"),Results!$U:$U,IF($C$3<>"",$C$3,"*"),Results!$T:$T,IF($D$3<>"",$D$3,"*"),Results!$V:$V,IF($F$3<>"",$F$3,"*"),Results!$F:$F,"Positive",Results!$G:$G,"=Positive",Results!$K:$K,"Unknown")+COUNTIFS(Results!$D:$D,IF($C$4<>"",$C$4,"*"),Results!$U:$U,IF($C$3<>"",$C$3,"*"),Results!$T:$T,IF($D$3<>"",$D$3,"*"),Results!$V:$V,IF($F$3<>"",$F$3,"*"),Results!$F:$F,"Positive",Results!$G:$G,"=Positive",Results!$K:$K,"N/A")+COUNTIFS(Results!$D:$D,IF($C$4<>"",$C$4,"*"),Results!$U:$U,IF($C$3<>"",$C$3,"*"),Results!$T:$T,IF($D$3<>"",$D$3,"*"),Results!$V:$V,IF($F$3<>"",$F$3,"*"),Results!$F:$F,"Positive",Results!$G:$G,"=Positive",Results!$K:$K,"") -> 0 | F20: =C20+D20+E20 -> 0
B21: TB with RIF- Indeterminate | C21: =COUNTIFS(Results!$D:$D,IF($C$4<>"",$C$4,"*"),Results!$U:$U,IF($C$3<>"",$C$3,"*"),Results!$T:$T,IF($D$3<>"",$D$3,"*"),Results!$V:$V,IF($F$3<>"",$F$3,"*"),Results!$F:$F,"Positive",Results!$G:$G,"Indeterminate",Results!$K:$K,"No") -> 0 | D21: =COUNTIFS(Results!$D:$D,IF($C$4<>"",$C$4,"*"),Results!$U:$U,IF($C$3<>"",$C$3,"*"),Results!$T:$T,IF($D$3<>"",$D$3,"*"),Results!$V:$V,IF($F$3<>"",$F$3,"*"),Results!$F:$F,"Positive",Results!$G:$G,"Indeterminate",Results!$K:$K,"Yes") -> 0 | E21: =COUNTIFS(Results!$D:$D,IF($C$4<>"",$C$4,"*"),Results!$U:$U,IF($C$3<>"",$C$3,"*"),Results!$T:$T,IF($D$3<>"",$D$3,"*"),Results!$V:$V,IF($F$3<>"",$F$3,"*"),Results!$F:$F,"Positive",Results!$G:$G,"=Indeterminate",Results!$K:$K,"Unknown")+COUNTIFS(Results!$D:$D,IF($C$4<>"",$C$4,"*"),Results!$U:$U,IF($C$3<>"",$C$3,"*"),Results!$T:$T,IF($D$3<>"",$D$3,"*"),Results!$V:$V,IF($F$3<>"",$F$3,"*"),Results!$F:$F,"Positive",Results!$G:$G,"=Indeterminate",Results!$K:$K,"N/A")+COUNTIFS(Results!$D:$D,IF($C$4<>"",$C$4,"*"),Results!$U:$U,IF($C$3<>"",$C$3,"*"),Results!$T:$T,IF($D$3<>"",$D$3,"*"),Results!$V:$V,IF($F$3<>"",$F$3,"*"),Results!$F:$F,"Positive",Results!$G:$G,"=Indeterminate",Results!$K:$K,"") -> 0 | F21: =C21+D21+E21 -> 0
B22: TB - Trace with RIF- Indeterminate | C22: =COUNTIFS(Results!$D:$D,IF($C$4<>"",$C$4,"*"),Results!$U:$U,IF($C$3<>"",$C$3,"*"),Results!$T:$T,IF($D$3<>"",$D$3,"*"),Results!$V:$V,IF($F$3<>"",$F$3,"*"),Results!$F:$F,"Trace",Results!$G:$G,"Indeterminate",Results!$K:$K,"No") -> 0 | D22: =COUNTIFS(Results!$D:$D,IF($C$4<>"",$C$4,"*"),Results!$U:$U,IF($C$3<>"",$C$3,"*"),Results!$T:$T,IF($D$3<>"",$D$3,"*"),Results!$V:$V,IF($F$3<>"",$F$3,"*"),Results!$F:$F,"Trace",Results!$G:$G,"Indeterminate",Results!$K:$K,"Yes") -> 0 | E22: =COUNTIFS(Results!$D:$D,IF($C$4<>"",$C$4,"*"),Results!$U:$U,IF($C$3<>"",$C$3,"*"),Results!$T:$T,IF($D$3<>"",$D$3,"*"),Results!$V:$V,IF($F$3<>"",$F$3,"*"),Results!$F:$F,"Trace",Results!$G:$G,"=Indeterminate",Results!$K:$K,"Unknown")+COUNTIFS(Results!$D:$D,IF($C$4<>"",$C$4,"*"),Results!$U:$U,IF($C$3<>"",$C$3,"*"),Results!$T:$T,IF($D$3<>"",$D$3,"*"),Results!$V:$V,IF($F$3<>"",$F$3,"*"),Results!$F:$F,"Trace",Results!$G:$G,"=Indeterminate",Results!$K:$K,"N/A")+COUNTIFS(Results!$D:$D,IF($C$4<>"",$C$4,"*"),Results!$U:$U,IF($C$3<>"",$C$3,"*"),Results!$T:$T,IF($D$3<>"",$D$3,"*"),Results!$V:$V,IF($F$3<>"",$F$3,"*"),Results!$F:$F,"Trace",Results!$G:$G,"=Indeterminate",Results!$K:$K,"") -> 0 | F22: =C22+D22+E22 -> 0
A23: Total | C23: =SUM(C18:C22) -> 0 | D23: =SUM(D18:D22) -> 0 | E23: =SUM(E18:E22) -> 0 | F23: =SUM(F18:F22) -> 0
A25: 4. Test results and HIV status
C26: HIV (+) | D26: HIV (-) | E26: Unknown | F26: Total
A27: Xpert MTB/RIF | B27: Negative | C27: =COUNTIFS(Results!$D:$D,IF($C$4<>"",$C$4,"*"),Results!$U:$U,IF($C$3<>"",$C$3,"*"),Results!$T:$T,IF($D$3<>"",$D$3,"*"),Results!$V:$V,IF($F$3<>"",$F$3,"*"),Results!$F:$F,"Negative",Results!$H:$H,"Positive") -> 0 | D27: =COUNTIFS(Results!$D:$D,IF($C$4<>"",$C$4,"*"),Results!$U:$U,IF($C$3<>"",$C$3,"*"),Results!$T:$T,IF($D$3<>"",$D$3,"*"),Results!$V:$V,IF($F$3<>"",$F$3,"*"),Results!$F:$F,"Negative",Results!$H:$H,"Negative") -> 0 | E27: =COUNTIFS(Results!$D:$D,IF($C$4<>"",$C$4,"*"),Results!$U:$U,IF($C$3<>"",$C$3,"*"),Results!$T:$T,IF($D$3<>"",$D$3,"*"),Results!$V:$V,IF($F$3<>"",$F$3,"*"),Results!$F:$F,"=Negative",Results!$H:$H,"Unknown")+COUNTIFS(Results!$D:$D,IF($C$4<>"",$C$4,"*"),Results!$U:$U,IF($C$3<>"",$C$3,"*"),Results!$T:$T,IF($D$3<>"",$D$3,"*"),Results!$V:$V,IF($F$3<>"",$F$3,"*"),Results!$F:$F,"=Negative",Results!$H:$H,"=Not On Form")+COUNTIFS(Results!$D:$D,IF($C$4<>"",$C$4,"*"),Results!$U:$U,IF($C$3<>"",$C$3,"*"),Results!$T:$T,IF($D$3<>"",$D$3,"*"),Results!$V:$V,IF($F$3<>"",$F$3,"*"),Results!$F:$F,"=Negative",Results!$H:$H,"") -> 0 | F27: =C27+D27+E27 -> 0
B28: TB with NO RIF- Resistance | C28: =COUNTIFS(Results!$D:$D,IF($C$4<>"",$C$4,"*"),Results!$U:$U,IF($C$3<>"",$C$3,"*"),Results!$T:$T,IF($D$3<>"",$D$3,"*"),Results!$V:$V,IF($F$3<>"",$F$3,"*"),Results!$F:$F,"Positive",Results!$G:$G,"Negative",Results!$H:$H,"Positive") -> 0 | D28: =COUNTIFS(Results!$D:$D,IF($C$4<>"",$C$4,"*"),Results!$U:$U,IF($C$3<>"",$C$3,"*"),Results!$T:$T,IF($D$3<>"",$D$3,"*"),Results!$V:$V,IF($F$3<>"",$F$3,"*"),Results!$F:$F,"Positive",Results!$G:$G,"Negative",Results!$H:$H,"Negative") -> 0 | E28: =COUNTIFS(Results!$D:$D,IF($C$4<>"",$C$4,"*"),Results!$U:$U,IF($C$3<>"",$C$3,"*"),Results!$T:$T,IF($D$3<>"",$D$3,"*"),Results!$V:$V,IF($F$3<>"",$F$3,"*"),Results!$F:$F,"Positive",Results!$G:$G,"=Negative",Results!$H:$H,"Unknown")+COUNTIFS(Results!$D:$D,IF($C$4<>"",$C$4,"*"),Results!$U:$U,IF($C$3<>"",$C$3,"*"),Results!$T:$T,IF($D$3<>"",$D$3,"*"),Results!$V:$V,IF($F$3<>"",$F$3,"*"),Results!$F:$F,"Positive",Results!$G:$G,"=Negative",Results!$H:$H,"=Not On Form")+COUNTIFS(Results!$D:$D,IF($C$4<>"",$C$4,"*"),Results!$U:$U,IF($C$3<>"",$C$3,"*"),Results!$T:$T,IF($D$3<>"",$D$3,"*"),Results!$V:$V,IF($F$3<>"",$F$3,"*"),Results!$F:$F,"Positive",Results!$G:$G,"=Negative",Results!$H:$H,"") -> 0 | F28: =C28+D28+E28 -> 0
B29: TB with RIF- Resistance | C29: =COUNTIFS(Results!$D:$D,IF($C$4<>"",$C$4,"*"),Results!$U:$U,IF($C$3<>"",$C$3,"*"),Results!$T:$T,IF($D$3<>"",$D$3,"*"),Results!$V:$V,IF($F$3<>"",$F$3,"*"),Results!$F:$F,"Positive",Results!$G:$G,"Positive",Results!$H:$H,"Positive") -> 0 | D29: =COUNTIFS(Results!$D:$D,IF($C$4<>"",$C$4,"*"),Results!$U:$U,IF($C$3<>"",$C$3,"*"),Results!$T:$T,IF($D$3<>"",$D$3,"*"),Results!$V:$V,IF($F$3<>"",$F$3,"*"),Results!$F:$F,"Positive",Results!$G:$G,"Positive",Results!$H:$H,"Negative") -> 0 | E29: =COUNTIFS(Results!$D:$D,IF($C$4<>"",$C$4,"*"),Results!$U:$U,IF($C$3<>"",$C$3,"*"),Results!$T:$T,IF($D$3<>"",$D$3,"*"),Results!$V:$V,IF($F$3<>"",$F$3,"*"),Results!$F:$F,"Positive",Results!$G:$G,"=Positive",Results!$H:$H,"Unknown")+COUNTIFS(Results!$D:$D,IF($C$4<>"",$C$4,"*"),Results!$U:$U,IF($C$3<>"",$C$3,"*"),Results!$T:$T,IF($D$3<>"",$D$3,"*"),Results!$V:$V,IF($F$3<>"",$F$3,"*"),Results!$F:$F,"Positive",Results!$G:$G,"=Positive",Results!$H:$H,"=Not On Form")+COUNTIFS(Results!$D:$D,IF($C$4<>"",$C$4,"*"),Results!$U:$U,IF($C$3<>"",$C$3,"*"),Results!$T:$T,IF($D$3<>"",$D$3,"*"),Results!$V:$V,IF($F$3<>"",$F$3,"*"),Results!$F:$F,"Positive",Results!$G:$G,"=Positive",Results!$H:$H,"") -> 0 | F29: =C29+D29+E29 -> 0
B30: TB with RIF- Indeterminate | C30: =COUNTIFS(Results!$D:$D,IF($C$4<>"",$C$4,"*"),Results!$U:$U,IF($C$3<>"",$C$3,"*"),Results!$T:$T,IF($D$3<>"",$D$3,"*"),Results!$V:$V,IF($F$3<>"",$F$3,"*"),Results!$F:$F,"Positive",Results!$G:$G,"Indeterminate",Results!$H:$H,"Positive") -> 0 | D30: =COUNTIFS(Results!$D:$D,IF($C$4<>"",$C$4,"*"),Results!$U:$U,IF($C$3<>"",$C$3,"*"),Results!$T:$T,IF($D$3<>"",$D$3,"*"),Results!$V:$V,IF($F$3<>"",$F$3,"*"),Results!$F:$F,"Positive",Results!$G:$G,"Indeterminate",Results!$H:$H,"Negative") -> 0 | E30: =COUNTIFS(Results!$D:$D,IF($C$4<>"",$C$4,"*"),Results!$U:$U,IF($C$3<>"",$C$3,"*"),Results!$T:$T,IF($D$3<>"",$D$3,"*"),Results!$V:$V,IF($F$3<>"",$F$3,"*"),Results!$F:$F,"Positive",Results!$G:$G,"=Indeterminate",Results!$H:$H,"Unknown")+COUNTIFS(Results!$D:$D,IF($C$4<>"",$C$4,"*"),Results!$U:$U,IF($C$3<>"",$C$3,"*"),Results!$T:$T,IF($D$3<>"",$D$3,"*"),Results!$V:$V,IF($F$3<>"",$F$3,"*"),Results!$F:$F,"Positive",Results!$G:$G,"=Indeterminate",Results!$H:$H,"=Not On Form")+COUNTIFS(Results!$D:$D,IF($C$4<>"",$C$4,"*"),Results!$U:$U,IF($C$3<>"",$C$3,"*"),Results!$T:$T,IF($D$3<>"",$D$3,"*"),Results!$V:$V,IF($F$3<>"",$F$3,"*"),Results!$F:$F,"Positive",Results!$G:$G,"=Indeterminate",Results!$H:$H,"") -> 0 | F30: =C30+D30+E30 -> 0
B31: TB - Trace with RIF- Indeterminate | C31: =COUNTIFS(Results!$D:$D,IF($C$4<>"",$C$4,"*"),Results!$U:$U,IF($C$3<>"",$C$3,"*"),Results!$T:$T,IF($D$3<>"",$D$3,"*"),Results!$V:$V,IF($F$3<>"",$F$3,"*"),Results!$F:$F,"Trace",Results!$G:$G,"Indeterminate",Results!$H:$H,"Positive") -> 0 | D31: =COUNTIFS(Results!$D:$D,IF($C$4<>"",$C$4,"*"),Results!$U:$U,IF($C$3<>"",$C$3,"*"),Results!$T:$T,IF($D$3<>"",$D$3,"*"),Results!$V:$V,IF($F$3<>"",$F$3,"*"),Results!$F:$F,"Trace",Results!$G:$G,"Indeterminate",Results!$H:$H,"Negative") -> 0 | E31: =COUNTIFS(Results!$D:$D,IF($C$4<>"",$C$4,"*"),Results!$U:$U,IF($C$3<>"",$C$3,"*"),Results!$T:$T,IF($D$3<>"",$D$3,"*"),Results!$V:$V,IF($F$3<>"",$F$3,"*"),Results!$F:$F,"Trace",Results!$G:$G,"=Indeterminate",Results!$H:$H,"Unknown")+COUNTIFS(Results!$D:$D,IF($C$4<>"",$C$4,"*"),Results!$U:$U,IF($C$3<>"",$C$3,"*"),Results!$T:$T,IF($D$3<>"",$D$3,"*"),Results!$V:$V,IF($F$3<>"",$F$3,"*"),Results!$F:$F,"Trace",Results!$G:$G,"=Indeterminate",Results!$H:$H,"=Not On Form")+COUNTIFS(Results!$D:$D,IF($C$4<>"",$C$4,"*"),Results!$U:$U,IF($C$3<>"",$C$3,"*"),Results!$T:$T,IF($D$3<>"",$D$3,"*"),Results!$V:$V,IF($F$3<>"",$F$3,"*"),Results!$F:$F,"Positive",Results!$G:$G,"=Indeterminate",Results!$H:$H,"") -> 0 | F31: =C31+D31+E31 -> 0
A32: Total | C32: =SUM(C27:C31) -> 0 | D32: =SUM(D27:D31) -> 0 | E32: =SUM(E27:E31) -> 0 | F32: =SUM(F27:F31) -> 0
A34: 5. Test results and Test reason
C35: Dx | D35: Fu | E35: MDR | F35: DM | G35: Na | H35: Total
A36: Xpert MTB/RIF | B36: Negative | C36: =COUNTIFS(Results!$D:$D,IF($C$4<>"",$C$4,"*"),Results!$U:$U,IF($C$3<>"",$C$3,"*"),Results!$T:$T,IF($D$3<>"",$D$3,"*"),Results!$V:$V,IF($F$3<>"",$F$3,"*"),Results!$F:$F,"Negative",Results!$O:$O,"dx") -> 0 | D36: =COUNTIFS(Results!$D:$D,IF($C$4<>"",$C$4,"*"),Results!$U:$U,IF($C$3<>"",$C$3,"*"),Results!$T:$T,IF($D$3<>"",$D$3,"*"),Results!$V:$V,IF($F$3<>"",$F$3,"*"),Results!$F:$F,"Negative",Results!$O:$O,"fu") -> 0 | E36: =COUNTIFS(Results!$D:$D,IF($C$4<>"",$C$4,"*"),Results!$U:$U,IF($C$3<>"",$C$3,"*"),Results!$T:$T,IF($D$3<>"",$D$3,"*"),Results!$V:$V,IF($F$3<>"",$F$3,"*"),Results!$F:$F,"Negative",Results!$O:$O,"mdr") -> 0 | F36: =COUNTIFS(Results!$D:$D,IF($C$4<>"",$C$4,"*"),Results!$U:$U,IF($C$3<>"",$C$3,"*"),Results!$T:$T,IF($D$3<>"",$D$3,"*"),Results!$V:$V,IF($F$3<>"",$F$3,"*"),Results!$F:$F,"Negative",Results!$O:$O,"dm") -> 0 | G36: =COUNTIFS(Results!$D:$D,IF($C$4<>"",$C$4,"*"),Results!$U:$U,IF($C$3<>"",$C$3,"*"),Results!$T:$T,IF($D$3<>"",$D$3,"*"),Results!$V:$V,IF($F$3<>"",$F$3,"*"),Results!$F:$F,"Negative",Results!$O:$O,"na") -> 0 | H36: =SUM(C36:G36) -> 0
B37: TB with NO RIF- Resistance | C37: =COUNTIFS(Results!$D:$D,IF($C$4<>"",$C$4,"*"),Results!$U:$U,IF($C$3<>"",$C$3,"*"),Results!$T:$T,IF($D$3<>"",$D$3,"*"),Results!$V:$V,IF($F$3<>"",$F$3,"*"),Results!$F:$F,"Positive",Results!$G:$G,"Negative",Results!$O:$O,"dx") -> 0 | D37: =COUNTIFS(Results!$D:$D,IF($C$4<>"",$C$4,"*"),Results!$U:$U,IF($C$3<>"",$C$3,"*"),Results!$T:$T,IF($D$3<>"",$D$3,"*"),Results!$V:$V,IF($F$3<>"",$F$3,"*"),Results!$F:$F,"Positive",Results!$G:$G,"Negative",Results!$O:$O,"fu") -> 0 | E37: =COUNTIFS(Results!$D:$D,IF($C$4<>"",$C$4,"*"),Results!$U:$U,IF($C$3<>"",$C$3,"*"),Results!$T:$T,IF($D$3<>"",$D$3,"*"),Results!$V:$V,IF($F$3<>"",$F$3,"*"),Results!$F:$F,"Positive",Results!$G:$G,"Negative",Results!$O:$O,"mdr") -> 0 | F37: =COUNTIFS(Results!$D:$D,IF($C$4<>"",$C$4,"*"),Results!$U:$U,IF($C$3<>"",$C$3,"*"),Results!$T:$T,IF($D$3<>"",$D$3,"*"),Results!$V:$V,IF($F$3<>"",$F$3,"*"),Results!$F:$F,"Positive",Results!$G:$G,"Negative",Results!$O:$O,"dm") -> 0 | G37: =COUNTIFS(Results!$D:$D,IF($C$4<>"",$C$4,"*"),Results!$U:$U,IF($C$3<>"",$C$3,"*"),Results!$T:$T,IF($D$3<>"",$D$3,"*"),Results!$V:$V,IF($F$3<>"",$F$3,"*"),Results!$F:$F,"Positive",Results!$G:$G,"Negative",Results!$O:$O,"na") -> 0 | H37: =SUM(C37:G37) -> 0
B38: TB with RIF- Resistance | C38: =COUNTIFS(Results!$D:$D,IF($C$4<>"",$C$4,"*"),Results!$U:$U,IF($C$3<>"",$C$3,"*"),Results!$T:$T,IF($D$3<>"",$D$3,"*"),Results!$V:$V,IF($F$3<>"",$F$3,"*"),Results!$F:$F,"Positive",Results!$G:$G,"Positive",Results!$O:$O,"dx") -> 0 | D38: =COUNTIFS(Results!$D:$D,IF($C$4<>"",$C$4,"*"),Results!$U:$U,IF($C$3<>"",$C$3,"*"),Results!$T:$T,IF($D$3<>"",$D$3,"*"),Results!$V:$V,IF($F$3<>"",$F$3,"*"),Results!$F:$F,"Positive",Results!$G:$G,"Positive",Results!$O:$O,"fu") -> 0 | E38: =COUNTIFS(Results!$D:$D,IF($C$4<>"",$C$4,"*"),Results!$U:$U,IF($C$3<>"",$C$3,"*"),Results!$T:$T,IF($D$3<>"",$D$3,"*"),Results!$V:$V,IF($F$3<>"",$F$3,"*"),Results!$F:$F,"Positive",Results!$G:$G,"Positive",Results!$O:$O,"mdr") -> 0 | F38: =COUNTIFS(Results!$D:$D,IF($C$4<>"",$C$4,"*"),Results!$U:$U,IF($C$3<>"",$C$3,"*"),Results!$T:$T,IF($D$3<>"",$D$3,"*"),Results!$V:$V,IF($F$3<>"",$F$3,"*"),Results!$F:$F,"Positive",Results!$G:$G,"Positive",Results!$O:$O,"dm") -> 0 | G38: =COUNTIFS(Results!$D:$D,IF($C$4<>"",$C$4,"*"),Results!$U:$U,IF($C$3<>"",$C$3,"*"),Results!$T:$T,IF($D$3<>"",$D$3,"*"),Results!$V:$V,IF($F$3<>"",$F$3,"*"),Results!$F:$F,"Positive",Results!$G:$G,"Positive",Results!$O:$O,"na") -> 0 | H38: =SUM(C38:G38) -> 0
B39: TB with RIF- Indeterminate | C39: =COUNTIFS(Results!$D:$D,IF($C$4<>"",$C$4,"*"),Results!$U:$U,IF($C$3<>"",$C$3,"*"),Results!$T:$T,IF($D$3<>"",$D$3,"*"),Results!$V:$V,IF($F$3<>"",$F$3,"*"),Results!$F:$F,"Positive",Results!$G:$G,"Indeterminate",Results!$O:$O,"dx") -> 0 | D39: =COUNTIFS(Results!$D:$D,IF($C$4<>"",$C$4,"*"),Results!$U:$U,IF($C$3<>"",$C$3,"*"),Results!$T:$T,IF($D$3<>"",$D$3,"*"),Results!$V:$V,IF($F$3<>"",$F$3,"*"),Results!$F:$F,"Positive",Results!$G:$G,"Indeterminate",Results!$O:$O,"fu") -> 0 | E39: =COUNTIFS(Results!$D:$D,IF($C$4<>"",$C$4,"*"),Results!$U:$U,IF($C$3<>"",$C$3,"*"),Results!$T:$T,IF($D$3<>"",$D$3,"*"),Results!$V:$V,IF($F$3<>"",$F$3,"*"),Results!$F:$F,"Positive",Results!$G:$G,"Indeterminate",Results!$O:$O,"mdr") -> 0 | F39: =COUNTIFS(Results!$D:$D,IF($C$4<>"",$C$4,"*"),Results!$U:$U,IF($C$3<>"",$C$3,"*"),Results!$T:$T,IF($D$3<>"",$D$3,"*"),Results!$V:$V,IF($F$3<>"",$F$3,"*"),Results!$F:$F,"Positive",Results!$G:$G,"Indeterminate",Results!$O:$O,"dm") -> 0 | G39: =COUNTIFS(Results!$D:$D,IF($C$4<>"",$C$4,"*"),Results!$U:$U,IF($C$3<>"",$C$3,"*"),Results!$T:$T,IF($D$3<>"",$D$3,"*"),Results!$V:$V,IF($F$3<>"",$F$3,"*"),Results!$F:$F,"Positive",Results!$G:$G,"Indeterminate",Results!$O:$O,"na") -> 0 | H39: =SUM(C39:G39) -> 0
B40: TB - Trace with RIF- Indeterminate | C40: =COUNTIFS(Results!$D:$D,IF($C$4<>"",$C$4,"*"),Results!$U:$U,IF($C$3<>"",$C$3,"*"),Results!$T:$T,IF($D$3<>"",$D$3,"*"),Results!$V:$V,IF($F$3<>"",$F$3,"*"),Results!$F:$F,"Trace",Results!$G:$G,"Indeterminate",Results!$O:$O,"dx") -> 0 | D40: =COUNTIFS(Results!$D:$D,IF($C$4<>"",$C$4,"*"),Results!$U:$U,IF($C$3<>"",$C$3,"*"),Results!$T:$T,IF($D$3<>"",$D$3,"*"),Results!$V:$V,IF($F$3<>"",$F$3,"*"),Results!$F:$F,"Trace",Results!$G:$G,"Indeterminate",Results!$O:$O,"fu") -> 0 | E40: =COUNTIFS(Results!$D:$D,IF($C$4<>"",$C$4,"*"),Results!$U:$U,IF($C$3<>"",$C$3,"*"),Results!$T:$T,IF($D$3<>"",$D$3,"*"),Results!$V:$V,IF($F$3<>"",$F$3,"*"),Results!$F:$F,"Trace",Results!$G:$G,"Indeterminate",Results!$O:$O,"mdr") -> 0 | F40: =COUNTIFS(Results!$D:$D,IF($C$4<>"",$C$4,"*"),Results!$U:$U,IF($C$3<>"",$C$3,"*"),Results!$T:$T,IF($D$3<>"",$D$3,"*"),Results!$V:$V,IF($F$3<>"",$F$3,"*"),Results!$F:$F,"Trace",Results!$G:$G,"Indeterminate",Results!$O:$O,"dm") -> 0 | G40: =COUNTIFS(Results!$D:$D,IF($C$4<>"",$C$4,"*"),Results!$U:$U,IF($C$3<>"",$C$3,"*"),Results!$T:$T,IF($D$3<>"",$D$3,"*"),Results!$V:$V,IF($F$3<>"",$F$3,"*"),Results!$F:$F,"Trace",Results!$G:$G,"Indeterminate",Results!$O:$O,"na") -> 0 | H40: =SUM(C40:G40) -> 0
A41: Total | C41: =SUM(C36:C40) -> 0 | D41: =SUM(D36:D40) -> 0 | E41: =SUM(E36:E40) -> 0 | F41: =SUM(F36:F40) -> 0 | G41: =SUM(G36:G40) -> 0 | H41: =SUM(H36:H40) -> 0
C43: Male | E43: Female | G43: Total
A44: 6. TB with Rif-Resistance detected | C44: =COUNTIFS(Results!$D:$D,IF($C$4<>"",$C$4,"*"),Results!$U:$U,IF($C$3<>"",$C$3,"*"),Results!$T:$T,IF($D$3<>"",$D$3,"*"),Results!$V:$V,IF($F$3<>"",$F$3,"*"),Results!$I:$I,"=Male",Results!$F:$F,"=Positive",Results!$G:$G,"=Positive")+COUNTIFS(Results!$D:$D,IF($C$4<>"",$C$4,"*"),Results!$U:$U,IF($C$3<>"",$C$3,"*"),Results!$T:$T,IF($D$3<>"",$D$3,"*"),Results!$V:$V,IF($F$3<>"",$F$3,"*"),Results!$I:$I,"=M",Results!$F:$F,"=Positive",Results!$G:$G,"=Positive") -> 0 | D44: 0 | E44: =COUNTIFS(Results!$D:$D,IF($C$4<>"",$C$4,"*"),Results!$U:$U,IF($C$3<>"",$C$3,"*"),Results!$T:$T,IF($D$3<>"",$D$3,"*"),Results!$V:$V,IF($F$3<>"",$F$3,"*"),Results!$I:$I,"=Female",Results!$F:$F,"=Positive",Results!$G:$G,"=Positive")+COUNTIFS(Results!$D:$D,IF($C$4<>"",$C$4,"*"),Results!$U:$U,IF($C$3<>"",$C$3,"*"),Results!$T:$T,IF($D$3<>"",$D$3,"*"),Results!$V:$V,IF($F$3<>"",$F$3,"*"),Results!$I:$I,"=F",Results!$F:$F,"=Positive",Results!$G:$G,"=Positive") -> 0 | F44: 0 | G44: =C44+E44 -> 0
A46: 7. Compare with sputum microscopy
...

Sheet Mar
A1: GeneXpert MTB/RIF Testing Report
C2: Quarter | D2: Month | F2: Year
A3: Reporting Period | C3: 1st Quarter | D3: March | F3: =YEAR(Results!E3) -> #VALUE!
A4: Reporting Unit
H5: Note: Press Ctrl + Alt + Shift + F9 to see the results in the cells.
A6: 1. Age and sex distribution of tested patients
B7: Male | D7: Female | F7: Total
B8: <15 | C8: >=15 | D8: <15 | E8: >=15
B9: =COUNTIFS(Results!$D:$D,IF($C$4<>"",$C$4,"*"),Results!$U:$U,IF($C$3<>"",$C$3,"*"),Results!$T:$T,IF($D$3<>"",$D$3,"*"),Results!$V:$V,IF($F$3<>"",$F$3,"*"),Results!$I:$I,"=Male",Results!$J:$J,"<15")+COUNTIFS(Results!$D:$D,IF($C$4<>"",$C$4,"*"),Results!$U:$U,IF($C$3<>"",$C$3,"*"),Results!$T:$T,IF($D$3<>"",$D$3,"*"),Results!$V:$V,IF($F$3<>"",$F$3,"*"),Results!$I:$I,"=M",Results!$J:$J,"<15") -> 0 | C9: =COUNTIFS(Results!$D:$D,IF($C$4<>"",$C$4,"*"),Results!$U:$U,IF($C$3<>"",$C$3,"*"),Results!$T:$T,IF($D$3<>"",$D$3,"*"),Results!$V:$V,IF($F$3<>"",$F$3,"*"),Results!$I:$I,"=Male",Results!$J:$J,">=15")+COUNTIFS(Results!$D:$D,IF($C$4<>"",$C$4,"*"),Results!$U:$U,IF($C$3<>"",$C$3,"*"),Results!$T:$T,IF($D$3<>"",$D$3,"*"),Results!$V:$V,IF($F$3<>"",$F$3,"*"),Results!$I:$I,"=M",Results!$J:$J,">=15") -> 0 | D9: =COUNTIFS(Results!$D:$D,IF($C$4<>"",$C$4,"*"),Results!$U:$U,IF($C$3<>"",$C$3,"*"),Results!$T:$T,IF($D$3<>"",$D$3,"*"),Results!$V:$V,IF($F$3<>"",$F$3,"*"),Results!$I:$I,"=Female",Results!$J:$J,"<15")+COUNTIFS(Results!$D:$D,IF($C$4<>"",$C$4,"*"),Results!$U:$U,IF($C$3<>"",$C$3,"*"),Results!$T:$T,IF($D$3<>"",$D$3,"*"),Results!$V:$V,IF($F$3<>"",$F$3,"*"),Results!$I:$I,"=F",Results!$J:$J,"<15") -> 0 | E9: =COUNTIFS(Results!$D:$D,IF($C$4<>"",$C$4,"*"),Results!$U:$U,IF($C$3<>"",$C$3,"*"),Results!$T:$T,IF($D$3<>"",$D$3,"*"),Results!$V:$V,IF($F$3<>"",$F$3,"*"),Results!$I:$I,"=Female",Results!$J:$J,">=15")+COUNTIFS(Results!$D:$D,IF($C$4<>"",$C$4,"*"),Results!$U:$U,IF($C$3<>"",$C$3,"*"),Results!$T:$T,IF($D$3<>"",$D$3,"*"),Results!$V:$V,IF($F$3<>"",$F$3,"*"),Results!$I:$I,"=F",Results!$J:$J,">=15") -> 0 | F9: =B9+C9+D9+E9 -> 0
A11: 2. Age and sex distribution of completed test
B12: Male | D12: Female | F12: Total
B13: <15 | C13: >=15 | D13: <15 | E13: >=15
B14: =COUNTIFS(Results!$D:$D,IF($C$4<>"",$C$4,"*"),Results!$U:$U,IF($C$3<>"",$C$3,"*"),Results!$T:$T,IF($D$3<>"",$D$3,"*"),Results!$V:$V,IF($F$3<>"",$F$3,"*"),Results!$F:$F,"<>Error",Results!$F:$F,"<>Invalid",Results!$F:$F,"<>No result",Results!$I:$I,"=Male",Results!$J:$J,"<15")+COUNTIFS(Results!$D:$D,IF($C$4<>"",$C$4,"*"),Results!$U:$U,IF($C$3<>"",$C$3,"*"),Results!$T:$T,IF($D$3<>"",$D$3,"*"),Results!$V:$V,IF($F$3<>"",$F$3,"*"),Results!$F:$F,"<>Error",Results!$F:$F,"<>Invalid",Results!$F:$F,"<>No result",Results!$I:$I,"=M",Results!$J:$J,"<15") -> 0 | C14: =COUNTIFS(Results!$D:$D,IF($C$4<>"",$C$4,"*"),Results!$U:$U,IF($C$3<>"",$C$3,"*"),Results!$T:$T,IF($D$3<>"",$D$3,"*"),Results!$V:$V,IF($F$3<>"",$F$3,"*"),Results!$F:$F,"<>Error",Results!$F:$F,"<>Invalid",Results!$F:$F,"<>No result",Results!$I:$I,"=Male",Results!$J:$J,">=15")+COUNTIFS(Results!$D:$D,IF($C$4<>"",$C$4,"*"),Results!$U:$U,IF($C$3<>"",$C$3,"*"),Results!$T:$T,IF($D$3<>"",$D$3,"*"),Results!$V:$V,IF($F$3<>"",$F$3,"*"),Results!$F:$F,"<>Error",Results!$F:$F,"<>Invalid",Results!$F:$F,"<>No result",Results!$I:$I,"=M",Results!$J:$J,">=15") -> 0 | D14: =COUNTIFS(Results!$D:$D,IF($C$4<>"",$C$4,"*"),Results!$U:$U,IF($C$3<>"",$C$3,"*"),Results!$T:$T,IF($D$3<>"",$D$3,"*"),Results!$V:$V,IF($F$3<>"",$F$3,"*"),Results!$F:$F,"<>Error",Results!$F:$F,"<>Invalid",Results!$F:$F,"<>No result",Results!$I:$I,"=Female",Results!$J:$J,"<15")+COUNTIFS(Results!$D:$D,IF($C$4<>"",$C$4,"*"),Results!$U:$U,IF($C$3<>"",$C$3,"*"),Results!$T:$T,IF($D$3<>"",$D$3,"*"),Results!$V:$V,IF($F$3<>"",$F$3,"*"),Results!$F:$F,"<>Error",Results!$F:$F,"<>Invalid",Results!$F:$F,"<>No result",Results!$I:$I,"=F",Results!$J:$J,"<15") -> 0 | E14: =COUNTIFS(Results!$D:$D,IF($C$4<>"",$C$4,"*"),Results!$U:$U,IF($C$3<>"",$C$3,"*"),Results!$T:$T,IF($D$3<>"",$D$3,"*"),Results!$V:$V,IF($F$3<>"",$F$3,"*"),Results!$F:$F,"<>Error",Results!$F:$F,"<>Invalid",Results!$F:$F,"<>No result",Results!$I:$I,"=Female",Results!$J:$J,">=15")+COUNTIFS(Results!$D:$D,IF($C$4<>"",$C$4,"*"),Results!$U:$U,IF($C$3<>"",$C$3,"*"),Results!$T:$T,IF($D$3<>"",$D$3,"*"),Results!$V:$V,IF($F$3<>"",$F$3,"*"),Results!$F:$F,"<>Error",Results!$F:$F,"<>Invalid",Results!$F:$F,"<>No result",Results!$I:$I,"=F",Results!$J:$J,">=15") -> 0 | F14: =B14+C14+D14+E14 -> 0
A16: 3. Test results and previous history of TB
C17: New | D17: Retreatment | E17: Unknown | F17: Total
A18: Xpert MTB/RIF | B18: Negative | C18: =COUNTIFS(Results!$D:$D,IF($C$4<>"",$C$4,"*"),Results!$U:$U,IF($C$3<>"",$C$3,"*"),Results!$T:$T,IF($D$3<>"",$D$3,"*"),Results!$V:$V,IF($F$3<>"",$F$3,"*"),Results!$F:$F,"Negative",Results!$K:$K,"No") -> 0 | D18: =COUNTIFS(Results!$D:$D,IF($C$4<>"",$C$4,"*"),Results!$U:$U,IF($C$3<>"",$C$3,"*"),Results!$T:$T,IF($D$3<>"",$D$3,"*"),Results!$V:$V,IF($F$3<>"",$F$3,"*"),Results!$F:$F,"Negative",Results!$K:$K,"Yes") -> 0 | E18: =COUNTIFS(Results!$D:$D,IF($C$4<>"",$C$4,"*"),Results!$U:$U,IF($C$3<>"",$C$3,"*"),Results!$T:$T,IF($D$3<>"",$D$3,"*"),Results!$V:$V,IF($F$3<>"",$F$3,"*"),Results!$F:$F,"=Negative",Results!$K:$K,"Unknown")+COUNTIFS(Results!$D:$D,IF($C$4<>"",$C$4,"*"),Results!$U:$U,IF($C$3<>"",$C$3,"*"),Results!$T:$T,IF($D$3<>"",$D$3,"*"),Results!$V:$V,IF($F$3<>"",$F$3,"*"),Results!$F:$F,"=Negative",Results!$K:$K,"N/A")+COUNTIFS(Results!$D:$D,IF($C$4<>"",$C$4,"*"),Results!$U:$U,IF($C$3<>"",$C$3,"*"),Results!$T:$T,IF($D$3<>"",$D$3,"*"),Results!$V:$V,IF($F$3<>"",$F$3,"*"),Results!$F:$F,"=Negative",Results!$K:$K,"") -> 0 | F18: =C18+D18+E18 -> 0
B19: TB with No RIF- Resistance | C19: =COUNTIFS(Results!$D:$D,IF($C$4<>"",$C$4,"*"),Results!$U:$U,IF($C$3<>"",$C$3,"*"),Results!$T:$T,IF($D$3<>"",$D$3,"*"),Results!$V:$V,IF($F$3<>"",$F$3,"*"),Results!$F:$F,"Positive",Results!$G:$G,"Negative",Results!$K:$K,"No") -> 0 | D19: =COUNTIFS(Results!$D:$D,IF($C$4<>"",$C$4,"*"),Results!$U:$U,IF($C$3<>"",$C$3,"*"),Results!$T:$T,IF($D$3<>"",$D$3,"*"),Results!$V:$V,IF($F$3<>"",$F$3,"*"),Results!$F:$F,"Positive",Results!$G:$G,"Negative",Results!$K:$K,"Yes") -> 0 | E19: =COUNTIFS(Results!$D:$D,IF($C$4<>"",$C$4,"*"),Results!$U:$U,IF($C$3<>"",$C$3,"*"),Results!$T:$T,IF($D$3<>"",$D$3,"*"),Results!$V:$V,IF($F$3<>"",$F$3,"*"),Results!$F:$F,"Positive",Results!$G:$G,"=Negative",Results!$K:$K,"Unknown")+COUNTIFS(Results!$D:$D,IF($C$4<>"",$C$4,"*"),Results!$U:$U,IF($C$3<>"",$C$3,"*"),Results!$T:$T,IF($D$3<>"",$D$3,"*"),Results!$V:$V,IF($F$3<>"",$F$3,"*"),Results!$F:$F,"Positive",Results!$G:$G,"=Negative",Results!$K:$K,"N/A")+COUNTIFS(Results!$D:$D,IF($C$4<>"",$C$4,"*"),Results!$U:$U,IF($C$3<>"",$C$3,"*"),Results!$T:$T,IF($D$3<>"",$D$3,"*"),Results!$V:$V,IF($F$3<>"",$F$3,"*"),Results!$F:$F,"Positive",Results!$G:$G,"=Negative",Results!$K:$K,"") -> 0 | F19: =C19+D19+E19 -> 0
B20: TB with RIF- Resistance | C20: =COUNTIFS(Results!$D:$D,IF($C$4<>"",$C$4,"*"),Results!$U:$U,IF($C$3<>"",$C$3,"*"),Results!$T:$T,IF($D$3<>"",$D$3,"*"),Results!$V:$V,IF($F$3<>"",$F$3,"*"),Results!$F:$F,"Positive",Results!$G:$G,"Positive",Results!$K:$K,"No") -> 0 | D20: =COUNTIFS(Results!$D:$D,IF($C$4<>"",$C$4,"*"),Results!$U:$U,IF($C$3<>"",$C$3,"*"),Results!$T:$T,IF($D$3<>"",$D$3,"*"),Results!$V:$V,IF($F$3<>"",$F$3,"*"),Results!$F:$F,"Positive",Results!$G:$G,"Positive",Results!$K:$K,"Yes") -> 0 | E20: =COUNTIFS(Results!$D:$D,IF($C$4<>"",$C$4,"*"),Results!$U:$U,IF($C$3<>"",$C$3,"*"),Results!$T:$T,IF($D$3<>"",$D$3,"*"),Results!$V:$V,IF($F$3<>"",$F$3,"*"),Results!$F:$F,"Positive",Results!$G:$G,"=Positive",Results!$K:$K,"Unknown")+COUNTIFS(Results!$D:$D,IF($C$4<>"",$C$4,"*"),Results!$U:$U,IF($C$3<>"",$C$3,"*"),Results!$T:$T,IF($D$3<>"",$D$3,"*"),Results!$V:$V,IF($F$3<>"",$F$3,"*"),Results!$F:$F,"Positive",Results!$G:$G,"=Positive",Results!$K:$K,"N/A")+COUNTIFS(Results!$D:$D,IF($C$4<>"",$C$4,"*"),Results!$U:$U,IF($C$3<>"",$C$3,"*"),Results!$T:$T,IF($D$3<>"",$D$3,"*"),Results!$V:$V,IF($F$3<>"",$F$3,"*"),Results!$F:$F,"Positive",Results!$G:$G,"=Positive",Results!$K:$K,"") -> 0 | F20: =C20+D20+E20 -> 0
B21: TB with RIF- Indeterminate | C21: =COUNTIFS(Results!$D:$D,IF($C$4<>"",$C$4,"*"),Results!$U:$U,IF($C$3<>"",$C$3,"*"),Results!$T:$T,IF($D$3<>"",$D$3,"*"),Results!$V:$V,IF($F$3<>"",$F$3,"*"),Results!$F:$F,"Positive",Results!$G:$G,"Indeterminate",Results!$K:$K,"No") -> 0 | D21: =COUNTIFS(Results!$D:$D,IF($C$4<>"",$C$4,"*"),Results!$U:$U,IF($C$3<>"",$C$3,"*"),Results!$T:$T,IF($D$3<>"",$D$3,"*"),Results!$V:$V,IF($F$3<>"",$F$3,"*"),Results!$F:$F,"Positive",Results!$G:$G,"Indeterminate",Results!$K:$K,"Yes") -> 0 | E21: =COUNTIFS(Results!$D:$D,IF($C$4<>"",$C$4,"*"),Results!$U:$U,IF($C$3<>"",$C$3,"*"),Results!$T:$T,IF($D$3<>"",$D$3,"*"),Results!$V:$V,IF($F$3<>"",$F$3,"*"),Results!$F:$F,"Positive",Results!$G:$G,"=Indeterminate",Results!$K:$K,"Unknown")+COUNTIFS(Results!$D:$D,IF($C$4<>"",$C$4,"*"),Results!$U:$U,IF($C$3<>"",$C$3,"*"),Results!$T:$T,IF($D$3<>"",$D$3,"*"),Results!$V:$V,IF($F$3<>"",$F$3,"*"),Results!$F:$F,"Positive",Results!$G:$G,"=Indeterminate",Results!$K:$K,"N/A")+COUNTIFS(Results!$D:$D,IF($C$4<>"",$C$4,"*"),Results!$U:$U,IF($C$3<>"",$C$3,"*"),Results!$T:$T,IF($D$3<>"",$D$3,"*"),Results!$V:$V,IF($F$3<>"",$F$3,"*"),Results!$F:$F,"Positive",Results!$G:$G,"=Indeterminate",Results!$K:$K,"") -> 0 | F21: =C21+D21+E21 -> 0
