Workbook
Name Bagerhat: 'DR-TB 10A (Stool)'!$G$393:$G$399
Name Bagerhat: 'DR-TB 10A (Sputum & EP Sample)'!$G$394:$G$400
Name Bandarban: 'DR-TB 10A (Stool)'!$G$150:$G$153
Name Bandarban: 'DR-TB 10A (Sputum & EP Sample)'!$G$150:$G$153
Name Barguna: 'DR-TB 10A (Stool)'!$G$102:$G$106
Name Barguna: 'DR-TB 10A (Sputum & EP Sample)'!$G$102:$G$106
Name Barisal: 'DR-TB 10A (Stool)'!$G$107:$G$119
Name Barisal: 'DR-TB 10A (Sputum & EP Sample)'!$G$107:$G$119
Name Barisal_Division: 'DR-TB 10A (Stool)'!$D$102:$D$107
Name Barisal_Division: 'DR-TB 10A (Sputum & EP Sample)'!$D$102:$D$107
Name Bhola: 'DR-TB 10A (Stool)'!$G$120:$G$126
Name Bhola: 'DR-TB 10A (Sputum & EP Sample)'!$G$120:$G$126
Name Bogra: 'DR-TB 10A (Stool)'!$G$499:$G$513
Name Bogra: 'DR-TB 10A (Sputum & EP Sample)'!$G$502:$G$516
Name Brahmanbaria: 'DR-TB 10A (Stool)'!$G$154:$G$162
Name Brahmanbaria: 'DR-TB 10A (Sputum & EP Sample)'!$G$154:$G$162
Name Chandpur: 'DR-TB 10A (Stool)'!$G$163:$G$168
Name Chandpur: 'DR-TB 10A (Sputum & EP Sample)'!$G$163:$G$168
Name Chattogram: 'DR-TB 10A (Stool)'!$G$169:$G$196
Name Chattogram: 'DR-TB 10A (Sputum & EP Sample)'!$G$169:$G$196
Name Chattogram_Division: 'DR-TB 10A (Stool)'!$D$108:$D$118
Name Chattogram_Division: 'DR-TB 10A (Sputum & EP Sample)'!$D$108:$D$118
Name Chuadanga: 'DR-TB 10A (Stool)'!$G$400:$G$404
Name Chuadanga: 'DR-TB 10A (Sputum & EP Sample)'!$G$401:$G$406
Name Comilla: 'DR-TB 10A (Stool)'!$G$197:$G$211
Name Comilla: 'DR-TB 10A (Sputum & EP Sample)'!$G$197:$G$211
Name Coxs_Bazar: 'DR-TB 10A (Stool)'!$G$213:$G$224
Name Coxs_Bazar: 'DR-TB 10A (Sputum & EP Sample)'!$G$213:$G$224
Name Dhaka: 'DR-TB 10A (Stool)'!$G$254:$G$300
Name Dhaka: 'DR-TB 10A (Sputum & EP Sample)'!$G$254:$G$300
Name Dhaka_Division: 'DR-TB 10A (Stool)'!$D$119:$D$131
Name Dhaka_Division: 'DR-TB 10A (Sputum & EP Sample)'!$D$119:$D$131
Name Dinajpur: 'DR-TB 10A (Stool)'!$G$574:$G$585
Name Dinajpur: 'DR-TB 10A (Sputum & EP Sample)'!$G$577:$G$588
Name Faridpur: 'DR-TB 10A (Stool)'!$G$301:$G$306
Name Faridpur: 'DR-TB 10A (Sputum & EP Sample)'!$G$301:$G$306
Name Feni: 'DR-TB 10A (Stool)'!$G$225:$G$230
Name Feni: 'DR-TB 10A (Sputum & EP Sample)'!$G$225:$G$230
Name Gaibandha: 'DR-TB 10A (Stool)'!$G$586:$G$594
Name Gaibandha: 'DR-TB 10A (Sputum & EP Sample)'!$G$589:$G$597
Name Gazipur: 'DR-TB 10A (Stool)'!$G$308:$G$315
Name Gazipur: 'DR-TB 10A (Sputum & EP Sample)'!$G$308:$G$316
Name Gopalganj: 'DR-TB 10A (Stool)'!$G$316:$G$320
Name Gopalganj: 'DR-TB 10A (Sputum & EP Sample)'!$G$317:$G$321
Name Habiganj: 'DR-TB 10A (Stool)'!$G$635:$G$645
Name Habiganj: 'DR-TB 10A (Sputum & EP Sample)'!$G$638:$G$648
Name Jamalpur: 'DR-TB 10A (Stool)'!$G$456:$G$464
Name Jamalpur: 'DR-TB 10A (Sputum & EP Sample)'!$G$459:$G$467
Name Jessore: 'DR-TB 10A (Stool)'!$G$405:$G$412
Name Jessore: 'DR-TB 10A (Sputum & EP Sample)'!$G$407:$G$414
Name Jhalakathi: 'DR-TB 10A (Stool)'!$G$132:$G$135
Name Jhalakathi: 'DR-TB 10A (Sputum & EP Sample)'!$G$132:$G$135
Name Jhenaidah: 'DR-TB 10A (Stool)'!$G$413:$G$419
Name Jhenaidah: 'DR-TB 10A (Sputum & EP Sample)'!$G$415:$G$421
Name Joypurhat: 'DR-TB 10A (Stool)'!$G$521:$G$526
Name Joypurhat: 'DR-TB 10A (Sputum & EP Sample)'!$G$524:$G$529
Name Khagrachari: 'DR-TB 10A (Stool)'!$G$231:$G$234
Name Khagrachari: 'DR-TB 10A (Sputum & EP Sample)'!$G$231:$G$234
Name Khulna: 'DR-TB 10A (Stool)'!$G$420:$G$428
Name Khulna: 'DR-TB 10A (Sputum & EP Sample)'!$G$422:$G$430

Sheet DR-TB 10A (Sputum & EP Sample)
A1: Government of the People's Republic of Bangladesh | S1: Form DR TB 10 A
A2: National TB Control Programme
A3: Programmatic Management of Drug Resistant Tuberculosis (PMDT)
A4: Monthly Report on Truenat/Xpert Results
A6: Division : | J6: Reporting period : | L6: <Dates>
A7: District : | J7: Name of the person completing the report :
A8: Name of the reporting unit : | J8: Designation and organization :
A9: Monthly reporting on : | C9: GeneXpert (Sputum & EP) | J9: Date of completion of the form :
J10: Signature : | O10: Cell Number :
A11: Block 1:
A12: Number of total Cases Tested | D12: Presumptive TB Cases(Total) | H12: =D27+E40 -> 0 | J12: For Xpert | N12: For Truenat
D13: Presumptive DR TB Cases(Total) | H13: =U27 -> 0 | J13: Number of Gene Xpert Machine: | N13: No. of TruePrep Device | R13: Functional TruePrep Device
D14: Total | H14: =H12+H13 -> 0 | J14: Total Number Of Module: | N14: No.of TrueLab Device | R14: Functional TrueLab Device
J15: Number of Module Functional: | N15: Total No. of Chip Ports | R15: Total functional Chip Ports
A16: Results: | D16: Presumptive TB | E16: Presumptive DR-TB | F16: Total
A17: A) Number of MTB detected, Rif Resistance not detected (T): | D17: =D30+E42-D33-E44 -> 0 | E17: =+U30-U33 -> 0 | F17: =+E17+D17 -> 0 | I17: Type Of Cartridge | J17: Presumptive TB | M17: Presumptive DR-TB | P17: Total | R17: No. of Truenat Cartriage Used
A18: B) Number of MTB detected, Rif Resistance detected (RR): | D18: =D33+E44 -> 0 | E18: =U33 -> 0 | F18: =+E18+D18 -> 0 | J18: Invalid | K18: No result | L18: Error | M18: Invalid | N18: No result | O18: Error | R18: No. of Truenat MTB Chip Used
A19: C) Number of MTB detected, Rif Resistance indeterminate (TI): | F19: =+E19+D19 -> 0 | I19: MTB | P19: =J19+K19+L19+M19+N19+O19 -> 0 | R19: No. of Truenat RIF Dx Chip Used
A20: D) Number of MTB Trace detected (TT): | D20: =T35 -> 0 | E20: =U35 -> 0 | F20: =+E20+D20 -> 0 | I20: XDR | P20: =J20+K20+L20+M20+N20+O20 -> 0
A21: E) Number of MTB not detected (N): | D21: =H12-D30-E42 -> 0 | E21: =H13-U30 -> 0 | F21: =+E21+D21 -> 0
A23: Block 2:
A24: Number of : | B24: Type of Patient : Presumptive TB Cases | E24: Type of Patient : Presumptive DR TB Cases | U24: Total (Column 3- Column 13)
B25: Unknown History | C25: New | D25: Total (Column 1- Column 2) | E25: Failures of CAT I (remain positive at month 5 or later/ Smear negative patients become smear positive at month 2) | F25: Failures of CAT II (remain positive at month 5 or 8) | G25: Non converters of CAT I (remain positive at month 2) | H25: Non converters of CAT II (remain positive at month 3) | I25: Relapses (CAT I) | J25: Relapses (CAT II) | K25: Treatment after loss to follow up (CAT I) | L25: Treatment after loss to follow up (CAT II) | M25: Close contacts of DR TB patient with symptoms | P25: HIV infected person with TB S/S | S25: Others (Specify)* i) Pulmonary clinically diagnosed ii) Extra Pulmonary iii) Pulmonary bacteriologically confirmed
B26: Column (1) | C26: Column (2) | E26: Column (3) | F26: Column (4) | G26: Column (5) | H26: Column (6) | I26: Column (7) | J26: Column (8) | K26: Column (9) | L26: Column (10) | M26: Column (11) | P26: Column (12) | S26: Column (13)
A27: Presumptive cases tested by Xpert MTB/RIF | D27: =B27+C27 -> 0 | M27: Unknown history: | P27: Unknown history: | S27: =M41+M42+M43+N41+N42+N43+O41+O42 -> 0 | U27: =E27+F27+G27+H27+I27+J27+K27+L27+O27+O28+O29+R27+R28+R29+S27 -> 0
M28: New: | P28: New:
M29: Prev. treated: | P29: Prev. treated:
A30: MTB detected | D30: =B30+C30 -> 0 | M30: Unknown history: | P30: Unknown history: | S30: =P41+P42+P43+Q41+Q42+Q43+R41+R42 -> 0 | U30: =E30+F30+G30+H30+I30+J30+K30+L30+O30+O31+O32+R30+R31+R32+S30 -> 0
M31: New: | P31: New:
M32: Prev. treated: | P32: Prev. treated:
A33: RR TB detected | D33: =B33+C33 -> 0 | M33: Unknown history: | P33: Unknown history: | S33: =S41+S42+S43+T41+T42+T43+U41+U42 -> 0 | U33: =E33+F33+G33+H33+I33+J33+K33+L33+O33+O34+O35+R33+R34+R35+S33 -> 0
M34: New: | P34: New:
M35: Prev. treated: | P35: Prev. treated:
A37: Block 3:
A38: Number of Presumptive smear negative TB cases | G38: Number of Xpert XDR Assay | J38: *Others (Specify)
B39: Unknown History | C39: New | D39: Prev. Treated | E39: Total | J39: Type of Patient | M39: Presumptive DR TB cases | P39: MTB detected | S39: RR TB detected
A40: Presumptive Sm. Neg cases tested by Xpert MTB/RIF | E40: =B40+C40+D40 -> 0 | G40: Eligible for XDR Testing | H40: =$E$17+$F$18 -> 0 | M40: Un. His. | N40: N | O40: Prev. Tr. | P40: Un. His. | Q40: N | R40: Prev. Tr. | S40: Un. His. | T40: N | U40: Prev. Tr.
J41: i) Pulmonary clinically diagnosed
A42: MTB Detected | E42: =B42+C42+D42 -> 0 | G42: Tested from Eligible | J42: ii) Extra Pulmonary
J43: iii) Pulmonary bacteriologically confirmed
...

Sheet DR-TB 10A (Stool)
A1: Government of the People's Republic of Bangladesh | S1: Form DR TB 10 A
A2: National TB Control Programme
A3: Programmatic Management of Drug Resistant Tuberculosis (PMDT)
A4: Monthly Report on Truenat/Xpert Results
A6: Division : | C6: ='DR-TB 10A (Sputum & EP Sample)'!C6:G6 -> 0 | J6: Reporting period : | L6: ='DR-TB 10A (Sputum & EP Sample)'!L6 -> <Dates>
A7: District : | C7: ='DR-TB 10A (Sputum & EP Sample)'!C7:G7 -> 0 | J7: Name of the person completing the report : | N7: ='DR-TB 10A (Sputum & EP Sample)'!N7 -> 0
A8: Name of the reporting unit : | C8: ='DR-TB 10A (Sputum & EP Sample)'!C8:G8 -> 0 | J8: Designation and organization : | M8: ='DR-TB 10A (Sputum & EP Sample)'!M8 -> 0
A9: Monthly reporting on : | C9: GeneXpert (Stool) | J9: Date of completion of the form : | M9: ='DR-TB 10A (Sputum & EP Sample)'!M9 -> 0
J10: Signature : | K10: ='DR-TB 10A (Sputum & EP Sample)'!K10:L10 -> 0 | P10: Cell Number: | Q10: ='DR-TB 10A (Sputum & EP Sample)'!Q10:S10 -> 0
A11: Block 1:
A12: Number of total Cases Tested | D12: Presumptive TB Cases(Total) | H12: =D27+E40 -> 0 | J12: For Xpert | N12: For Truenat
D13: Presumptive DR TB Cases(Total) | H13: =U27 -> 0 | J13: Number of Gene Xpert Machine: | M13: ='DR-TB 10A (Sputum & EP Sample)'!M13 -> 0 | N13: No. of TruePrep Device | Q13: ='DR-TB 10A (Sputum & EP Sample)'!Q13 -> 0 | R13: Functional TruePrep Device | U13: ='DR-TB 10A (Sputum & EP Sample)'!U13 -> 0
D14: Total | H14: =H12+H13 -> 0 | J14: Total Number Of Module: | M14: ='DR-TB 10A (Sputum & EP Sample)'!M14 -> 0 | N14: No.of TrueLab Device | Q14: ='DR-TB 10A (Sputum & EP Sample)'!Q14 -> 0 | R14: Functional TrueLab Device | U14: ='DR-TB 10A (Sputum & EP Sample)'!U14 -> 0
J15: Number of Module Functional: | M15: ='DR-TB 10A (Sputum & EP Sample)'!M15 -> 0 | N15: Total No. of Chip Ports | Q15: ='DR-TB 10A (Sputum & EP Sample)'!Q15 -> 0 | R15: Total functional Chip Ports | U15: ='DR-TB 10A (Sputum & EP Sample)'!U15 -> 0
A16: Results: | D16: Presumptive TB | E16: Presumptive DR-TB | F16: Total
A17: A) Number of MTB detected, Rif Resistance not detected (T): | D17: =D30+E42-D33-E44 -> 0 | E17: =+U30-U33 -> 0 | F17: =+E17+D17 -> 0 | I17: Type Of Cartridge | J17: Presumptive TB | M17: Presumptive DR-TB | P17: Total | R17: No. of Truenat Cartriage Used | U17: ='DR-TB 10A (Sputum & EP Sample)'!U17 -> 0
A18: B) Number of MTB detected, Rif Resistance detected (RR): | D18: =D33+E44 -> 0 | E18: =U33 -> 0 | F18: =+E18+D18 -> 0 | J18: Invalid | K18: No result | L18: Error | M18: Invalid | N18: No result | O18: Error | R18: No. of Truenat MTB Chip Used | U18: ='DR-TB 10A (Sputum & EP Sample)'!U18 -> 0
A19: C) Number of MTB detected, Rif Resistance indeterminate (TI): | F19: =+E19+D19 -> 0 | I19: MTB | P19: =J19+K19+L19+M19+N19+O19 -> 0 | R19: No. of Truenat RIF Dx Chip Used | U19: ='DR-TB 10A (Sputum & EP Sample)'!U19 -> 0
A20: D) Number of MTB Trace detected (TT): | F20: =+E20+D20 -> 0 | I20: XDR | P20: =J20+K20+L20+M20+N20+O20 -> 0
A21: E) Number of MTB not detected (N): | D21: =H12-D30-E42 -> 0 | E21: =H13-U30 -> 0 | F21: =+E21+D21 -> 0
A23: Block 2:
A24: Number of : | B24: Type of Patient : Presumptive TB Cases | E24: Type of Patient : Presumptive DR TB Cases | U24: Total (Column 3- Column 13)
B25: Unknown History | C25: New | D25: Total (Column 1- Column 2) | E25: Failures of CAT I (remain positive at month 5 or later/ Smear negative patients become smear positive at month 2) | F25: Failures of CAT II (remain positive at month 5 or 8) | G25: Non converters of CAT I (remain positive at month 2) | H25: Non converters of CAT II (remain positive at month 3) | I25: Relapses (CAT I) | J25: Relapses (CAT II) | K25: Treatment after loss to follow up (CAT I) | L25: Treatment after loss to follow up (CAT II) | M25: Close contacts of DR TB patient with symptoms | P25: HIV infected person with TB S/S | S25: Others (Specify)* i) Pulmonary clinically diagnosed ii) Extra Pulmonary iii) Pulmonary bacteriologically confirmed
B26: Column (1) | C26: Column (2) | E26: Column (3) | F26: Column (4) | G26: Column (5) | H26: Column (6) | I26: Column (7) | J26: Column (8) | K26: Column (9) | L26: Column (10) | M26: Column (11) | P26: Column (12) | S26: Column (13)
A27: Presumptive cases tested by Xpert MTB/RIF | D27: =B27+C27 -> 0 | M27: Unknown history: | P27: Unknown history: | S27: =M41+M42+M43+N41+N42+N43+O41+O42 -> 0 | U27: =E27+F27+G27+H27+I27+J27+K27+L27+O27+O28+O29+R27+R28+R29+S27 -> 0
M28: New: | P28: New:
M29: Prev. treated: | P29: Prev. treated:
A30: MTB detected | D30: =B30+C30 -> 0 | M30: Unknown history: | P30: Unknown history: | S30: =P41+P42+P43+Q41+Q42+Q43+R41+R42 -> 0 | U30: =E30+F30+G30+H30+I30+J30+K30+L30+O30+O31+O32+R30+R31+R32+S30 -> 0
M31: New: | P31: New:
M32: Prev. treated: | P32: Prev. treated:
A33: RR TB detected | D33: =B33+C33 -> 0 | M33: Unknown history: | P33: Unknown history: | S33: =S41+S42+S43+T41+T42+T43+U41+U42 -> 0 | U33: =E33+F33+G33+H33+I33+J33+K33+L33+O33+O34+O35+R33+R34+R35+S33 -> 0
M34: New: | P34: New:
M35: Prev. treated: | P35: Prev. treated:
A37: Block 3:
A38: Number of Presumptive smear negative TB cases | G38: Number of Xpert XDR Assay | J38: *Others (Specify)
B39: Unknown History | C39: New | D39: Prev. Treated | E39: Total | J39: Type of Patient | M39: Presumptive DR TB cases | P39: MTB detected | S39: RR TB detected
A40: Presumptive Sm. Neg cases tested by Xpert MTB/RIF | E40: =B40+C40+D40 -> 0 | G40: Eligible for XDR Testing | H40: =$E$17+$F$18 -> 0 | M40: Un. His. | N40: N | O40: Prev. Tr. | P40: Un. His. | Q40: N | R40: Prev. Tr. | S40: Un. His. | T40: N | U40: Prev. Tr.
J41: i) Pulmonary clinically diagnosed
A42: MTB Detected | E42: =B42+C42+D42 -> 0 | G42: Tested from Eligible | J42: ii) Extra Pulmonary
J43: iii) Pulmonary bacteriologically confirmed
...

Sheet DR-TB 10B
A1: Government of the People's Republic of Bangladesh
A2: National TB Control Program
A3: Programmatic Management of Drug Resistant Tuberculosis (PMDT)
A4: Monthly Report of Enrolment status of Detected
A5: Drug Resistant Cases by Xpert/Truenat
A7: Fill this format as per total DR TB detected cases during the reporting month reported in the form DR TB 10 A
A8: Name and address of the reporting Unit: | D8: =IF('DR-TB 10A (Sputum & EP Sample)'!C8="","",'DR-TB 10A (Sputum & EP Sample)'!C8) | H8: Reporting period: | I8: ='DR-TB 10A (Sputum & EP Sample)'!L6 -> <Dates>
A9: Number of total DR TB detected in the reporting month: | F9: ='DR-TB 10A (Sputum & EP Sample)'!F18+'DR-TB 10A (Stool)'!F18 -> 0
A10: <Table> | B10: 2
A11: Sl. No | B11: Name of the RR patient | C11: Age | D11: Sex (M/F) | E11: Date of Diagnosis | F11: Address and cell number | G11: Name & address of the referring unit and cell number | H11: * Type of patient | I11: Type Of Sample | J11: Current and previous (if any) TB registration number | K11: Result of Xpert/Truenat MTB/RIF/Ultra | L11: Bacterial Load | M11: Result Of MTB/XDR | T11: Name and address of the hospital/ treatment initiation center for enrollment of DR TB treatment | U11: Enrollment status (Y/N) | V11: Date Of Enrollment | W11: eTB/ DR TB Registration Number | X11: ** Current status of the patient | Y11: Remarks
M12: MTB | N12: INH | O12: FLQ | P12: AMK | Q12: KAN | R12: CAP | S12: ETH
A13: <#> | B13: <patientName> | C13: <patientAge> | D13: <gender> | E13: <dateOfDiagnosis> | F13: <patientAddressAndCell> | G13: <referringAddressAndCell> | H13: <patientType> | I13: <sampleType> | J13: <tbRegistrationNumber> | K13: <resultMtbRif> | L13: <bacterialLoad> | M13: <mtbDetected> | N13: <inhDetected> | O13: <flqDetected> | P13: <amkDetected> | Q13: <kanDetected> | R13: <capDetected> | S13: <ethDetected> | T13: <hospitalTreatmentDRTB> | U13: <enrollmentStatus> | V13: <enrollmentDate> | W13: <tbRegistrationNumber> | X13: <patientStatus> | Y13: <remarks>
A16: *Type of patient (Code): 1, Failures of Category I (remain positive at month 5 or later and / Smear negative patients become smear positive at month 2); 2, Failures of Category II (remain positive at month 5 or 8); 3, Non Converters of CAT II (remain positive at month 3); 4, Non Converters of Category I (remain positive at month 2) ; 5, Relapse - a) Category I, b) Category II; 6, Treatment after loss to follow up - a) Category I, b) Category II ; 7, Close contacts of DR-TB patient with symptoms, a) Unknown history b) New c) Prev. treated; 8, HIV infected person with TB S/S, a) Unknown history b) New c) Prev. treated; 9, Others (Specify) i) Pulmonary, clinically diagnosed, a) Unknown history b) New c) Prev. treated, ii) Extra Pulmonary, a) Unknown history b) New c) Prev. treated, iii) Pulmonary, bacteriologically confirmed, a) Unknown history b) New; 10, Presumptive Pulmonary Smear Negative cases a) Unknown history b) New c) Prev. treated.
A17: **Example: died(With Date), absconded/Lost to follow up, under treatment etc.

Sheet COVID19 Reporting Form
A1: Government of the People's Republic of Bangladesh | P1: COVID19 Test Reporting Form
A2: National TB Control Programme
A3: Directorate General of Health Services
A5: Monthly Report on Xpert COVID19 Results
A7: Division : | C7: ='DR-TB 10A (Sputum & EP Sample)'!C6:G6 -> 0 | J7: Reporting period : | L7: ='DR-TB 10A (Sputum & EP Sample)'!L6 -> <Dates>
A8: District : | C8: ='DR-TB 10A (Sputum & EP Sample)'!C7:G7 -> 0 | J8: Name of the person reporting | N8: ='DR-TB 10A (Sputum & EP Sample)'!N7:S7 -> 0
A9: Name of the reporting unit : | C9: ='DR-TB 10A (Sputum & EP Sample)'!C8:G8 -> 0 | J9: Designation and organization : | M9: ='DR-TB 10A (Sputum & EP Sample)'!M8:S8 -> 0
J10: Date of completion of the form : | M10: ='DR-TB 10A (Sputum & EP Sample)'!M9:N9 -> 0
J11: Signature : | K11: ='DR-TB 10A (Sputum & EP Sample)'!K10:L10 -> 0 | O11: Cell Number : | Q11: ='DR-TB 10A (Sputum & EP Sample)'!Q10:S10 -> 0
A13: Cartridge information | B13: Cartridges Received | D13: Cartridges in Hand | H13: Number of invalid / no result / error: | L13: COVID19 Test | O13: Total
O14: =L14+M14+N14 -> 0
C17: Type of test : New | F17: Type of Test : Follow up | L17: Grand Total
C18: Male | D18: Female | E18: Total | F18: Male | H18: Female | J18: Total | L18: Male | N18: Female | P18: Total
A20: Number Of COVID19 Test | E20: =C20+D20 -> 0 | J20: =F20+H20 -> 0 | L20: =C20+F20 -> 0 | N20: =D20+H20 -> 0 | P20: =L20+N20 -> 0
A23: Number of COVID 19 Positive Detected | E23: =C23+D23 -> 0 | J23: =F23+H23 -> 0 | L23: =C23+F23 -> 0 | N23: =D23+H23 -> 0 | P23: =L23+N23 -> 0
A26: Number of COVID 19 Negative Detected | E26: =C26+D26 -> 0 | J26: =F26+H26 -> 0 | L26: =C26+F26 -> 0 | N26: =D26+H26 -> 0 | P26: =L26+N26 -> 0
H30: Name and designation of Coordinator/ authority :
H31: Signature: | N31: Date:
H32: Cell number:

Sheet For NTP Use
A1: Division | B1: District / Area | C1: Name of GeneXpert/Truenat Site | E1: Presumptive DS TB Cases | H1: Presumptive DR TB Cases | AG1: Presumptive Smear Negative TB Cases | AK1: Total Presumptive TB Cases Tested | AL1: Total Presumptive DR-TB Cases Tested | AM1: Total Presumptive Tested | AN1: Number of MTB detected-DS TB | AR1: Number of MTB not detected (N)- DS TB | AS1: Number of MTB detected-DR TB | AW1: Number of MTB not detected (N)- DR TB | AX1: Number of MTB detected-Total | BB1: Number of MTB not detected -Total | BC1: Type Of Cartridge | BD1: Presumptive TB | BG1: Presumptive DR-TB | BJ1: Total | BK1: ='DR-TB 10A (Sputum & EP Sample)'!J7 -> Name of the person completing the report : | BL1: ='DR-TB 10A (Sputum & EP Sample)'!J8 -> Designation and organization : | BM1: ='DR-TB 10A (Sputum & EP Sample)'!O10 -> Cell Number : | BN1: ='COVID19 Reporting Form'!B13 -> Cartridges Received | BO1: ='COVID19 Reporting Form'!D13 -> Cartridges in Hand | BP1: ='COVID19 Reporting Form'!C17 -> Type of test : New | BV1: ='COVID19 Reporting Form'!F17 -> Type of Test : Follow up | CB1: Number of invalid / no result / error: | CE1: ='DR-TB 10A (Sputum & EP Sample)'!J12 -> For Xpert | CH1: ='DR-TB 10A (Sputum & EP Sample)'!N12 -> For Truenat | CQ1: ='DR-TB 10A (Sputum & EP Sample)'!G38 -> Number of Xpert XDR Assay | CS1: Presumptive DS TB Cases | CV1: Presumptive DR TB Cases | DU1: Presumptive Smear Negative TB Cases | DY1: Total Presumptive TB Cases Tested | DZ1: Total Presumptive DR-TB Cases Tested | EA1: Total Presumptive Tested | EB1: Number of MTB detected-DS TB | EF1: Number of MTB not detected (N)- DS TB | EG1: Number of MTB detected-DR TB | EK1: Number of MTB not detected (N)- DR TB | EL1: Number of MTB detected-Total | EP1: Number of MTB not detected -Total | EQ1: Number of Xpert XDR Assay | ET1: Number Of Xpert XDR Assay From Sputum & EP 10A
E2: Unknown History | F2: New | G2: Total | H2: Failures of CAT I (remain positive at month 5 or later/ Smear negative patients become smear positive at month 2) | I2: Failures of CAT II (remain positive at month 5 or 8) | J2: Non converters of CAT I (remain positive at month 2) | K2: Non converters of CAT II (remain positive at month 3) | L2: Relapses (CAT I) | M2: Relapses (CAT II) | N2: Treatment after loss to follow up (CAT I) | O2: Treatment after loss to follow up (CAT II) | P2: Close contacts of DR TB patient with symptoms | S2: HIV infected person with TB S/S | V2: Others (Pulmonary clinically diagnosed) | Y2: Others (Extra Pulmonary) | AB2: Others (Pulmonary bacteriologically confirmed) | AE2: Others (Total) | AF2: Total | AG2: Unknown History | AH2: New | AI2: Previously Treated | AJ2: Total | AN2: Rif Resistance not detected (T) | AO2: Rif Resistance detected (RR) | AP2: Rif Resistance indeterminate (TI) | AQ2: Number of MTB Trace detected (TT): | AS2: Rif Resistance not detected (T) | AT2: Rif Resistance detected (RR) | AU2: Rif Resistance indeterminate (TI) | AV2: Number of MTB Trace detected (TT): | AX2: Rif Resistance not detected (T) | AY2: Rif Resistance detected (RR) | AZ2: Rif Resistance indeterminate (TI) | BA2: Number of MTB Trace detected (TT): | BP2: ='COVID19 Reporting Form'!A20 -> Number Of COVID19 Test | BR2: ='COVID19 Reporting Form'!A23 -> Number of COVID 19 Positive Detected | BT2: ='COVID19 Reporting Form'!A26 -> Number of COVID 19 Negative Detected | BV2: ='COVID19 Reporting Form'!A20 -> Number Of COVID19 Test | BX2: ='COVID19 Reporting Form'!A23 -> Number of COVID 19 Positive Detected | BZ2: ='COVID19 Reporting Form'!A26 -> Number of COVID 19 Negative Detected | CE2: ='DR-TB 10A (Sputum & EP Sample)'!J13 -> Number of Gene Xpert Machine: | CF2: ='DR-TB 10A (Sputum & EP Sample)'!J14 -> Total Number Of Module: | CG2: ='DR-TB 10A (Sputum & EP Sample)'!J15 -> Number of Module Functional: | CH2: ='DR-TB 10A (Sputum & EP Sample)'!N13 -> No. of TruePrep Device | CI2: ='DR-TB 10A (Sputum & EP Sample)'!N14 -> No.of TrueLab Device | CJ2: ='DR-TB 10A (Sputum & EP Sample)'!N15 -> Total No. of Chip Ports | CK2: ='DR-TB 10A (Sputum & EP Sample)'!R13 -> Functional TruePrep Device | CL2: ='DR-TB 10A (Sputum & EP Sample)'!R14 -> Functional TrueLab Device | CM2: ='DR-TB 10A (Sputum & EP Sample)'!R15 -> Total functional Chip Ports | CN2: ='DR-TB 10A (Sputum & EP Sample)'!R17 -> No. of Truenat Cartriage Used | CO2: ='DR-TB 10A (Sputum & EP Sample)'!R18 -> No. of Truenat MTB Chip Used | CP2: ='DR-TB 10A (Sputum & EP Sample)'!R19 -> No. of Truenat RIF Dx Chip Used | CQ2: ='DR-TB 10A (Sputum & EP Sample)'!G40 -> Eligible for XDR Testing | CR2: ='DR-TB 10A (Sputum & EP Sample)'!G42 -> Tested from Eligible | CS2: Unknown History | CT2: New | CU2: Total | CV2: Failures of CAT I (remain positive at month 5 or later/ Smear negative patients become smear positive at month 2) | CW2: Failures of CAT II (remain positive at month 5 or 8) | CX2: Non converters of CAT I (remain positive at month 2) | CY2: Non converters of CAT II (remain positive at month 3) | CZ2: Relapses (CAT I) | DA2: Relapses (CAT II) | DB2: Treatment after loss to follow up (CAT I) | DC2: Treatment after loss to follow up (CAT II) | DD2: Close contacts of DR TB patient with symptoms | DG2: HIV infected person with TB S/S | DJ2: Others (Pulmonary clinically diagnosed) | DM2: Others (Extra Pulmonary) | DP2: Others (Pulmonary bacteriologically confirmed) | DS2: Others (Total) | DT2: Total | DU2: Unknown History | DV2: New | DW2: Previously Treated | DX2: Total | EB2: Rif Resistance not detected (T) | EC2: Rif Resistance detected (RR) | ED2: Rif Resistance indeterminate (TI) | EE2: Number of MTB Trace detected (TT): | EG2: Rif Resistance not detected (T) | EH2: Rif Resistance detected (RR) | EI2: Rif Resistance indeterminate (TI) | EJ2: Number of MTB Trace detected (TT): | EL2: Rif Resistance not detected (T) | EM2: Rif Resistance detected (RR) | EN2: Rif Resistance indeterminate (TI) | EO2: Number of MTB Trace detected (TT): | EQ2: Eligible for XDR Testing | ER2: Tested from Eligible | ES2: No. of Total Tests | ET2: No. of Total Tests
P3: Unknown history | Q3: New | R3: Prev. treated | S3: Unknown history | T3: New | U3: Prev. treated | V3: Unknown history | W3: New | X3: Prev. treated | Y3: Unknown history | Z3: New | AA3: Prev. treated | AB3: Unknown history | AC3: New | AD3: Prev. treated | BD3: Invalid | BE3: No Result | BF3: Error | BG3: Invalid | BH3: No Result | BI3: Error | BP3: ='COVID19 Reporting Form'!C18 -> Male | BQ3: ='COVID19 Reporting Form'!D18 -> Female | BR3: ='COVID19 Reporting Form'!C18 -> Male | BS3: ='COVID19 Reporting Form'!D18 -> Female | BT3: ='COVID19 Reporting Form'!C18 -> Male | BU3: ='COVID19 Reporting Form'!D18 -> Female | BV3: Male | BW3: Female | BX3: Male | BY3: Female | BZ3: Male | CA3: Female | DD3: Unknown history | DE3: New | DF3: Prev. treated | DG3: Unknown history | DH3: New | DI3: Prev. treated | DJ3: Unknown history | DK3: New | DL3: Prev. treated | DM3: Unknown history | DN3: New | DO3: Prev. treated | DP3: Unknown history | DQ3: New | DR3: Prev. treated
A4: ='DR-TB 10A (Sputum & EP Sample)'!$C6 -> 0 | B4: ='DR-TB 10A (Sputum & EP Sample)'!$C7 -> 0 | C4: ='DR-TB 10A (Sputum & EP Sample)'!$C8 -> 0 | D4: Tested by Xpert MTB/RIF | E4: ='DR-TB 10A (Sputum & EP Sample)'!$B27 -> 0 | F4: ='DR-TB 10A (Sputum & EP Sample)'!$C27 -> 0 | G4: ='DR-TB 10A (Sputum & EP Sample)'!$D27 -> 0 | H4: ='DR-TB 10A (Sputum & EP Sample)'!$E27 -> 0 | I4: ='DR-TB 10A (Sputum & EP Sample)'!$F27 -> 0 | J4: ='DR-TB 10A (Sputum & EP Sample)'!$G27 -> 0 | K4: ='DR-TB 10A (Sputum & EP Sample)'!$H27 -> 0 | L4: ='DR-TB 10A (Sputum & EP Sample)'!$I27 -> 0 | M4: ='DR-TB 10A (Sputum & EP Sample)'!$J27 -> 0 | N4: ='DR-TB 10A (Sputum & EP Sample)'!$K27 -> 0 | O4: ='DR-TB 10A (Sputum & EP Sample)'!$L27 -> 0 | P4: ='DR-TB 10A (Sputum & EP Sample)'!$O27 -> 0 | Q4: ='DR-TB 10A (Sputum & EP Sample)'!$O28 -> 0 | R4: ='DR-TB 10A (Sputum & EP Sample)'!$O29 -> 0 | S4: ='DR-TB 10A (Sputum & EP Sample)'!$R27 -> 0 | T4: ='DR-TB 10A (Sputum & EP Sample)'!$R28 -> 0 | U4: ='DR-TB 10A (Sputum & EP Sample)'!$R29 -> 0 | V4: ='DR-TB 10A (Sputum & EP Sample)'!$M41 -> 0 | W4: ='DR-TB 10A (Sputum & EP Sample)'!$N41 -> 0 | X4: ='DR-TB 10A (Sputum & EP Sample)'!$O41 -> 0 | Y4: ='DR-TB 10A (Sputum & EP Sample)'!$M42 -> 0 | Z4: ='DR-TB 10A (Sputum & EP Sample)'!$N42 -> 0 | AA4: ='DR-TB 10A (Sputum & EP Sample)'!$O42 -> 0 | AB4: ='DR-TB 10A (Sputum & EP Sample)'!$M43 -> 0 | AC4: ='DR-TB 10A (Sputum & EP Sample)'!$N43 -> 0 | AE4: ='DR-TB 10A (Sputum & EP Sample)'!$S27 -> 0 | AF4: ='DR-TB 10A (Sputum & EP Sample)'!$U27 -> 0 | AG4: ='DR-TB 10A (Sputum & EP Sample)'!$B40 -> 0 | AH4: ='DR-TB 10A (Sputum & EP Sample)'!$C40 -> 0 | AI4: ='DR-TB 10A (Sputum & EP Sample)'!$D40 -> 0 | AJ4: ='DR-TB 10A (Sputum & EP Sample)'!$E40 -> 0 | AK4: ='DR-TB 10A (Sputum & EP Sample)'!$H12 -> 0 | AL4: ='DR-TB 10A (Sputum & EP Sample)'!$H13 -> 0 | AM4: ='DR-TB 10A (Sputum & EP Sample)'!$H14 -> 0 | AN4: ='DR-TB 10A (Sputum & EP Sample)'!$D17 -> 0 | AO4: ='DR-TB 10A (Sputum & EP Sample)'!$D18 -> 0 | AP4: ='DR-TB 10A (Sputum & EP Sample)'!$D19 -> 0 | AQ4: ='DR-TB 10A (Sputum & EP Sample)'!$D20 -> 0 | AR4: ='DR-TB 10A (Sputum & EP Sample)'!$D21 -> 0 | AS4: ='DR-TB 10A (Sputum & EP Sample)'!$E17 -> 0 | AT4: ='DR-TB 10A (Sputum & EP Sample)'!$E18 -> 0 | AU4: ='DR-TB 10A (Sputum & EP Sample)'!$E19 -> 0 | AV4: ='DR-TB 10A (Sputum & EP Sample)'!$E20 -> 0 | AW4: ='DR-TB 10A (Sputum & EP Sample)'!$E21 -> 0 | AX4: ='DR-TB 10A (Sputum & EP Sample)'!$F17 -> 0 | AY4: ='DR-TB 10A (Sputum & EP Sample)'!$F18 -> 0 | AZ4: ='DR-TB 10A (Sputum & EP Sample)'!$F19 -> 0 | BA4: ='DR-TB 10A (Sputum & EP Sample)'!$F20 -> 0 | BB4: ='DR-TB 10A (Sputum & EP Sample)'!$F21 -> 0 | BC4: MTB | BD4: ='DR-TB 10A (Sputum & EP Sample)'!J19 -> 0 | BE4: ='DR-TB 10A (Sputum & EP Sample)'!K19 -> 0 | BF4: ='DR-TB 10A (Sputum & EP Sample)'!L19 -> 0 | BG4: ='DR-TB 10A (Sputum & EP Sample)'!M19 -> 0 | BH4: ='DR-TB 10A (Sputum & EP Sample)'!N19 -> 0 | BI4: ='DR-TB 10A (Sputum & EP Sample)'!O19 -> 0 | BJ4: ='DR-TB 10A (Sputum & EP Sample)'!P19 -> 0 | BK4: ='DR-TB 10A (Sputum & EP Sample)'!N7 -> 0 | BL4: ='DR-TB 10A (Sputum & EP Sample)'!M8 -> 0 | BM4: ='DR-TB 10A (Sputum & EP Sample)'!Q10 -> 0 | BN4: ='COVID19 Reporting Form'!B14 -> 0 | BO4: ='COVID19 Reporting Form'!D14 -> 0 | BP4: ='COVID19 Reporting Form'!C20 -> 0 | BQ4: ='COVID19 Reporting Form'!D20 -> 0 | BR4: ='COVID19 Reporting Form'!C23 -> 0 | BS4: ='COVID19 Reporting Form'!D23 -> 0 | BT4: ='COVID19 Reporting Form'!C26 -> 0 | BU4: ='COVID19 Reporting Form'!D26 -> 0 | BV4: ='COVID19 Reporting Form'!F20 -> 0 | BW4: ='COVID19 Reporting Form'!H20 -> 0 | BX4: ='COVID19 Reporting Form'!F23 -> 0 | BY4: ='COVID19 Reporting Form'!H23 -> 0 | BZ4: ='COVID19 Reporting Form'!F26 -> 0 | CA4: ='COVID19 Reporting Form'!H26 -> 0 | CB4: ='COVID19 Reporting Form'!L14 -> 0 | CC4: ='COVID19 Reporting Form'!M14 -> 0 | CD4: ='COVID19 Reporting Form'!N14 -> 0 | CE4: ='DR-TB 10A (Sputum & EP Sample)'!M13 -> 0 | CF4: ='DR-TB 10A (Sputum & EP Sample)'!M14 -> 0 | CG4: ='DR-TB 10A (Sputum & EP Sample)'!M15 -> 0 | CH4: ='DR-TB 10A (Sputum & EP Sample)'!Q13 -> 0 | CI4: ='DR-TB 10A (Sputum & EP Sample)'!Q14 -> 0 | CJ4: ='DR-TB 10A (Sputum & EP Sample)'!Q15 -> 0 | CK4: ='DR-TB 10A (Sputum & EP Sample)'!U13 -> 0 | CL4: ='DR-TB 10A (Sputum & EP Sample)'!U14 -> 0 | CM4: ='DR-TB 10A (Sputum & EP Sample)'!U15 -> 0 | CN4: ='DR-TB 10A (Sputum & EP Sample)'!U17 -> 0 | CO4: ='DR-TB 10A (Sputum & EP Sample)'!U18 -> 0 | CP4: ='DR-TB 10A (Sputum & EP Sample)'!U19 -> 0 | CQ4: ='DR-TB 10A (Sputum & EP Sample)'!H40 -> 0 | CR4: ='DR-TB 10A (Sputum & EP Sample)'!H42 -> 0 | CS4: ='DR-TB 10A (Stool)'!$B27 -> 0 | CT4: ='DR-TB 10A (Stool)'!$C27 -> 0 | CU4: ='DR-TB 10A (Stool)'!$D27 -> 0 | CV4: ='DR-TB 10A (Stool)'!$E27 -> 0 | CW4: ='DR-TB 10A (Stool)'!$F27 -> 0 | CX4: ='DR-TB 10A (Stool)'!$G27 -> 0 | CY4: ='DR-TB 10A (Stool)'!$H27 -> 0 | CZ4: ='DR-TB 10A (Stool)'!$I27 -> 0 | DA4: ='DR-TB 10A (Stool)'!$J27 -> 0 | DB4: ='DR-TB 10A (Stool)'!$K27 -> 0 | DC4: ='DR-TB 10A (Stool)'!$L27 -> 0 | DD4: ='DR-TB 10A (Stool)'!$O27 -> 0 | DE4: ='DR-TB 10A (Stool)'!$O28 -> 0 | DF4: ='DR-TB 10A (Stool)'!$O29 -> 0 | DG4: ='DR-TB 10A (Stool)'!$R27 -> 0 | DH4: ='DR-TB 10A (Stool)'!$R28 -> 0 | DI4: ='DR-TB 10A (Stool)'!$R29 -> 0 | DJ4: ='DR-TB 10A (Stool)'!$M41 -> 0 | DK4: ='DR-TB 10A (Stool)'!$N41 -> 0 | DL4: ='DR-TB 10A (Stool)'!$O41 -> 0 | DM4: ='DR-TB 10A (Stool)'!$M42 -> 0 | DN4: ='DR-TB 10A (Stool)'!$N42 -> 0 | DO4: ='DR-TB 10A (Stool)'!$O42 -> 0 | DP4: ='DR-TB 10A (Stool)'!$M43 -> 0 | DQ4: ='DR-TB 10A (Stool)'!$N43 -> 0 | DS4: ='DR-TB 10A (Stool)'!$S27 -> 0 | DT4: ='DR-TB 10A (Stool)'!$U27 -> 0 | DU4: ='DR-TB 10A (Stool)'!$B40 -> 0 | DV4: ='DR-TB 10A (Stool)'!$C40 -> 0 | DW4: ='DR-TB 10A (Stool)'!$D40 -> 0 | DX4: ='DR-TB 10A (Stool)'!$E40 -> 0 | DY4: ='DR-TB 10A (Stool)'!$H12 -> 0 | DZ4: ='DR-TB 10A (Stool)'!$H13 -> 0 | EA4: ='DR-TB 10A (Stool)'!$H14 -> 0 | EB4: ='DR-TB 10A (Stool)'!$D17 -> 0 | EC4: ='DR-TB 10A (Stool)'!$D18 -> 0 | ED4: ='DR-TB 10A (Stool)'!$D19 -> 0 | EE4: ='DR-TB 10A (Stool)'!$D20 -> 0 | EF4: ='DR-TB 10A (Stool)'!$D21 -> 0 | EG4: ='DR-TB 10A (Stool)'!$E17 -> 0 | EH4: ='DR-TB 10A (Stool)'!$E18 -> 0 | EI4: ='DR-TB 10A (Stool)'!$E19 -> 0 | EJ4: ='DR-TB 10A (Stool)'!$E20 -> 0 | EK4: ='DR-TB 10A (Stool)'!$E21 -> 0 | EL4: ='DR-TB 10A (Stool)'!$F17 -> 0 | EM4: ='DR-TB 10A (Stool)'!$F18 -> 0 | EN4: ='DR-TB 10A (Stool)'!$F19 -> 0 | EO4: ='DR-TB 10A (Stool)'!$F20 -> 0 | EP4: ='DR-TB 10A (Stool)'!$F21 -> 0 | EQ4: ='DR-TB 10A (Stool)'!$H40 -> 0 | ER4: ='DR-TB 10A (Stool)'!$H42 -> 0 | ES4: ='DR-TB 10A (Stool)'!$H44 -> 0 | ET4: ='DR-TB 10A (Sputum & EP Sample)'!$H44 -> 0
D5: MTB detected | E5: ='DR-TB 10A (Sputum & EP Sample)'!$B30 -> 0 | F5: ='DR-TB 10A (Sputum & EP Sample)'!$C30 -> 0 | G5: ='DR-TB 10A (Sputum & EP Sample)'!$D30 -> 0 | H5: ='DR-TB 10A (Sputum & EP Sample)'!$E30 -> 0 | I5: ='DR-TB 10A (Sputum & EP Sample)'!$F30 -> 0 | J5: ='DR-TB 10A (Sputum & EP Sample)'!$G30 -> 0 | K5: ='DR-TB 10A (Sputum & EP Sample)'!$H30 -> 0 | L5: ='DR-TB 10A (Sputum & EP Sample)'!$I30 -> 0 | M5: ='DR-TB 10A (Sputum & EP Sample)'!$J30 -> 0 | N5: ='DR-TB 10A (Sputum & EP Sample)'!$K30 -> 0 | O5: ='DR-TB 10A (Sputum & EP Sample)'!$L30 -> 0 | P5: ='DR-TB 10A (Sputum & EP Sample)'!$O30 -> 0 | Q5: ='DR-TB 10A (Sputum & EP Sample)'!$O31 -> 0 | R5: ='DR-TB 10A (Sputum & EP Sample)'!$O32 -> 0 | S5: ='DR-TB 10A (Sputum & EP Sample)'!$R30 -> 0 | T5: ='DR-TB 10A (Sputum & EP Sample)'!$R31 -> 0 | U5: ='DR-TB 10A (Sputum & EP Sample)'!$R32 -> 0 | V5: ='DR-TB 10A (Sputum & EP Sample)'!$P41 -> 0 | W5: ='DR-TB 10A (Sputum & EP Sample)'!$Q41 -> 0 | X5: ='DR-TB 10A (Sputum & EP Sample)'!$R41 -> 0 | Y5: ='DR-TB 10A (Sputum & EP Sample)'!$P42 -> 0 | Z5: ='DR-TB 10A (Sputum & EP Sample)'!$Q42 -> 0 | AA5: ='DR-TB 10A (Sputum & EP Sample)'!$R42 -> 0 | AB5: ='DR-TB 10A (Sputum & EP Sample)'!$P43 -> 0 | AC5: ='DR-TB 10A (Sputum & EP Sample)'!$Q43 -> 0 | AE5: ='DR-TB 10A (Sputum & EP Sample)'!$S30 -> 0 | AF5: ='DR-TB 10A (Sputum & EP Sample)'!$U30 -> 0 | AG5: ='DR-TB 10A (Sputum & EP Sample)'!$B42 -> 0 | AH5: ='DR-TB 10A (Sputum & EP Sample)'!$C42 -> 0 | AI5: ='DR-TB 10A (Sputum & EP Sample)'!$D42 -> 0 | AJ5: ='DR-TB 10A (Sputum & EP Sample)'!$E42 -> 0 | BC5: XDR | BD5: ='DR-TB 10A (Sputum & EP Sample)'!J20 -> 0 | BE5: ='DR-TB 10A (Sputum & EP Sample)'!K20 -> 0 | BF5: ='DR-TB 10A (Sputum & EP Sample)'!L20 -> 0 | BG5: ='DR-TB 10A (Sputum & EP Sample)'!M20 -> 0 | BH5: ='DR-TB 10A (Sputum & EP Sample)'!N20 -> 0 | BI5: ='DR-TB 10A (Sputum & EP Sample)'!O20 -> 0 | BJ5: ='DR-TB 10A (Sputum & EP Sample)'!P20 -> 0 | CS5: ='DR-TB 10A (Stool)'!$B30 -> 0 | CT5: ='DR-TB 10A (Stool)'!$C30 -> 0 | CU5: ='DR-TB 10A (Stool)'!$D30 -> 0 | CV5: ='DR-TB 10A (Stool)'!$E30 -> 0 | CW5: ='DR-TB 10A (Stool)'!$F30 -> 0 | CX5: ='DR-TB 10A (Stool)'!$G30 -> 0 | CY5: ='DR-TB 10A (Stool)'!$H30 -> 0 | CZ5: ='DR-TB 10A (Stool)'!$I30 -> 0 | DA5: ='DR-TB 10A (Stool)'!$J30 -> 0 | DB5: ='DR-TB 10A (Stool)'!$K30 -> 0 | DC5: ='DR-TB 10A (Stool)'!$L30 -> 0 | DD5: ='DR-TB 10A (Stool)'!$O30 -> 0 | DE5: ='DR-TB 10A (Stool)'!$O31 -> 0 | DF5: ='DR-TB 10A (Stool)'!$O32 -> 0 | DG5: ='DR-TB 10A (Stool)'!$R30 -> 0 | DH5: ='DR-TB 10A (Stool)'!$R31 -> 0 | DI5: ='DR-TB 10A (Stool)'!$R32 -> 0 | DJ5: ='DR-TB 10A (Stool)'!$P41 -> 0 | DK5: ='DR-TB 10A (Stool)'!$Q41 -> 0 | DL5: ='DR-TB 10A (Stool)'!$R41 -> 0 | DM5: ='DR-TB 10A (Stool)'!$P42 -> 0 | DN5: ='DR-TB 10A (Stool)'!$Q42 -> 0 | DO5: ='DR-TB 10A (Stool)'!$R42 -> 0 | DP5: ='DR-TB 10A (Stool)'!$P43 -> 0 | DQ5: ='DR-TB 10A (Stool)'!$Q43 -> 0 | DS5: ='DR-TB 10A (Stool)'!$S30 -> 0 | DT5: ='DR-TB 10A (Stool)'!$U30 -> 0 | DU5: ='DR-TB 10A (Stool)'!$B42 -> 0 | DV5: ='DR-TB 10A (Stool)'!$C42 -> 0 | DW5: ='DR-TB 10A (Stool)'!$D42 -> 0 | DX5: ='DR-TB 10A (Stool)'!$E42 -> 0
D6: RR TB detected | E6: ='DR-TB 10A (Sputum & EP Sample)'!$B33 -> 0 | F6: ='DR-TB 10A (Sputum & EP Sample)'!$C33 -> 0 | G6: ='DR-TB 10A (Sputum & EP Sample)'!$D33 -> 0 | H6: ='DR-TB 10A (Sputum & EP Sample)'!$E33 -> 0 | I6: ='DR-TB 10A (Sputum & EP Sample)'!$F33 -> 0 | J6: ='DR-TB 10A (Sputum & EP Sample)'!$G33 -> 0 | K6: ='DR-TB 10A (Sputum & EP Sample)'!$H33 -> 0 | L6: ='DR-TB 10A (Sputum & EP Sample)'!$I33 -> 0 | M6: ='DR-TB 10A (Sputum & EP Sample)'!$J33 -> 0 | N6: ='DR-TB 10A (Sputum & EP Sample)'!$K33 -> 0 | O6: ='DR-TB 10A (Sputum & EP Sample)'!$L33 -> 0 | P6: ='DR-TB 10A (Sputum & EP Sample)'!$O33 -> 0 | Q6: ='DR-TB 10A (Sputum & EP Sample)'!$O34 -> 0 | R6: ='DR-TB 10A (Sputum & EP Sample)'!$O35 -> 0 | S6: ='DR-TB 10A (Sputum & EP Sample)'!$R33 -> 0 | T6: ='DR-TB 10A (Sputum & EP Sample)'!$R34 -> 0 | U6: ='DR-TB 10A (Sputum & EP Sample)'!$R35 -> 0 | V6: ='DR-TB 10A (Sputum & EP Sample)'!$S41 -> 0 | W6: ='DR-TB 10A (Sputum & EP Sample)'!$T41 -> 0 | X6: ='DR-TB 10A (Sputum & EP Sample)'!$U41 -> 0 | Y6: ='DR-TB 10A (Sputum & EP Sample)'!$S42 -> 0 | Z6: ='DR-TB 10A (Sputum & EP Sample)'!$T42 -> 0 | AA6: ='DR-TB 10A (Sputum & EP Sample)'!$U42 -> 0 | AB6: ='DR-TB 10A (Sputum & EP Sample)'!$S43 -> 0 | AC6: ='DR-TB 10A (Sputum & EP Sample)'!$T43 -> 0 | AE6: ='DR-TB 10A (Sputum & EP Sample)'!$S33 -> 0 | AF6: ='DR-TB 10A (Sputum & EP Sample)'!$U33 -> 0 | AG6: ='DR-TB 10A (Sputum & EP Sample)'!$B44 -> 0 | AH6: ='DR-TB 10A (Sputum & EP Sample)'!$C44 -> 0 | AI6: ='DR-TB 10A (Sputum & EP Sample)'!$D44 -> 0 | AJ6: ='DR-TB 10A (Sputum & EP Sample)'!$E44 -> 0 | CS6: ='DR-TB 10A (Stool)'!$B33 -> 0 | CT6: ='DR-TB 10A (Stool)'!$C33 -> 0 | CU6: ='DR-TB 10A (Stool)'!$D33 -> 0 | CV6: ='DR-TB 10A (Stool)'!$E33 -> 0 | CW6: ='DR-TB 10A (Stool)'!$F33 -> 0 | CX6: ='DR-TB 10A (Stool)'!$G33 -> 0 | CY6: ='DR-TB 10A (Stool)'!$H33 -> 0 | CZ6: ='DR-TB 10A (Stool)'!$I33 -> 0 | DA6: ='DR-TB 10A (Stool)'!$J33 -> 0 | DB6: ='DR-TB 10A (Stool)'!$K33 -> 0 | DC6: ='DR-TB 10A (Stool)'!$L33 -> 0 | DD6: ='DR-TB 10A (Stool)'!$O33 -> 0 | DE6: ='DR-TB 10A (Stool)'!$O34 -> 0 | DF6: ='DR-TB 10A (Stool)'!$O35 -> 0 | DG6: ='DR-TB 10A (Stool)'!$R33 -> 0 | DH6: ='DR-TB 10A (Stool)'!$R34 -> 0 | DI6: ='DR-TB 10A (Stool)'!$R35 -> 0 | DJ6: ='DR-TB 10A (Stool)'!$S41 -> 0 | DK6: ='DR-TB 10A (Stool)'!$T41 -> 0 | DL6: ='DR-TB 10A (Stool)'!$U41 -> 0 | DM6: ='DR-TB 10A (Stool)'!$S42 -> 0 | DN6: ='DR-TB 10A (Stool)'!$T42 -> 0 | DO6: ='DR-TB 10A (Stool)'!$U42 -> 0 | DP6: ='DR-TB 10A (Stool)'!$S43 -> 0 | DQ6: ='DR-TB 10A (Stool)'!$T43 -> 0 | DS6: ='DR-TB 10A (Stool)'!$S33 -> 0 | DT6: ='DR-TB 10A (Stool)'!$U33 -> 0 | DU6: ='DR-TB 10A (Stool)'!$B44 -> 0 | DV6: ='DR-TB 10A (Stool)'!$C44 -> 0 | DW6: ='DR-TB 10A (Stool)'!$D44 -> 0 | DX6: ='DR-TB 10A (Stool)'!$E44 -> 0
A10: Division | B10: District / Area | C10: Name of GeneXpert/Truenat Site | D10: ='DR-TB 10B'!A11 -> Sl. No | E10: ='DR-TB 10B'!B11 -> Name of the RR patient | F10: ='DR-TB 10B'!C11 -> Age | G10: ='DR-TB 10B'!D11 -> Sex (M/F) | H10: ='DR-TB 10B'!F11 -> Address and cell number | I10: ='DR-TB 10B'!G11 -> Name & address of the referring unit and cell number | J10: ='DR-TB 10B'!H11 -> * Type of patient | K10: ='DR-TB 10B'!J11 -> Current and previous (if any) TB registration number | L10: ='DR-TB 10B'!K11 -> Result of Xpert/Truenat MTB/RIF/Ultra | M10: ='DR-TB 10B'!L11 -> Bacterial Load | N10: ='DR-TB 10B'!T11 -> Name and address of the hospital/ treatment initiation center for enrollment of DR TB treatment | O10: ='DR-TB 10B'!U11 -> Enrollment status (Y/N) | P10: ='DR-TB 10B'!X11 -> ** Current status of the patient | Q10: ='DR-TB 10B'!Y11 -> Remarks | R10: ='DR-TB 10B'!E11 -> Date of Diagnosis | S10: ='DR-TB 10B'!V11 -> Date Of Enrollment | T10: ='DR-TB 10B'!W11 -> eTB/ DR TB Registration Number | U10: ='DR-TB 10B'!I11 -> Type Of Sample | V10: ='DR-TB 10B'!M11 -> Result Of MTB/XDR | AC10: Site of Xpert/Truenat MTB/RIF Test
V11: ='DR-TB 10B'!M12 -> MTB | W11: ='DR-TB 10B'!N12 -> INH | X11: ='DR-TB 10B'!O12 -> FLQ | Y11: ='DR-TB 10B'!P12 -> AMK | Z11: ='DR-TB 10B'!Q12 -> KAN | AA11: ='DR-TB 10B'!R12 -> CAP | AB11: ='DR-TB 10B'!S12 -> ETH
A12: ='DR-TB 10A (Sputum & EP Sample)'!$C$6 -> 0 | B12: ='DR-TB 10A (Sputum & EP Sample)'!$C$7 -> 0 | C12: ='DR-TB 10A (Sputum & EP Sample)'!$C$8 -> 0 | D12: ='DR-TB 10B'!A13 -> <#> | E12: ='DR-TB 10B'!B13 -> <patientName> | F12: ='DR-TB 10B'!C13 -> <patientAge> | G12: ='DR-TB 10B'!D13 -> <gender> | H12: ='DR-TB 10B'!F13 -> <patientAddressAndCell> | I12: ='DR-TB 10B'!G13 -> <referringAddressAndCell> | J12: ='DR-TB 10B'!H13 -> <patientType> | K12: ='DR-TB 10B'!J13 -> <tbRegistrationNumber> | L12: ='DR-TB 10B'!K13 -> <resultMtbRif> | M12: ='DR-TB 10B'!L13 -> <bacterialLoad> | N12: ='DR-TB 10B'!T13 -> <hospitalTreatmentDRTB> | O12: ='DR-TB 10B'!U13 -> <enrollmentStatus> | P12: ='DR-TB 10B'!X13 -> <patientStatus> | Q12: ='DR-TB 10B'!Y13 -> <remarks> | R12: ='DR-TB 10B'!E13 -> <dateOfDiagnosis> | S12: ='DR-TB 10B'!V13 -> <enrollmentDate> | T12: ='DR-TB 10B'!W13 -> <tbRegistrationNumber> | U12: ='DR-TB 10B'!I13 -> <sampleType> | V12: ='DR-TB 10B'!M13 -> <mtbDetected> | W12: ='DR-TB 10B'!N13 -> <inhDetected> | X12: ='DR-TB 10B'!O13 -> <flqDetected> | Y12: ='DR-TB 10B'!P13 -> <amkDetected> | Z12: ='DR-TB 10B'!Q13 -> <kanDetected> | AA12: ='DR-TB 10B'!R13 -> <capDetected> | AB12: ='DR-TB 10B'!S13 -> <ethDetected> | AC12: ='DR-TB 10B'!$M13 -> <mtbDetected>
