Workbook
Name Bagerhat: 'DR-TB 10A'!#REF!
Name Bandarban: 'DR-TB 10A'!#REF!
Name Barguna: 'DR-TB 10A'!#REF!
Name Barisal: 'DR-TB 10A'!#REF!
Name Barisal_Division: 'DR-TB 10A'!#REF!
Name Bhola: 'DR-TB 10A'!#REF!
Name Bogra: 'DR-TB 10A'!#REF!
Name Brahmanbaria: 'DR-TB 10A'!#REF!
Name Chandpur: 'DR-TB 10A'!#REF!
Name Chattogram: 'DR-TB 10A'!#REF!
Name Chattogram_Division: 'DR-TB 10A'!#REF!
Name Chuadanga: 'DR-TB 10A'!#REF!
Name Comilla: 'DR-TB 10A'!#REF!
Name Coxs_Bazar: 'DR-TB 10A'!#REF!
Name Dhaka: 'DR-TB 10A'!#REF!
Name Dhaka_Division: 'DR-TB 10A'!#REF!
Name Dinajpur: 'DR-TB 10A'!#REF!
Name Faridpur: 'DR-TB 10A'!#REF!
Name Feni: 'DR-TB 10A'!#REF!
Name Gaibandha: 'DR-TB 10A'!#REF!
Name Gazipur: 'DR-TB 10A'!#REF!
Name Gopalganj: 'DR-TB 10A'!#REF!
Name Habiganj: 'DR-TB 10A'!#REF!
Name Jamalpur: 'DR-TB 10A'!#REF!
Name Jessore: 'DR-TB 10A'!#REF!
Name Jhalakathi: 'DR-TB 10A'!#REF!
Name Jhenaidah: 'DR-TB 10A'!#REF!
Name Joypurhat: 'DR-TB 10A'!#REF!
Name Khagrachari: 'DR-TB 10A'!#REF!
Name Khulna: 'DR-TB 10A'!#REF!
Name Khulna_Division: 'DR-TB 10A'!#REF!
Name Kishoreganj: 'DR-TB 10A'!#REF!
Name Kurigram: 'DR-TB 10A'!#REF!
Name Kushtia: 'DR-TB 10A'!#REF!
Name Lalmonirhat: 'DR-TB 10A'!#REF!
Name Laxmipur: 'DR-TB 10A'!#REF!
Name Madaripur: 'DR-TB 10A'!#REF!
Name Magura: 'DR-TB 10A'!#REF!
Name Manikganj: 'DR-TB 10A'!#REF!
Name Meherpur: 'DR-TB 10A'!#REF!
Name Moulvibazar: 'DR-TB 10A'!#REF!
Name Munshiganj: 'DR-TB 10A'!#REF!
Name Mymensingh: 'DR-TB 10A'!#REF!
Name Mymensingh_Division: 'DR-TB 10A'!#REF!
Name Naogaon: 'DR-TB 10A'!#REF!
Name Narail: 'DR-TB 10A'!#REF!
Name Narayanganj: 'DR-TB 10A'!#REF!
Name Narsingdi: 'DR-TB 10A'!#REF!
Name Natore: 'DR-TB 10A'!#REF!
Name Nawabganj: 'DR-TB 10A'!#REF!
Name Netrakona: 'DR-TB 10A'!#REF!
Name Nilphamari: 'DR-TB 10A'!#REF!
Name Noakhali: 'DR-TB 10A'!#REF!
Name Pabna: 'DR-TB 10A'!#REF!
Name Panchagarh: 'DR-TB 10A'!#REF!
Name Patuakhali: 'DR-TB 10A'!#REF!
Name Pirojpur: 'DR-TB 10A'!#REF!
Name Rajbari: 'DR-TB 10A'!#REF!
Name Rajshahi: 'DR-TB 10A'!#REF!
Name Rajshahi_Division: 'DR-TB 10A'!#REF!

Sheet DR-TB 10A
A1: Government of the People's Republic of Bangladesh | S1: Form DR TB 10 A
A2: National TB Control Programme
A3: Programmatic Management of Drug Resistant Tuberculosis (PMDT)
A4: Monthly Report on Xpert MTB/RIF Results
A6: Division : | J6: Reporting period : | M6: Month | N6: =IF(L6="","",VLOOKUP(L6,#REF!,2,FALSE)) | P6: Quarter of year
A7: District : | J7: Name of the person completing the report :
A8: Name of the reporting unit : | J8: Designation and organization :
J9: Date of completion of the form :
J10: Signature : | O10: Cell Number :
A11: Block 1:
A12: Number of total Cases Tested | D12: Presumptive TB Cases(Total) | H12: =D26+E39 -> 0 | J12: Number of Gene Xpert Machine:
D13: Presumptive DR TB Cases(Total) | H13: =U26 -> 0 | J13: Total Number Of Module:
D14: Total | H14: =H12+H13 -> 0 | J14: Number of Module Functional:
A16: Results: | D16: Presumptive TB | E16: Presumptive DR-TB | F16: Total
A17: A) Number of MTB detected, Rif Resistance not detected (T): | D17: =D29+E41-D32-E43 -> 0 | E17: =+U29-U32 -> 0 | F17: =+E17+D17 -> 0 | H17: E) Number of invalid / no result / error (I): | L17: Presumptive TB | O17: Presumptive DR-TB | R17: Total
A18: B) Number of MTB detected, Rif Resistance detected (RR): | D18: =D32+E43 -> 0 | E18: =U32 -> 0 | F18: =+E18+D18 -> 0 | R18: =L18+M18+N18+O18+P18+Q18 -> 0
A19: C) Number of MTB detected, Rif Resistance indeterminate (TI): | F19: =+E19+D19 -> 0
A20: D) Number of MTB not detected (N): | D20: =H12-D29-E41 -> 0 | E20: =H13-U29 -> 0 | F20: =+E20+D20 -> 0
A22: Block 2:
A23: Number of : | B23: Type of Patient : Presumptive TB Cases | E23: Type of Patient : Presumptive DR TB Cases | U23: Total (Column 3- Column 13)
B24: Unknown History | C24: New | D24: Total (Column 1- Column 2) | E24: Failures of CAT I (remain positive at month 5 or later/ Smear negative patients become smear positive at month 2) | F24: Failures of CAT II (remain positive at month 5 or 8) | G24: Non converters of CAT I (remain positive at month 2) | H24: Non converters of CAT II (remain positive at month 3) | I24: Relapses (CAT I) | J24: Relapses (CAT II) | K24: Treatment after loss to follow up (CAT I) | L24: Treatment after loss to follow up (CAT II) | M24: Close contacts of DR TB patient with symptoms | P24: HIV infected person with TB S/S | S24: Others (Specify)* i) Pulmonary clinically diagnosed ii) Extra Pulmonary iii) Pulmonary bacteriologically confirmed
B25: Column (1) | C25: Column (2) | E25: Column (3) | F25: Column (4) | G25: Column (5) | H25: Column (6) | I25: Column (7) | J25: Column (8) | K25: Column (9) | L25: Column (10) | M25: Column (11) | P25: Column (12) | S25: Column (13)
A26: Presumptive cases tested by Xpert MTB/RIF | D26: =B26+C26 -> 0 | M26: Unknown history: | P26: Unknown history: | S26: =M40+M41+M42+N40+N41+N42+O40+O41 -> 0 | U26: =E26+F26+G26+H26+I26+J26+K26+L26+O26+O27+O28+R26+R27+R28+S26 -> 0
M27: New: | P27: New:
M28: Prev. treated: | P28: Prev. treated:
A29: MTB detected | D29: =B29+C29 -> 0 | M29: Unknown history: | P29: Unknown history: | S29: =P40+P41+P42+Q40+Q41+Q42+R40+R41 -> 0 | U29: =E29+F29+G29+H29+I29+J29+K29+L29+O29+O30+O31+R29+R30+R31+S29 -> 0
M30: New: | P30: New:
M31: Prev. treated: | P31: Prev. treated:
A32: RR TB detected | D32: =B32+C32 -> 0 | M32: Unknown history: | P32: Unknown history: | S32: =S40+S41+S42+T40+T41+T42+U40+U41 -> 0 | U32: =E32+F32+G32+H32+I32+J32+K32+L32+O32+O33+O34+R32+R33+R34+S32 -> 0
M33: New: | P33: New:
M34: Prev. treated: | P34: Prev. treated:
A36: Block 3:
A37: Number of Presumptive smear negative TB cases | J37: *Others (Specify)
B38: Unknown History | C38: New | D38: Prev. Treated | E38: Total | J38: Type of Patient | M38: Presumptive DR TB cases | P38: MTB detected | S38: RR TB detected
A39: Presumptive Sm. Neg cases tested by Xpert MTB/RIF | E39: =B39+C39+D39 -> 0 | M39: Un. His. | N39: N | O39: Prev. Tr. | P39: Un. His. | Q39: N | R39: Prev. Tr. | S39: Un. His. | T39: N | U39: Prev. Tr.
J40: i) Pulmonary clinically diagnosed
A41: MTB Detected | E41: =B41+C41+D41 -> 0 | J41: ii) Extra Pulmonary
J42: iii) Pulmonary bacteriologically confirmed
A43: RR TB Detected | E43: =B43+C43+D43 -> 0 | J43: Un. His. = Unknown History, N = New, Prev. Tr. = Previously Treated
F45: Comments | L45: Name and disignation of Coordinator/ authority of the center:
...

Sheet DR-TB 10B
A1: Government of the People's Republic of Bangladesh
A2: National TB Control Program
A3: Programmatic Management of Drug Resistant Tuberculosis (PMDT)
A4: Monthly Report of Enrolment status of Detected
A5: Drug Resistant Cases by Xpert MTB/RIF
A7: Fill this format as per total RR TB detected cases during the reporting month reported in the form DR TB 10 A
A8: Name and address of the reporting Unit: | D8: =IF('DR-TB 10A'!C8="","",'DR-TB 10A'!C8) | H8: Reporting period: | I8: =IF('DR-TB 10A'!L6="","",'DR-TB 10A'!L6) | J8: Month: | K8: =IF('DR-TB 10A'!N6="","",'DR-TB 10A'!N6) | L8: Quarter of year: | O8: =IF('DR-TB 10A'!R6="","",'DR-TB 10A'!R6)
A9: Number of total RR TB detected in the reporting month: | F9: ='DR-TB 10A'!F18 -> 0
A11: Sl. No | B11: Name of the RR TB patient | C11: Age | D11: Sex (M/F) | E11: Date of Diagnosis | F11: Address and cell number | G11: Name and address of the referring unit and cell number | H11: * Type of patient | I11: Current and previous (if any) TB registration number | J11: ** Result of Xpert MTB/RIF | K11: Name and address of the hospital/ treatment initiation center for enrollment of DR TB treatment | L11: Enrollment status (Y/N) | M11: Date Of Enrollment | N11: *** Current status of the patient | O11: Remarks
A30: *Type of patient (Code): 1, Failures of Category I (remain positive at month 5 or later and / Smear negative patients become smear positive at month 2); 2, Failures of Category II (remain positive at month 5 or 8); 3, Non Converters of CAT II (remain positive at month 3); 4, Non Converters of Category I (remain positive at month 2) ; 5, Relapse - a) Category I, b) Category II; 6, Treatment after loss to follow up - a) Category I, b) Category II ; 7, Close contacts of DR-TB patient with symptoms, a) Unknown history b) New c) Prev. treated; 8, HIV infected person with TB S/S, a) Unknown history b) New c) Prev. treated; 9, Others (Specify) i) Pulmonary, clinically diagnosed, a) Unknown history b) New c) Prev. treated, ii) Extra Pulmonary, a) Unknown history b) New c) Prev. treated, iii) Pulmonary, bacteriologically confirmed, a) Unknown history b) New; 10, Presumptive Pulmonary Smear Negative cases a) Unknown history b) New c) Prev. treated.
A31: **Result of Xpert MTB/RIF: T = MTB detected, Rif resistance not detected, RR = MTB detected, Rif resistance detected, TI = MTB detected, Rif resistance indeterminate, N = MTB not detected, I = invalid/ no result/ error
A32: ***Example: died(With Date), absconded/Lost to follow up, under treatment etc.

Sheet COVID19 Reporting Form
A1: Government of the People's Republic of Bangladesh | P1: COVID19 Test Reporting Form
A2: National TB Control Programme
A3: Directorate General of Health Services
A5: Monthly Report on Xpert COVID19 Results
A7: Division : | C7: ='DR-TB 10A'!C6:G6 -> 0 | J7: Reporting period : | L7: ='DR-TB 10A'!L6 -> 0 | M7: Month | N7: ='DR-TB 10A'!N6:O6 | P7: Quarter of year | R7: ='DR-TB 10A'!R6 -> 0
A8: District : | C8: ='DR-TB 10A'!C7:G7 -> 0 | J8: Name of the person reporting
A9: Name of the reporting unit : | C9: ='DR-TB 10A'!C8:G8 -> 0 | J9: Designation and organization :
J10: Date of completion of the form :
J11: Signature : | O11: Cell Number :
A13: Cartridge information | B13: Cartridges Received | D13: Cartridges in Hand | H13: Number of invalid / no result / error: | L13: COVID19 Test | O13: Total
O14: =L14+M14+N14 -> 0
C17: Type of test : New | F17: Type of Test : Follow up | L17: Grand Total
C18: Male | D18: Female | E18: Total | F18: Male | H18: Female | J18: Total | L18: Male | N18: Female | P18: Total
A20: Number Of COVID19 Test | E20: =C20+D20 -> 0 | J20: =F20+H20 -> 0 | L20: =C20+F20 -> 0 | N20: =D20+H20 -> 0 | P20: =L20+N20 -> 0
A23: Number of COVID 19 Positive Detected | E23: =C23+D23 -> 0 | J23: =F23+H23 -> 0 | L23: =C23+F23 -> 0 | N23: =D23+H23 -> 0 | P23: =L23+N23 -> 0
A26: Number of COVID 19 Negative Detected | E26: =C26+D26 -> 0 | J26: =F26+H26 -> 0 | L26: =C26+F26 -> 0 | N26: =D26+H26 -> 0 | P26: =L26+N26 -> 0
H30: Name and designation of Coordinator/ authority :
H31: Signature: | N31: Date:
H32: Cell number:
